Workbook

Sheet FICHE R1 
B5: Dénomination sociale de l'entité:
AC6: Sigle usuel :
B7: Adresse :
B8: N° d'identification fiscale : | W8: Exercice clos le : | AN8: Durée (en mois) :
B10: ZA | G10: EXERCICE COMPTABLE: | Z10: DU: | AJ10: AU
B12: ZB | G12: DATE D'ARRETE EFFECTIF DES COMPTES
B14: ZC | G14: EXERCICE PRECEDENT CLOS LE: | AB14: DUREE EXERCICE PRECEDENT EN MOIS:
B16: ZD
G17: Greffe | J17: N° Registre du commerce | AC17: N° Répertoire des entités
B19: ZE
G20: N° de caisse sociale | P20: N° Code Importateur | AJ20: Code activité principale
B22: ZF
R23: Désignation de l'entité | AN23: Sigle
B25: ZG | AA25: 02
G26: N° de téléphone | Q26: email | AB26: Code | AE26: Bote postale | AN26: Ville
B28: ZH
G29: Adresse géographique complète (Immeuble, rue, quartier, ville, pays)
B31: ZI
I32: Désignation précise de l'activité principale exercée par l'entité
G35: Nom, adresse et qualité de la personne à contacter en cas de demande d'informations complémentaires
G38: Nom du professionnel salarié de l'entité ou
G39: Nom, adresse et téléhone du cabinet comptable ou du professionnel INSCRIT A L'ORDRE NATIONAL
G40: DES EXPERTS COMPTABLES ET DES COMPTABLES AGREES ayant établi les états financiers
H45: Visa de l'Expert comptable agrée
AM49: Non | AP49: Oui
AG51: Etats financiers approuvés par l'Assemeblée Générale (cocher la case)
AC53: Domiciliations bancaires:
H54: Nom du sigantaire des états financiers | AB54: Banque | AK54: Numéro de compte
H57: Nom du sigantaire des états financiers
H60: Date de signature
H66: Signature

Sheet FICHE R2 
B5: Désignation entité : | AB5: Exercice clos le
B6: Numéro d'identification : | K6: ='FICHE R1 '!K8:T8 -> 0 | AB6: Durée (en mois) 12
W9: Contrôle de l'entité (cocher la case)
B10: ZK | D10: Forme juridique (1) : | W10: ZQ | X10: Entité sous contrôle public
B12: ZL | D12: Régime fiscal (1) : | W12: ZR | X12: Entité sous contrôle privé national
B14: ZM | D14: Pays du siège social (1) : | W14: ZS | X14: Entité sous contrôle privé étranger
B16: ZN | D16: Nombre d'établissements dans le pays :
B18: ZO | D18: Nombre d'établissements hors du pays pour
D19: lesquels une comptabilité distincte est tenue :
B21: ZP | D21: Première année d'exercice dans le pays :
B24: ACTIVITE DE L'ENTITE
B26: Désignation de l'activité (2) | Q26: Code nomenclature | Y26: Chiffre d'affaires HT | AH26: % activité
Q27: d'activité (1) | Y27: (CA HT) | AH27: dans le CA
AH28: HT
Y30: 0 | AH30: =Y30/Y42 -> #DIV/0!
AH34: =Y34/Y42 -> #DIV/0!
AH37: =Y37/Y42 -> #DIV/0!
B40: Divers | AH40: =Y40/Y42 -> #DIV/0!
Q42: TOTAL | Y42: =Y30+Y34+Y37+Y40 -> 0 | AH42: =AH30+AH34+AH37+AH40 -> #DIV/0!
B45: (1) NOTE 36
B46: (2) Lister de manière précise les activités dans l'ordre décroissant du C. A. HT, ou de la valeur ajoutée (V. A.).

Sheet FICHE R3 
B6: Désignation entité : | F6: =+'FICHE R2 '!AB5 -> Exercice clos le
B7: Numéro d'identification : | F7: Durée (en mois)
B9: DIRIGEANTS (1)
B11: Nom | C11: Prénoms | D11: Qualité | E11: N° identification fiscale | F11: Adresse (BP, ville, pays)
B19: (1) Dirigeants = Président Directeur Général, Directeur Général, Administrateur Général, Gérant, Autres.
B22: MEMBRES DU CONSEIL D'ADMINISTRATION
B24: Nom | C24: Prénoms | D24: Qualité | E24: Adresse (BP, ville, pays)

Sheet FICHE R4
A3: Désignation entité : | C3: Exercice clos le
A4: Numéro d’identification : | C4: Durée (en mois)
A6: NOTES | B6: INTITULES | C6: A | D6: N/A
A7: NOTE 1 | B7: DETTES GARANTIES PAR DES SURETTES REELLES
A8: NOTE 2 | B8: INFORMATIONS OBLIGTOIRES
A9: NOTE 3A | B9: IMMOBILISATION BRUTE
A10: NOTE 3B | B10: BIENS PRIS EN LOCATION ACQUISITION
A11: NOTE 3C | B11: IMMOBILISATIONS : AMORTISSEMENTS
A12: NOTE 3D | B12: IMMOBLISATIONS : PLUS-VALUES ET MOINS VALUE DE CESSION
A13: NOTE 3E | B13: INFORMATIONS SUR LES REEVALUATIONS EFFECTUEES PAR L’ENTITE
A14: NOTE 3F | B14: TABLEAU D’ETALEMENT DES CHARGES IMMOBILISEES
A15: NOTE 4 | B15: IMMOBILISATIONS FINANCIERES
A16: NOTE 5 | B16: ACTIF CIRCULANT HAO
A17: NOTE 6 | B17: STOCKS ET ENCOURS
A18: NOTE 7 | B18: CLIENTS
... A52: NOTE 36 | B52: TABLES DES CODES
A53: A : Applicable N/A : Non Applicable.

Sheet ACTIF
A4: Désignation entité : | E4: Exercice clos le
A5: Numéro d’identification : | E5: Durée (en mois)
A6: BILAN AU 31 DECEMBRE N
A7: REF | B7: ACTIF | C7: Note | D7: EXERCICE AU 31/12/ N | G7: EXERCICE AU
G8: 31/12/N-1
D9: BRUT | E9: AMORT ET DEPREC | F9: NET | G9: NET
A10: AD | B10: IMMOBILISATIONS INCORPORELLES | C10: 3 | D10: =SUM(D11:D14) -> 0 | E10: =SUM(E11:E14) -> 0 | F10: =SUM(F11:F14) -> 0 | G10: =SUM(G11:G14) -> 0
A11: AE | B11: Frais de développement et de prospection | G11: 0
A12: AF | B12: Brevets, licences, logiciels, et droits similaires | F12: =D12-E12 -> 0
A13: AG | B13: Fonds commercial et droit au bail | F13: =D13-E13 -> 0
A14: AH | B14: Autres immobilisations incorporelles | F14: =D14-E14 -> 0
A15: AI | B15: IMMOBILISATIONS CORPORELLES | C15: 3 | D15: =SUM(D16:D23) -> 0 | E15: =SUM(E16:E23) -> 0 | F15: =SUM(F16:F23) -> 0 | G15: =SUM(G16:G23) -> 0
A16: AJ | B16: Terrains (1) | D16: 0 | F16: =D16-E16 -> 0 | G16: 0
B17: (1) dont Placement en Net………../…………
A18: AK | B18: Bâtiments | D18: 0 | E18: 0 | F18: =D18-E18 -> 0 | G18: 0
B19: (1) dont Placement en Net…........./…...…........
A20: AL | B20: Aménagements, agencements et installations | D20: 0 | E20: 0 | F20: =D20-E20 -> 0 | G20: 0
A21: AM | B21: Matériel, mobilier et actifs biologiques | D21: 0 | E21: 0 | F21: =D21-E21 -> 0 | G21: 0
A22: AN | B22: Matériel de transport | D22: 0 | E22: 0 | F22: 0 | G22: 0
A23: AP | B23: Avances et acomptes versés sur immobilisations | C23: 3 | F23: =D23-E23 -> 0
A24: AQ | B24: IMMOBILISATIONS FINANCIERES | C24: 4 | D24: =SUM(D25:D26) -> 0 | E24: =SUM(E25:E26) -> 0 | F24: =SUM(F25:F26) -> 0 | G24: =SUM(G25:G26) -> 0
A25: AR | B25: Titres de participation | F25: =D25-E25 -> 0
A26: AS | B26: Autres immobilisations financières | D26: 0 | F26: =D26-E26 -> 0 | G26: 0
A27: AZ | B27: TOTAL ACTIF IMMOBILISE | D27: =SUM(D10+D15+D24) -> 0 | E27: =SUM(E10+E15+E24) -> 0 | F27: =SUM(F10+F15+F24) -> 0 | G27: =SUM(G10+G15+G24) -> 0
A28: BA | B28: ACTIF CIRCULANT HAO | C28: 5 | D28: 0 | F28: =D28-E28 -> 0 | G28: 0
A29: BB | B29: STOCKS ET ENCOURS | C29: 6 | D29: 0 | F29: =D29-E29 -> 0 | G29: 0
A30: BG | B30: CREANCES ET EMPLOIS ASSIMILES | D30: =SUM(D31:D33) -> 0 | E30: =SUM(E31:E33) -> 0 | F30: =SUM(F31:F33) -> 0 | G30: =SUM(G31:G33) -> 0
A31: BH | B31: Fournisseurs avances versées | C31: 17 | D31: 0 | F31: =D31-E31 -> 0
A32: BI | B32: Clients | C32: 7 | D32: 0 | F32: =D32-E32 -> 0 | G32: 0
A33: BJ | B33: Autres créances | C33: 8 | D33: 0 | F33: =D33-E33 -> 0 | G33: 0
A34: BK | B34: TOTAL ACTIF CIRCULANT | D34: =D28+D29+D30 -> 0 | E34: =E28+E29+E30 -> 0 | F34: =F28+F29+F30 -> 0 | G34: =G28+G29+G30 -> 0
A35: BQ | B35: Titres de placement | C35: 9 | D35: 0 | E35: 0 | F35: =D35-E35 -> 0 | G35: 0
A36: BR | B36: Valeurs à encaisser | C36: 10 | D36: 0 | E36: 0 | F36: =D36-E36 -> 0 | G36: 0
A37: BS | B37: Banques, chèques postaux, caisse et assimilés | C37: 11 | D37: 0 | F37: 0 | G37: 0
A38: BT | B38: TOTAL TRESORERIE-ACTIF | D38: =SUM(D35:D37) -> 0 | E38: =SUM(E35:E37) -> 0 | F38: =SUM(F35:F37) -> 0 | G38: =SUM(G35:G37) -> 0
A39: BU | B39: Ecart de conversion-Actif | C39: 12 | D39: 0 | E39: 0 | F39: 0 | G39: 0
A40: BZ | B40: TOTAL GENERAL | D40: =SUM(D27+D34+D38+D39) -> 0 | E40: =SUM(E27+E34+E38+E39) -> 0 | F40: =SUM(F27+F34+F38+F39) -> 0 | G40: =SUM(G27+G34+G38+G39) -> 0

Sheet PASSIF
A4: Désignation entité : | D4: Exercice clos le :
A5: Numéro d’identification : | D5: Durée (en mois)
A6: BILAN AU 31 DECEMBRE N
A7: REF | B7: PASSIF | C7: Note | D7: EXERCICE AU | E7: EXERCICE AU
D8: 31/12/N | E8: 31/12/N-1
D9: NET | E9: NET
A10: CA | B10: Capital | C10: 13 | D10: 0 | E10: 0
A11: CB | B11: Apporteurs capital non appelé (-) | C11: 13
A12: CD | B12: Primes liées au capital social | C12: 14
A13: CE | B13: Ecarts de réévaluation | C13: 3e
A14: CF | B14: Réserves indisponibles | C14: 14
A15: CG | B15: Réserves libres | C15: 14
A16: CH | B16: Report à nouveau (+ ou -) | C16: 14 | D16: 0 | E16: 0
A17: CJ | B17: Résultat net de l'exercice (bénéfice + ou perte -) | D17: 0 | E17: 0
A18: CL | B18: Subventions d'investissement | C18: 15
A19: CM | B19: Provisions réglementées | C19: 15 | D19: 0
A20: CP | B20: TOTAL CAPITAUX PROPRES ET RESSOURCES ASSIMILEES | D20: =SUM(D10:D19) -> 0 | E20: =SUM(E10:E19) -> 0
A21: DA | B21: Emprunts et dettes financières diverses | C21: 16 | E21: 0
A22: DB | B22: Dettes de location acquisition | C22: 16
A23: DC | B23: Provisions pour risques et charges | C23: 16
A24: DD | B24: TOTAL DETTES FINANCIERES ET RESSOURCES ASSIMILEES | D24: =SUM(D21:D23) -> 0 | E24: =SUM(E21:E23) -> 0
A25: DF | B25: TOTAL RESSOURCES STABLES | D25: =D20+D24 -> 0 | E25: =E20+E24 -> 0
A26: DH | B26: Dettes circulantes HAO | C26: 5
A27: DI | B27: Clients, avances reçues | C27: 7
A28: DJ | B28: Fournisseurs d'exploitation | C28: 17 | D28: 0 | E28: 0
A29: DK | B29: Dettes fiscales et sociales | C29: 18 | D29: 0 | E29: 0
A30: DM | B30: Autres dettes | C30: 19 | D30: 0 | E30: 0
A31: DN | B31: Provisions pour risques à court terme | C31: 19
A32: DP | B32: TOTAL PASSIF CIRCULANT | D32: =SUM(D26:D31) -> 0 | E32: =SUM(E26:E31) -> 0
A33: DQ | B33: Banques, crédits d'escompte | C33: 20 | D33: 0 | E33: 0
A34: DR | B34: Banques, établissements financiers et crédits de trésorerie | C34: 20 | D34: 0 | E34: 0
A35: DT | B35: TOTAL TRESORERIE-PASSIF | D35: =D33+D34 -> 0 | E35: =E33+E34 -> 0
A36: DV | B36: Ecart de conversion-Passif | C36: 12 | D36: 0 | E36: 0
A37: DZ | B37: TOTAL GENERAL | D37: =SUM(D25+D32+D35+D36) -> 0 | E37: =SUM(E25+E32+E35+E36) -> 0

Sheet Compte de Résultat
A3: Désignation entité : | D3: Exercice clos le
A4: Numéro d’identification : | D4: Durée (en mois)
A5: COMPTE DE RESULTAT AU 31 DECEMBRE N
A6: REF | B6: LIBELLES | D6: NOTE | E6: EXERCICE AU 31/12/N | F6: EXERCICE AU 31/12/N-1
E8: NET | F8: NET
A9: TA | B9: Ventes de marchandises A | C9: + | D9: 21 | E9: 0 | F9: 0
A10: RA | B10: Achats de marchandises | C10: - | D10: 22 | E10: 0 | F10: 0
A11: RB | B11: Variation de stocks de marchandises | C11: -/+ | D11: 6 | E11: 0 | F11: 0
A12: XA | B12: MARGE COMMERCIALE (Somme TA à RB) | E12: =E9-E10-E11 -> 0 | F12: =F9-F10-F11 -> 0
A13: TB | B13: Ventes de produits fabriqués B | C13: + | D13: 21 | E13: 0 | F13: 0
A14: TC | B14: Travaux, services vendus C | C14: + | D14: 21 | E14: 0 | F14: 0
A15: TD | B15: Produits accessoires D | C15: + | D15: 21 | E15: 0 | F15: 0
A16: XB | B16: CHIFFRE D'AFFAIRES (A + B + C + D) | E16: =E9+E13+E14+E15 -> 0 | F16: =F9+F13+F14+F15 -> 0
A17: TE | B17: Production stockée (ou déstockage) | C17: -/+ | D17: 6
A18: TF | B18: Production immobilisée | D18: 21
A19: TG | B19: Subventions d’exploitation | D19: 21
A20: TH | B20: Autres produits | C20: + | D20: 21 | E20: 0 | F20: 0
A21: TI | B21: Transferts de charges d'exploitation | C21: + | D21: 12
A22: RC | B22: Achats de matières premières et fournitures liées | C22: - | D22: 22
A23: RD | B23: Variation de stocks de matières premières et fournitures liées | C23: -/+ | D23: 6
A24: RE | B24: Autres achats | C24: - | D24: 22 | E24: 0 | F24: 0
A25: RF | B25: Variation de stocks d’autres approvisionnements | C25: -/+ | D25: 6
A26: RG | B26: Transports | C26: - | D26: 23 | E26: 0 | F26: 0
A27: RH | B27: Services extérieurs | C27: - | D27: 24 | E27: 0 | F27: 0
A28: RI | B28: Impôts et taxes | C28: - | D28: 25 | E28: 0 | F28: 0
A29: RJ | B29: Autres charges | C29: - | D29: 26 | E29: 0 | F29: 0
A30: XC | B30: VALEUR AJOUTEE (XB +RA+RB) + (somme TE à RJ) | E30: =E16-E10-E11+E17+E18+E19+E20+E21-E22-E23-E24-E25-E26-E27-E28-E29 -> 0 | F30: =F16-F10-F11+F17+F18+F19+F20+F21-F22-F23-F24-F25-F26-F27-F28-F29 -> 0
A31: RK | B31: Charges de personnel | C31: - | D31: 27 | E31: 0 | F31: 0
A32: XD | B32: EXCEDENT BRUT D'EXPLOITATION (XC+RK) | D32: 28 | E32: =E30-E31 -> 0 | F32: =F30-F31 -> 0
A33: TJ | B33: Reprises d’amortissements, provisions et dépréciations | C33: + | D33: 28
A34: RL | B34: Dotations aux amortissements, aux provisions et dépréciations | C34: - | D34: 3C&28 | E34: 0 | F34: 0
A35: XE | B35: RESULTAT D'EXPLOITATION (XD+TJ+ RL) | E35: =E32+E33-E34 -> 0 | F35: =F32+F33-F34 -> 0
A36: TK | B36: Revenus financiers et assimilés | C36: + | D36: 29 | E36: 0 | F36: 0
A37: TL | B37: Reprises de provisions et dépréciations financières | C37: + | D37: 28
A38: TM | B38: Transferts de charges financières | C38: + | D38: 12
A39: RM | B39: Frais financiers et charges assimilées | C39: - | D39: 29 | E39: 0 | F39: 0
A40: RN | B40: Dotations aux provisions et aux dépréciations financières | C40: - | D40: 3C&28
A41: XF | B41: RESULTAT FINANCIER (somme TK à RN) | E41: =E36+E37+E38-E39-E40 -> 0 | F41: =F36+F37+F38-F39-F40 -> 0
A42: XG | B42: RESULTAT DES ACTIVITES ORDINAIRES (XE+XF) | E42: =E35+E41 -> 0 | F42: =F35+F41 -> 0
A43: TN | B43: Produits des cessions d'immobilisations | C43: + | D43: 3D
...

Sheet TFT
B5: Désignation entité : | G5: Exercice clos le
B6: Numéro d’identification : | G6: Durée (en mois)
B8: TABLEAU DES FLUX DE TRESORERIE AU 31 DECEMBRE N
B9: REF | C9: LIBELLES | G9: Note | H9: EXERCICE | I9: EXERCICE
H10: N | I10: N-1
B11: ZA | C11: Trésorerie nette au 1er janvier | F11: A
C12: (Trésorerie actif N-1 - Trésorerie passif N-1)
C13: Flux de trésorerie provenant des activités opérationnelles
B14: FA | C14: Capacité d'Autofinancement Globale (CAFG) | H14: 0
B15: FB | C15: - Variation Actif circulant HAO (1) | H15: 0
B16: FC | C16: - Variation des stocks | H16: 0
B17: FD | C17: - Variation des créances | H17: 0
B18: FE | C18: + Variation du passif circulant (1) | H18: 0
C19: Variation du BF lié aux activités opérationnelles (FB+FC+FD+FE) : | D19: =SUM(H15:H18) -> 0 | E19: =SUM(I15:I18) -> 0
B20: ZB | C20: Flux de trésorerie provenant des activités opérationnelles (somme FA à FE) | F20: B | H20: =H14+H15+H16+H17+H18 -> 0
C21: Flux de trésorerie provenant des activités d’investissements
B22: FF | C22: - Décaissements liés aux acquisitions d'immobilisations incorporelles
B23: FG | C23: - Décaissements liés aux acquisitions d'immobilisations corporelles | H23: 0
B24: FH | C24: - Décaissements liés aux acquisitions d'immobilisations financières
B25: FI | C25: + Encaissements liés aux cessions d’immobilisations incorporelles et corporelles
B26: FJ | C26: + Encaissements liés aux cessions d’immobilisations financières
B27: ZC | C27: Flux de trésorerie provenant des activités d’investissement (somme FF à FJ) | F27: C | H27: =-H22-H23-H24+H25+H26 -> 0
C28: Flux de trésorerie provenant du financement par les capitaux propres
B29: FK | C29: + Augmentations de capital par apports nouveaux
B30: FL | C30: + Subventions d'investissement reçues | H30: 0
B31: FM | C31: - Prélèvements sur le capital
B32: FN | C32: - Dividendes versés
B33: ZD | C33: Flux de trésorerie provenant des capitaux propres (somme FK à FN) | F33: D | H33: =SUM(H29:H32) -> 0
C34: Trésorerie provenant du financement par les capitaux étrangers
B35: FO | C35: + Emprunts
B36: FP | C36: + Autres dettes financières
B37: FQ | C37: - Remboursements des emprunts et autres dettes financières | H37: 0
B38: ZE | C38: Flux de trésorerie provenant des capitaux étrangers (somme FO à FQ) | F38: E | H38: =H35+H36-H37 -> 0
B39: ZF | C39: Flux de trésorerie provenant des activités de financement (D+E) | F39: F | H39: =H33+H38 -> 0
B40: ZG | C40: VARIATION DE LA TRÉSORERIE NETTE DE LA PÉRIODE (B+C+F) | F40: G | H40: =H20+H27+H39 -> 0
B41: ZH | C41: Trésorerie nette au 31 Décembre (G+A) | F41: H | H41: =H11+H40 -> 0
C42: Contrôle : Trésorerie actif N - Trésorerie passif N =
B43: [1] à l’exclusion des variations des créances et dettes liées aux activités d’investissement (variation des créances sur cession d’immobilisation et des dettes sur acquisition ou production d’immobilisation) et de financement (par exemple variation des créances sur subventions d’investissements reçues).

Sheet NOTE 1
A5: Désignation entité : | D5: Exercice clos le
A6: Numéro d’identification : | D6: Durée (en mois)
A8: DETTES GARANTIES PAR DES SURETES REELLES
A9: LIBELLES | B9: Note | C9: Montant brut | D9: SURETES REELLES
D10: Hypothèques | E10: Nantissements | F10: Gages/ autres
A12: Dettes financières et ressources assimilées :
A13: Emprunts obligataires convertibles
A14: Autres emprunts obligataires
A15: Emprunts et dettes des établissements de crédit
A16: Autres dettes financières
A17: SOUS TOTAL (1)
A19: Dettes de location-acquisition :
A20: Dettes de crédit-bail immobilier
A21: Dettes de crédit-bail mobilier
A22: Dettes sur contrats de location-vente
A23: Dettes sur contrats de location-acquisition
A24: SOUS TOTAL (2)
... A36: TOTAL (1) + (2) + (3)
A37: ENGAGEMENTS FINANCIERS | E37: Engagements donnés | F37: Engagements reçus
A38: Engagements consentis à des entités liées
A39: Primes de remboursement non échues
A40: Avals, cautions, garanties
A41: hypothèques, nantissements, gages, autres
A42: Effets escomptés non échus
A43: Créances commerciales et professionnelles cédées
A44: Abandons de créances conditionnels
A45: TOTAL
A46: Commentaire :
A47: • Indiquer la raison d'être des suretés.

Sheet NOTE 2
B5: Désignation entité : | E5: Exercice clos le
B6: Numéro d’identification : | E6: Durée (en mois)
B8: NOTE 2
B9: INFORMATIONS OBLIGATOIRES
B10: A - DECLARATION DE CONFORMITE AU SYSCOHADA
B13: B - REGLES ET METHODES COMPTABLES
B16: C- DEROGATION AUX POSTULATS ET CONVENTIONS COMPTABLES
B18: D - INFORMATIONS COMPLEMENTAIRES RELATIVES AU BILAN, AU COMPTE DE
B19: RESULTAT ET AU TABLEAU DES FLUX DE TRESORERIE

Sheet NOTE 3A
A5: Désignation entité : | E5: Exercice clos le
A6: Numéro d’identification : | E6: Durée (en mois)
B8: NOTE 3A
A9: IMMOBILISATION BRUTE
A11: SITUATIONS ET MOUVEMENTS | B11: MONTANT | C11: Acquisitions | D11: Virements | E11: Suite à une | F11: Cessions | G11: Virements | H11: MONTANT
B12: BRUT A | C12: Apports | D12: de | E12: réévaluation | F12: Scissions | G12: de | H12: BRUT A LA
A13: RUBRIQUES | B13: L'OUVERTURE DE | C13: Créations | D13: poste à poste | E13: Pratiquée au cours | F13: Hors service | G13: poste à | H13: CLOTURE DE
B14: L’EXERCICE | E14: de l’exercice | G14: poste | H14: L’EXERCICE
A15: IMMOBILISATIONS INCORPORELLES | B15: =SUM(B16:B19) -> 0 | C15: =SUM(C16:C19) -> 0 | D15: =SUM(D16:D19) -> 0 | E15: =SUM(E16:E19) -> 0 | F15: =SUM(F16:F19) -> 0 | G15: =SUM(G16:G19) -> 0 | H15: =SUM(H16:H19) -> 0
A16: Frais de développement et de prospection | H16: =B16+C16+D16+E16-F16-G16 -> 0
A17: Brevets, licences, logiciels, et droits similaires | H17: =B17+C17+D17+E17-F17-G17 -> 0
A18: Fonds commercial et droit au bail | H18: =B18+C18+D18+E18-F18-G18 -> 0
A19: Autres immobilisations incorporelles | H19: =B19+C19+D19+E19-F19-G19 -> 0
A20: IMMOBILISATIONS CORPORELLES | B20: =SUM(B22:B27) -> 0 | C20: =SUM(C22:C27) -> 0 | D20: =SUM(D22:D27) -> 0 | E20: =SUM(E22:E27) -> 0 | F20: =SUM(F22:F27) -> 0 | G20: =SUM(G22:G27) -> 0 | H20: =SUM(H22:H27) -> 0
A21: Terrains hors immeuble de placement | H21: =B21+C21+D21+E21-F21-G21 -> 0
A22: Terrains - immeuble de placement | H22: =B22+C22+D22+E22-F22-G22 -> 0
A23: Bâtiments hors immeuble de placement | H23: =B23+C23+D23+E23-F23-G23 -> 0
A24: Bâtiments - immeuble de placement | H24: =B24+C24+D24+E24-F24-G24 -> 0
A25: Aménagements, agencements et installations | H25: =B25+C25+D25+E25-F25-G25 -> 0
A26: Matériel, mobilier et actifs biologiques | H26: =B26+C26+D26+E26-F26-G26 -> 0
A27: Matériel de transport | H27: =B27+C27+D27+E27-F27-G27 -> 0
A28: AVANCES ET ACOMPTES VERSES SUR IMMOBILISATIONS | D28: =SUM(D29:D30) -> 0 | E28: =SUM(E29:E30) -> 0 | F28: =SUM(F29:F30) -> 0 | G28: =SUM(G29:G30) -> 0 | H28: =SUM(H29:H30) -> 0
A29: Immobilisations incorporelles | H29: =B29+C29+D29+E29-F29-G29 -> 0
A30: Immobilisations corporelles | H30: =B30+C30+D30+E30-F30-G30 -> 0
A31: IMMOBILISATIONS FINANCIERES | B31: =SUM(B32:B33) -> 0 | C31: =SUM(C32:C33) -> 0 | D31: =SUM(D32:D33) -> 0 | E31: =SUM(E32:E33) -> 0 | F31: =SUM(F32:F33) -> 0 | G31: =SUM(G32:G33) -> 0 | H31: =SUM(H32:H33) -> 0
A32: Titres de participation | H32: =B32+C32+D32+E32-F32-G32 -> 0
A33: Autres immobilisations financières | H33: =B33+C33+D33+E33-F33-G33 -> 0
A34: TOTAL GENERAL | B34: =B15+B20+B28+B31 -> 0 | C34: =C15+C20+C28+C31 -> 0 | D34: =D15+D20+D28+D31 -> 0 | E34: =E15+E20+E28+E31 -> 0 | F34: =F15+F20+F28+F31 -> 0 | G34: =G15+G20+G28+G31 -> 0 | H34: =H15+H20+H28+H31 -> 0
A36: Commentaire :
A37: • Toute variation significative doit être commentée. • Détailler les éléments constitutifs du fonds commercial et indiquer la date d'acquisition. • Pour l'immobilisation incorporelle relative à la concession faire un descriptif de l'accord. Indiquer : - la nature de la créance ; - la durée de la concession ; - l'échéance. • Indiquer les créances du groupe avec nature et date d'échéance. • Pour les banques, DAT indiquer le nom de la banque le montant et la date d'échéance.

Sheet NOTE 3B
A5: Désignation entité : | E5: Exercice clos le
A6: Numéro d’identification : | E6: Durée (en mois)
A8: NOTE 3B
A9: BIENS PRIS EN LOCATION ACQUISITION
A10: SITUATIONS ET MOUVEMENTS | B10: NATURE | C10: A | D10: AUGMENTATIONS B | G10: DIMINUTIONS C | I10: D = A + B - C
B11: DU CONTRAT
B12: (I ; M ; A)
B13: [1]
C15: MONTANT | D15: Acquisitions | E15: Virements de | F15: Suite à une | G15: Cessions | H15: Virements de | I15: MONTANT
C16: BRUT A | D16: Apports | E16: poste à poste | F16: Réévaluation | G16: Scissions | H16: poste à | I16: BRUT A LA
C17: L'OUVERTURE | D17: Créations | F17: Pratiquée | G17: Hors service | H17: poste | I17: CLOTURE DE
C18: DE L'EXERCICE | F18: au cours | I18: L'EXERCICE
A19: RUBRIQUES | C19: L'EXERCICE | F19: de l'exercice
A20: Brevets, licences, logiciels et droits similaires
A21: Fonds commercial et droit au bail
A22: Autres immobilisations incorporelles
A23: SOUS TOTAL : IMMOBILISATIONS INCORPORELLES | C23: =SUM(C20:C22) -> 0
A24: Terrains | I24: =SUM(C24:H24) -> 0
A25: Bâtiments | I25: =SUM(C25:H25) -> 0
A26: Aménagements, agencements et installations | I26: =SUM(C26:H26) -> 0
A27: Matériel, mobilier et actifs biologiques | I27: =SUM(C27:H27) -> 0
A28: Matériel de transport | I28: =SUM(C28:H28) -> 0
A29: SOUS TOTAL : IMMOBILISATIONS CORPORELLES | C29: =SUM(C24:C28) -> 0
A31: TOTAL GENERAL | C31: =+C29+C23 -> 0
A33: [1] I : Crédit-bail immobilier ; M : Crédit-bail mobilier ; A : Autres contrats (dédoubler le poste si montants significatifs)
A35: Commentaire :
A36: Indiquer la nature du bien, le nom du bailleur et la durée du bail.

Sheet NOTE 3C
A5: Désignation entité : | E5: Exercice clos le
A6: Numéro d’identification : | E6: Durée (en mois)
A8: NOTE 3C
A9: IMMOBILISATION (AMORTISSEMENTS)
A11: SITUATIONS ET MOUVEMENTS | B11: A | C11: B | E11: DIMINUTIONS : Amortissements relatifs aux éléments sortis de l’actif | F11: E= A + B +C-D
D13: C
A14: RUBRIQUES | B14: AMORTISSEMENTS CUMULES A L’OUVERTURE DE L’EXERCICE | C14: AUGMENTATIONS : DOTATIONS DE l’EXERCICE | D14: COMPLEMENT D AMORTISSEMENT | E14: DIMINUTIONS : Amortissements relatifs aux éléments sortis de l’actif | F14: CUMUL DES AMORTISSEMENTS A LA CLOTURE DE L’EXERCICE
A15: Frais de développement et de prospection | F15: =B15+C15-E15 -> 0
A16: Brevets, licences, logiciels et droits similaires | F16: =B16+C16-E16 -> 0
A17: Fonds commercial et droit au bail | F17: =B17+C17-E17 -> 0
A18: Autres immobilisations incorporelles | F18: =B18+C18-E18 -> 0
A19: SOUS TOTAL : IMMOBILISATIONS INCORPORELLES | B19: =SUM(B15:B18) -> 0 | C19: =SUM(C15:C18) -> 0 | E19: =SUM(E15:E18) -> 0 | F19: =SUM(F15:F18) -> 0
A20: Terrains hors immeuble de placement | F20: =B20+C20-E20 -> 0
A21: Terrains-immeuble de placement | F21: =B21+C21-E21 -> 0
A22: Bâtiments hors immeuble de placement | F22: =B22+C22-E22 -> 0
A23: Bâtiments-immeuble de placement | B23: 0 | C23: 0 | F23: =B23+C23-E23 -> 0
A24: Aménagements, agencements et installations | B24: 0 | C24: 0 | F24: =B24+C24-E24 -> 0
A25: Matériel, mobilier et actifs biologiques | B25: 0 | C25: 0 | F25: =B25+C25-E25 -> 0
A26: Matériel de transport | B26: 0 | C26: 0 | F26: 0
A27: SOUS TOTAL : IMMOBILISATIONS CORPORELLES | B27: =SUM(B20:B26) -> 0 | C27: =SUM(C20:C26) -> 0 | E27: =SUM(E20:E26) -> 0 | F27: =SUM(F20:F26) -> 0
A29: TOTAL GENERAL | B29: =B27+B19 -> 0 | C29: =C27+C19 -> 0 | E29: =E27+E19 -> 0 | F29: =F27+F19 -> 0
A31: Commentaire :
A32: • Indiquer - les modes d'amortissement utilisés ; - la durée de vie ou les taux d'amortissements utilisés.

Sheet NOTE 3D
B1: NOTE 3D : IMMOBILISATIONS (PLUS-VALUES ET MOINS VALUE DE CESSION)
B6: Désignation entité : | E6: Exercice clos le
B7: Numéro d’identification : | E7: Durée (en mois)
B9: NOTE 3D
B10: IMMOBILISATIONS : PLUS-VALUES ET MOINS VALUE DE CESSION
C11: MONTANT | D11: AMORTISSEMENTS | E11: VALEUR | F11: PRIX | G11: PLUS-VALUE
C12: BRUT | D12: PRATIQUES | E12: COMPTABLE | F12: DE | G12: OU MOINS-VALUE
E13: NETTE | F13: CESSION
C14: A | D14: B | E14: C = A - B | F14: D | G14: E = D - C
B15: Frais de développement et de prospection
B16: Brevets, licences, logiciels et droits similaires
B17: Fonds commercial et droit au bail
B18: Autres immobilisations incorporelles
B19: SOUS TOTAL : IMMOBILISATIONS INCORPORELLES
B20: Terrains
B21: Bâtiments
B22: Aménagements, agencements et installations
B23: Matériel, mobilier et actifs biologiques
B24: Matériel de transport
B25: SOUS TOTAL : IMMOBILISATIONS CORPORELLES
B26: Titres de participations
... B33: . Mentionner la justification de la cession ainsi que la date et la date de sortie.

Sheet NOTE 3E
B2: NOTE 3D : IMMOBILISATIONS (PLUS-VALUES ET MOINS VALUE DE CESSION)
B7: Désignation entité : | C7: Exercice clos le
B8: Numéro d’identification : | C8: Durée (en mois)
B9: NOTE 3E : INFORMATIONS SUR LES REEVALUATIONS EFFECTUEES
B10: NOTE 3E
B11: INFORMATIONS SUR LES REEVALUATIONS EFFECTUEES PAR L'ENTITE
B12: Nature et date des réévaluations :
B16: Eléments réévalués par postes du bilan | C16: Montants coûts historiques | D16: Amortissements supplémentaires
B25: Méthode de réévaluation utilisée :
B31: Traitement fiscal de l'écart de réévaluation et des amortissements supplémentaires :
B37: Montant de l'écart incorporé au capital :

Sheet NOTE 4
A6: Désignation entité : | E6: Exercice clos le
A7: Numéro d’identification : | E7: Durée (en mois)
A9: NOTE 4
A10: IMMOBILISATIONS FINANCIERES
A11: Libellés | B11: Année N | C11: Année N-1 | D11: Variation en % | E11: Créances à un an au plus | F11: Créances à plus d'un an et à | G11: Créances à plus de deux ans
F12: deux ans au plus
A13: Titres de participation
A14: Prêts et créances
A15: Prêt au personnel
A16: Créances sur l'état
A17: Titres immobilisés
A18: Dépôts et cautionnements | B18: =ACTIF!D26 -> 0 | C18: =ACTIF!G26 -> 0 | D18: =B18-C18 -> 0 | E18: 0 | F18: 0 | G18: =C18 -> 0
A19: Intérêts courus
A20: TOTAL BRUT | B20: =SUM(B13:B19) -> 0 | C20: =SUM(C13:C19) -> 0 | D20: =SUM(D13:D19) -> 0 | E20: =SUM(E13:E19) -> 0 | F20: =SUM(F13:F19) -> 0 | G20: =SUM(G13:G19) -> 0
A21: Dépréciations titres de participation
A22: Dépréciations autres immobilisations
A23: TOTAL NET DE DEPRECIATION
A24: Liste des filiales et participations :
A25: Dénomination sociale | B25: Localisation (ville / pays) | D25: Valeur d'acquisition | E25: % Détenu | F25: Montant des | G25: Résultat dernier
F26: capitaux propres filiale | G26: exercice filiale
A33: Commentaire :
A34: • Justifier toute variation significative.
A35: • Commenter toutes les créances anciennes.
A36: • Pour les créances relatives à la concession, faire un descriptif de l'accord.
A37: • Indiquer :
A38: - la nature de la créance ;
A39: - la durée de la concession ;
A40: - l'échéance.
A41: • Indiquer le nombre et la date d'acquisition des actions ou parts propres.
A42: • Dépréciation : indiquer les évènements et les circonstances qui ont motivé la dépréciation ou la reprise.

Sheet NOTE 5
A6: Désignation entité : | C6: Exercice clos le
A7: Numéro d’identification : | C7: Durée (en mois)
A10: NOTE 5
A11: ACTIF CIRCULANT HAO
A13: Libellés | C13: Année N | D13: Année N-1 | E13: Variation en %
A14: Créances sur cessions d'immobilisations | C14: 0 | D14: 0 | E14: 0
A15: Autres créances hors activités ordinaires
A16: TOTAL BRUT
A17: Dépréciations des créances HAO
A19: TOTAL NET DE DEPRECIATION
A20: Commentaire:
A21: • Commenter toute variation significative.
A22: • Dépréciation : indiquer les évènements et les circonstances qui ont motivé la dépréciation ou la reprise.
A25: DETTES CIRCULANTES HAO
A26: Libellés | C26: Année N | D26: Année N-1 | E26: Variation en %
A27: Fournisseurs d'investissements
A28: Fournisseurs d'investissements effets à payer
A29: Versements restant à effectuer sur titres de participation et titres immobilisés non libérés
A30: Autres dettes hors activités ordinaires
A31: TOTAL
A33: Commentaire :
A35: • Indiquer la date de cession et la nature de l'immobilisation achetée et/ou cédée.
A36: • Expliciter toute variation significative.

Sheet NOTE 6
B6: Désignation entité : | C6: Exercice clos le
B7: Numéro d’identification : | C7: Durée (en mois)
B9: NOTE 6
B10: STOCKS ET EN COURS (1)
B11: Libellés | C11: Année N | D11: Année N-1 | E11: Variation en %
B12: Marchandises | C12: =+ACTIF!F29 -> 0 | D12: =+ACTIF!G29 -> 0 | E12: =+(C12-D12)/D12 -> #DIV/0!
B13: Matières premières et fournitures liées
B14: Autres approvisionnements
B15: Produits en cours
B16: Services en cours
B17: Produits finis
B18: Produits intermédiaires
B19: Stocks en cours de route, en consignation ou en dépôt
B20: TOTAL BRUT STOCKS ET EN COURS | C20: =SUM(C12:C19) -> 0 | D20: =SUM(D12:D19) -> 0 | E20: =+(C20-D20)/D20 -> #DIV/0!
B22: Dépréciations des stocks
B24: TOTAL NET DE DEPRECIATION | C24: =C20 -> 0 | D24: =D20 -> 0 | E24: =E20 -> #DIV/0!
B25: (1) Les stocks H.A.O. seront inscrits dans l'actif circulant H.A.O. que lorsque leur montant total est significatif (supérieur à 5 % du total de l'actif circulant).
B27: Commentaire :
B28: • Indiquer la date de prise d'inventaire et décrire brièvement la procédure, les méthodes comptables adoptées pour évaluer le stock.
B29: • Commenter toute variation significative des stocks.
B30: • Indiquer le détail des stocks dépréciés et les évènements et circonstances qui ont conduit à la dépréciation et à la reprise.

Sheet NOTE 7
A4: Désignation entité : | E4: Exercice clos le
A5: Numéro d’identification : | E5: Durée (en mois)
A6: NOTE 7
A7: CLIENTS
A8: Libellés | B8: Année N | C8: Année N-1 | D8: Variation en % | E8: Créances à un an au plus | F8: Créances à plus | G8: Créances à plus de deux ans
F9: d'un an
F10: et à deux
F11: ans au plus
A12: Clients (hors réserves de propriété Groupe) | B12: =ACTIF!F32 -> 0 | C12: =+ACTIF!G32 -> 0 | D12: =(B12-C12)/C12 -> #DIV/0! | E12: =B12 -> 0
A13: Clients effets à recevoir (hors réserves de propriété groupe)
A14: Clients et effets à recevoir avec réserves de propriété
A15: Clients et effets à recevoir Groupe
A16: Créances sur cession d'immobilisations
A17: Clients effets escomptés et non échus
A18: Créances litigieuses ou douteuses
A19: Clients produits à recevoir
A20: TOTAL BRUT CLIENTS | B20: =SUM(B12:B19) -> 0 | C20: =SUM(C12:C19) -> 0 | D20: =SUM(D12:D19) -> #DIV/0! | E20: =SUM(E12:E19) -> 0 | F20: =SUM(F12:F19) -> 0 | G20: =SUM(G12:G19) -> 0
A22: Dépréciations des comptes clients
A24: TOTAL NET DE DEPRECIATION | B24: =B20 -> 0 | C24: =C20 -> 0 | D24: =D20 -> #DIV/0! | E24: =E20 -> 0
A26: Clients, avances reçues hors groupe
A27: Clients, avances reçues groupe
A28: Autres clients créditeurs
A29: TOTAL CLIENTS CREDITEURS
A30: Commentaire :
A31: • Commenter toutes variations significatives. • Indiquer pour les créances du groupe, le nom de la société du groupe et le % de titres détenus. • Commenter les créances anciennes. • Indiquer les événements et circonstances qui ont conduit à la dépréciation et à la reprise.

Sheet NOTE 8
A5: Désignation entité : | E5: Exercice clos le
A6: Numéro d’identification : | E6: Durée (en mois)
A8: NOTE 8
A9: AUTRES CREANCES
A10: Libellés | B10: Année N | C10: Année N-1 | D10: Variation en % | E10: Créances à un an au plus | F10: Créances à plus | G10: Créances à plus de deux ans
F11: d'un an
F12: et à deux
F13: ans au plus
A14: Personnel
A15: Organismes sociaux
A16: Etat et Collectivités publiques
A17: Organismes internationaux
A18: Apporteurs, associés et groupe
A19: Compte transitoire ajustement spécial lié à la révision du SYSCOHADA
A20: Autres débiteurs divers | B20: 0 | C20: 0 | E20: =B20 -> 0
A21: Comptes permanents non bloqués des établissements et des succursales
A22: Comptes de liaison charges et produits
A23: Comptes de liaison des sociétés en participation
A24: TOTAL BRUT AUTRES CREANCES | B24: =SUM(B14:B23) -> 0 | C24: =SUM(C14:C23) -> 0 | D24: =SUM(D14:D23) -> 0 | E24: =SUM(E14:E23) -> 0 | F24: =SUM(F14:F23) -> 0 | G24: =SUM(G14:G23) -> 0
A26: Dépréciations des autres créances
A28: TOTAL NET DE DEPRECIATION | B28: =B24 -> 0 | C28: =C24 -> 0 | D28: =D24 -> 0 | E28: =E24 -> 0
A30: Commentaire :
A31: • Justifier toute variation significative.
A32: • Détailler les créances dont le montant est significatif.
A33: • Justifier les créances anciennes.
A34: • Indiquer les événements et circonstances qui ont conduit à la dépréciation et à la reprise.
A35: • Compte transitoire ajustement spécial, indiquer le détail du compte et la durée restant pour l'apurement.

Sheet NOTE 8A
A4: NOTE 8A: TABLEAU D’ETALEMENT DES CHARGES IMMOBILISEES
A6: Désignation entité : | E6: Exercice clos le
A7: Numéro d’identification : | E7: Durée (en mois)
A9: NOTE 8A
A10: TABLEAU D’ETALEMENT DES CHARGES IMMOBILISEES
A11: Libellés | B11: Frais d'établissement | D11: Charges à repartir sur plusieurs exercices | F11: Primes de remboursement des obligations
A12: Montant global à étaler au 1er janvier 2018
A13: Durée d'étalement retenue
A14: Exercice 2018 | B14: Comptes | C14: Montants | D14: Comptes | E14: Montants | F14: Comptes | G14: Montants
B15: 60... | D15: 60... | F15: 6714
B16: 61... | D16: 61...
B17: 62... | D17: 62...
B18: 63... | D18: 63...
B19: ... | D19: ...
A20: Total exercice 2018
A21: Total exercice 2019
A22: Total exercice 2020
A23: Total exercice 2021
A24: Total exercice 2022
A25: TOTAL GENERAL

Sheet NOTE 9
A4: Désignation entité : | B4: Exercice clos le
A5: Numéro d’identification : | B5: Durée (en mois)
A7: NOTE 9
A8: TITRES DE PLACEMENT
A9: Libellés | B9: Année N | C9: Année | D9: Variation en %
C10: N-1
A11: Titres de trésor et bons de caisse à court terme
A12: Actions
A13: Obligations
A14: Bons de souscription
A15: Titres négociables hors régions
A16: Intérêts courus
A17: Autres valeurs assimilés
A18: TOTAL BRUT TITRES
A19: Dépréciations des titres
A21: TOTAL NET DE DEPRECIATION
A22: Commentaires:
A23: • Justifier toute variation significative.
... A26: • Indiquer les événements et circonstances qui ont conduit à la dépréciation et à la reprise.

Sheet NOTE 10
A4: Désignation entité : | C4: Exercice clos le
A5: Numéro d’identification : | C5: Durée (en mois)
A7: NOTE 10
A8: VALEURS A ENCAISSER
A9: Libellés | B9: Année N | C9: Année N-1 | D9: Variation en %
A10: Effets à encaisser
A11: Effets à l'encaissement
A12: Chèques à encaisser
A13: Chèques à l'encaissement
A14: Cartes de crédit à encaisser
A15: Autres valeurs à encaisser
A16: TOTAL BRUT VALEURS A ENCAISSER
A17: Dépréciations des valeurs à encaisser
A19: TOTAL NET DE DEPRECIATION
A20: Commentaires :
A21: • Commenter toute variation significative ;
A22: • Indiquer les événements et circonstances qui ont conduit à la dépréciation et à la reprise.

Sheet NOTE 11
B3: NOTE 11 : BANQUES, CHEQUES POSTAUX ET CHEQUES
B5: Désignation entité : | C5: Exercice clos le
B6: Numéro d’identification : | C6: Durée (en mois)
B8: NOTE 11
B9: DISPONIBILITES
B10: Libellés | C10: Année N | D10: Année | E10: Variation
D11: N-1 | E11: en %
B12: Banques locales | C12: 0 | D12: 0 | E12: =(C12-D12)/D12 -> #DIV/0!
B13: Banques autres états région
B14: Banques, dépôt à terme
B15: Autres Banques
B16: Banques intérêts courus
B17: Chèques postaux
B18: Autres établissement financiers
B19: Etablissement financiers intérêts courus
B20: Instruments de trésorerie
B21: Caisse | C21: 0 | D21: 0
B22: Caisse électronique mobile
B23: Régies d'avances et virements accréditifs
B24: TOTAL BRUT DISPONIBILITES | C24: =SUM(C12:C23) -> 0 | D24: =SUM(D12:D23) -> 0 | E24: =(C24-D24)/D24 -> #DIV/0!
B25: Dépréciations
B27: TOTAL NET DE DEPRECIATIONS | C27: =C24 -> 0 | D27: =D24 -> 0 | E27: =E24 -> #DIV/0!
B28: Commentaires :
B29: • Indiquer la date de rapprochement des comptes bancaires.
B30: • Indiquer la date d'inventaire de la caisse et des instruments de monnaie électronique.
B31: • Justifier toute variation significative.
B32: • Détailler les instruments de monnaie électronique si le montant est significatif.
B33: • Indiquer les événements et circonstances qui ont conduit à la dépréciation et à la reprise.
B34: NB : Banques et intérêts courus et Etablissement financiers intérêts courus figurent dans cette rubrique en négatif si le compte principal attaché est débiteur.

Sheet NOTE 12
A4: Désignation entité : | D4: Exercice clos le
A5: Numéro d’identification : | D5: Durée (en mois)
A7: NOTE 12
A8: ECARTS DE CONVERSION
A9: Libellés | B9: Devises | C9: Montant en devises | D9: Cours | E9: Cours | F9: Variation en valeur absolue
D10: UML | E10: UML
D11: Année acquisition | E11: 43100
A12: Ecarts de conversion actif :
A13: détailler les créances et dettes concernées
A16: Ecart de conversion passif : détailler les créances et dettes concernées
A21: Commentaire:
A22:  Faire un commentaire.
A23: TRANSFERTS DE CHARGES
A24: Libellés | B24: Année N | C24: Année N-1 | D24: Variation en %
A25: Transferts de charges d'exploitation :
A26: détailler la nature des charges transférer
A29: Transferts de charges financières : détailler la nature des charges transférer
A35: Commentaire:
A36: • Faire un commentaire

Sheet NOTE 13
B5: Désignation entité : | E5: Exercice clos le
B6: Numéro d’identification : | E6: Durée (en mois)
B8: NOTE 13
B9: CAPITAL
D10: Valeur nominale des actions ou parts :
B12: Nom et Prénoms | C12: Nationalité | D12: Nature des actions ou parts (ordinaires ou préférences) | E12: Nombre | F12: Montant total | G12: Cessions ou rembourse-ments
G13: en cours
G14: d’exercice
F15: =PASSIF!D10 -> 0 | G15: 0
B23: Apporteurs, capital non appelé
B24: TOTAL | F24: =SUM(F15:F22) -> 0 | G24: =SUM(G15:G22) -> 0
B26: Commentaire :
B28: · Indiquer si possible le montant du capital à la constitution.
B29: · Indiquer si possible les dates des AGE et le montant du capital augmenté en cas d’augmentation de capital.
B30: · Indiquer si possible les dates des AGE et le montant du capital diminué en cas de réduction de capital.
B31: · Indiquer les avantages accordés aux actions de préférence.
B32: · Apporteurs, capital non appelé : indiquer le délai restant pour appeler le capital.

Sheet NOTE 14
B4: Désignation entité : | C4: Exercice clos le
B5: Numéro d’identification : | C5: Durée (en mois)
B7: NOTE 14
B8: PRIMES ET RESERVES
B9: Libellés | C9: Année N | D9: Année N-1 | E9: Variation en valeur absolue
B10: Prime d'apport
B11: Primes d'émission
B12: Prime de fusion
B13: Prime de conversion
B14: Autres primes
B15: TOTAL PRIMES
B17: Réserves légales
B18: Réserves statutaires
B19: Réserves de plus-values nettes à long terme
B20: Réserves d’attribution gratuite d’actions au personnel salarié et aux dirigeants
B21: Autres réserves réglementées
B22: TOTAL RESERVES INDISPONIBLES
B24: Réserves libres
B26: Report à nouveau | C26: =PASSIF!D16 -> 0 | D26: =PASSIF!E16 -> 0 | E26: =(C26-D26)/D26 -> #DIV/0!
B27: Commentaires:
B28: • Indiquer les dates de l'AGE qui a décidé des primes d'apport, d'émission de fusion.
B29: • Indiquer le détail des réserves libres.
B30: • Indiquer le montant restant à doter et le taux de dotation de la réserve légale.
B31: • Indiquer la date de l'AGO qui justifie la variation des réserves et du report à nouveau.

Sheet NOTE 15A
A4: Désignation entité : | E4: Exercice clos le
A5: Numéro d’identification : | E5: Durée (en mois)
A7: NOTE 15 A
A8: TOTAL SUBVENTIONS ET PROVISIONS REGLEMENTEES
A9: Libellés | B9: NOTE | C9: Année N | D9: Année N-1 | E9: Variation en valeur absolue | F9: Variation en % | G9: Régime fiscal | H9: Echéances
A10: État
A11: Régions
A12: Départements
A13: Communes et collectivités publiques décentralisées
A14: Entités publiques ou mixtes
A15: Entités et organismes privés
A16: Organismes internationaux
A17: Autres
A18: TOTAL SUBVENTIONS
A20: Amortissements dérogatoires
A21: Plus-value de cession à réinvestir
A22: Provision spéciale de réévaluation
... A25: Provisions pour investissement
A26: Autres provisions et fonds réglementées | D26: =+[1]PASSIF!E19 -> 0
A27: TOTAL PROVISIONS REGLEMENTEES
A29: TOTAL SUBVENTIONS ET | C29: =C26 -> 0 | D29: =D26 -> 0
A30: PROVISIONS REGLEMENTEES
A32: Commentaire:
A33: Indiquer pour la subvention la date d’octroi, la nature, les obligations éventuelles. Pour les provisions réglementées, indiquer le texte de référence, les obligations. Commenter toute variation significative.

Sheet NOTES 15B
A4: Désignation entité : | E4: Exercice clos le
A5: Numéro d’identification : | E5: Durée (en mois)
A7: NOTE 15 B
A8: AUTRES FONDS PROPRES (1)
A9: Libellés | B9: NOTE | C9: Année N | D9: Année N-1 | E9: Variation en valeur absolue | F9: Variation en % | G9: Echéances
A10: Titres participatifs
A11: Avances conditionnées (1)
A12: Titres subordonnés à durée indéterminée (T.S.D.I.)
A13: Obligations remboursables en actions (O.R.A.)
A14: Autres
A15: TOTAL AUTRES FONDS PROPRES
A16: Commentaire :
A17: (1) Le cas échéant, une rubrique "Autres fonds propres" (montant des émissions de titres participatifs, avances conditionnées, ...) sur une ligne séparée est intercalée entre les rubriques "TOTAL CAPITAUX PROPRES ET RESSOURCES ASSIMILEES" et "emprunts et dettes financières" si le montant des autres fonds propres est significatif.
A18: Commentaires :
A19: * Justifier l'inscription de ces dettes dans une rubrique spécifique du passif du bilan "autres fonds propres" (faible probabilité de remboursement, absence d’échéancier…;
A20: *Justifier le caractère significatif du montant total de cette rubrique Commenter toute variation significative.

Sheet NOTE 16A
A3: Désignation entité : | E3: Exercice clos le
A4: Numéro d’identification : | E4: Durée (en mois)
A5: NOTE 16A
A6: Libellés | B6: Année N | C6: Année N-1 | D6: Variation en valeur absolue | E6: Variation en % | F6: Dettes à un an au plus | G6: Dettes à plus d’un an et à deux ans au plus | H6: Dettes à plus de deux ans
A7: Emprunts obligataires
A8: Emprunts et dettes auprès des établissements de crédit | B8: =+PASSIF!D21 -> 0 | C8: =+PASSIF!E21 -> 0 | D8: =B8-C8 -> 0 | E8: =D8/C8 -> #DIV/0! | F8: =0 -> 0 | H8: =B8-G8 -> 0
A9: Avances reçues de l’Etat
A10: Avances reçues et comptes courants bloqués
A11: Dépôts et cautionnements reçus
A12: Intérêt courus
A13: Avances assorties de conditions particulières
A14: Autres emprunts et dettes | D14: 0 | E14: 0 | G14: 0 | H14: =C14 -> 0
A15: Dettes liées à des participations
A16: Comptes permanents bloqués des établissements et succursales
A17: TOTAL EMPRUNTS ET DETTES FINANCIERES | B17: =SUM(B7:B16) -> 0 | C17: =SUM(C7:C16) -> 0 | D17: =SUM(D7:D16) -> 0 | E17: =SUM(E7:E16) -> #DIV/0! | F17: =SUM(F7:F16) -> 0 | G17: =SUM(G7:G16) -> 0 | H17: =SUM(H7:H16) -> 0
A19: Crédit-bail immobilier
A20: Crédit-bail mobilier
A21: Location-vente
A22: Intérêts courus
A23: Autres dettes de location acquisition
A24: TOTAL DETTES DE LOCATION ACQUISITION
A26: Provisions pour litiges | B26: =PASSIF!D23 -> 0 | C26: =B26 -> 0 | D26: =B26-C26 -> 0 | E26: 0
A27: Provisions pour garantie donnés aux clients
A28: Provisions pour pertes sur marchés à achèvement futur
A29: Provisions pour pertes de change
A30: Provisions pour impôts
A31: Provisions pour pensions et obligations assimilées
A32: Actif du régime de retraite
A33: Provisions pour restructuration
A34: Provisions pour amendes et pénalités
A35: Provisions de propre assureur
A36: Provisions pour démantèlement et remise en état
A37: Provisions de droits à déduction
A38: Autres provisions
A39: TOTAL PROVISIONS POUR RISQUES ET CHARGES | B39: =SUM(B26:B38) -> 0 | C39: =SUM(C26:C38) -> 0 | D39: =SUM(D26:D38) -> 0 | E39: =SUM(E26:E38) -> 0
A40: Commentaire :
A41: Pour chaque emprunt et dette de location acquisition: mentionner la date d'octroi, le nom de l'organisme financier, le montant initial de l'emprunt ou de la dette, la durée du crédit, les garanties données par la société. Indiquer les événements et circonstances qui ont conduit à la provision et à la reprise. Pour les pensions et obligations de retraite indiquer : • indiquer la méthode d'évaluation retenue ; • pour les actifs du régime, indiquer le nom de la compagnie d'assurance ou du fonds de pension, le descriptif de la convention signée avec l'organisme, la périodicité des versements, le montant et la durée de la convention ; • indication de la valeur retenue pour les principales hypothèses actuarielle à la date de clôture et leur base de détermination.

Sheet NOTE 16B
A5: Désignation entité : | B5: Exercice clos le
A6: Numéro d’identification : | B6: Durée (en mois)
A7: NOTE 16B
A8: ENGAGEMENTS DE RETRAITE ET AVANTAGES ASSIMILES
A9: HYPOTHESES ACTUARIELLES
A10: Libellés | B10: Année N | C10: Année N-1
A11: Taux d'augmentation des salaires
A12: Taux d'actualisation
A13: Taux d'inflation
A14: Probabilité d'être présent dans l'entité à la date de départ à la retraite (expérience passée)
A15: Probabilité d'être en vie à l'âge de départ à la retraite (table de mortalité)
A16: Taux de rendement effectif des actifs du régime
A17: Commentaire :
A18: • Commenter les variations d'hypothèses actuarielles utilisées pour le calcul des engagements de retraite et avantages assimilés.
A20: VARIATION DE LA VALEUR DE L'ENGAGEMENT DE RETRAITE AU COURS DE L'EXERCICE
A21: Libellés | B21: Année N | C21: Année N-1
A22: Obligation au titre des engagements de retraite à l'ouverture
A23: Coût des services rendus au cours de l'exercice
A24: Coût financier
A25: Pertes actuarielles / (gain)
A26: Prestations payées au cours de l'exercice
A27: Coût des services passés
A28: Obligation au titre des engagements de retraite à la clôture
A30: Commentaire :
A31: • Indiquer le montant de la charge par nature comptabilisée au cours de l'exercice
A33: ANALYSE DE SENSIBILITE DES HYPOTHESES ACTUARIELLES
A34: Libellés | B34: Année N | D34: Année N-1
B35: Augmentation | C35: Diminution | D35: Augmentation | E35: Diminution
A36: Taux d'actualisation
A37: (variation de ...%)
A38: Taux de progression des salaires (variation de ...%)
A39: Taux de départ du personnel (variation de ...%)
A41: Commentaire :
A42: • Indiquer l’impact des variations obtenues sur le montant des engagements de retraite.
A43: • clôture et leur base de détermination.

Sheet NOTE 16B bis
A5: Désignation entité : | C5: Exercice clos le
A6: Numéro d’identification : | C6: Durée (en mois)
A8: NOTE 16B bis
A10: ENGAGEMENTS DE RETRAITE ET AVANTAGES ASSIMILES
A11: ACTIF/PASSIF NET COMPTABILISE AU TITRE DES REGIMES FINANCES
A12: Libellés | B12: Année N | C12: Année N-1
A13: Valeur actuelle de l'obligation résultant de régimes financés
A14: Valeur actuelle des actifs affectés aux plans de retraite
A15: Excédent / Déficit de régime
A16: Commentaire :
A17: • Indiquer le montant comptabilisé au passif (ou actif) à la clôture de l'exercice
A19: VALEUR ACTUELLE DES ACTIFS DU REGIME
A20: Libellés | B20: Année N | D20: Année N-1
B21: Rendement attendu | C21: Juste valeur des actifs | D21: Rendement attendu | E21: Juste valeur des actifs
A22: Actions
A23: Obligations
A24: Autres
A25: Total
A27: Commentaires :
A28: • Expliquer comment les taux de rendement par catégorie d’actifs et global ont été déterminés
A29: • Indiquer le montant des rendements réels des actifs affectés aux plans en N et N-1
A30: • Indiquer….

Sheet NOTE 16C
A6: Désignation entité : | B6: Exercice clos le
A7: Numéro d’identification : | B7: Durée (en mois)
A10: NOTE 16C
A11: ACTIFS ET PASSIFS EVENTUELS
A12: Libellés | B12: Année N | C12: Année N-1
A13: Actif éventuel
A14: Litiges
A15: .............
A16: .............
A17: Passif éventuel
A18: Litiges
A19: .............
A20: .............
A21: Commentaire:
A22: • Décrire les principales caractéristiques des actifs / passifs éventuels, l’horizon de temps auquel les encaissements / décaissements sont attendus et les éventuels remboursements à percevoir.

Sheet NOTE 17
A4: Désignation entité : | D4: Exercice clos le
A5: Numéro d’identification : | D5: Durée (en mois)
A7: NOTE 17
A8: FOURNISSEURS D'EXPLOITATION
A9: Libellés | B9: Année N | C9: Année N-1 | D9: Variation en % | E9: Dettes à un an au plus | F9: Dettes à plus d'un an et à deux ans au plus | G9: Dettes à plus de deux ans
A10: Fournisseurs dettes en compte (hors groupe) | B10: =PASSIF!D28 -> 0 | C10: =PASSIF!E28 -> 0 | D10: =(B10-C10)/C10 -> #DIV/0! | E10: =B10 -> 0
A11: Fournisseurs effets à payer (hors groupe)
A12: Fournisseurs, dettes et effets à payer groupe
A13: Fournisseurs factures non parvenues (hors groupe)
A14: Fournisseurs factures non parvenues groupe
A15: TOTAL FOURNISSEURS | B15: =SUM(B10:B14) -> 0 | C15: =SUM(C10:C14) -> 0 | E15: =SUM(E10:E14) -> 0
A17: Fournisseurs, avances et acomptes (hors groupe)
A18: Fournisseurs, avances et acomptes groupe
A19: Autres fournisseurs débiteurs
A20: TOTAL FOURNISSEURS DEBITEURS
A21: Commentaires:
A22: • Commenter toutes variations significatives • Indiquer pour les dettes du groupe le nom de la société du groupe et le % de titres détenus. • Commenter les dettes anciennes.

Sheet NOTE 18
A4: Désignation entité : | F4: Exercice clos le
A5: Numéro d’identification : | F5: Durée (en mois)
A7: NOTE 18
A8: DETTES FISCALES ET SOCIALES
A9: Libellés | B9: Année N | C9: Année N-1 | D9: Variation en valeur absolue | E9: Variation en % | F9: Dettes à un an au plus | G9: Dettes à plus d'un | H9: Dettes à plus de deux ans
G10: an et à deux ans au plus
A11: Personnel avances et acomptes
A12: Personnel rémunérations dues | B12: 0 | C12: 0 | D12: =B12-C12 -> 0
A13: Autres personnel | D13: 0
A14: Caisse de sécurité sociale | B14: 0 | C14: 0 | D14: 0 | E14: =D14/C14 -> #DIV/0! | F14: =B14 -> 0 | G14: 0 | H14: 0
A15: Caisse de retraite | B15: 0 | C15: 0 | D15: =B15-C15 -> 0
A16: Autres organisme sociaux | D16: =B16-C16 -> 0
A17: TOTAL DETTES SOCIALES | B17: =SUM(B11:B16) -> 0 | C17: =SUM(C11:C16) -> 0 | D17: =SUM(D11:D16) -> 0 | F17: =SUM(F11:F16) -> 0 | G17: =SUM(G11:G16) -> 0 | H17: =SUM(H11:H16) -> 0
A19: Etat, impôts sur les bénéfices | B19: 0 | C19: 0 | D19: =B19-C19 -> 0 | E19: =D19/C19 -> #DIV/0! | F19: =B19 -> 0 | G19: 0 | H19: 0
A20: Etat, impôts et taxes | D20: =B20-C20 -> 0 | G20: =B20-F20 -> 0 | H20: 0
A21: Etat, TVA | D21: =B21-C21 -> 0
A22: Etat, impôts retenus à la source
A23: Autres dettes Etat
A24: TOTAL DETTES FISCALES | B24: =SUM(B18:B23) -> 0 | C24: =SUM(C18:C23) -> 0 | D24: =SUM(D18:D23) -> 0 | E24: =D24/C24 -> #DIV/0! | F24: =SUM(F18:F23) -> 0 | G24: =SUM(G18:G23) -> 0 | H24: =SUM(H18:H23) -> 0
A26: TOTAL DETTES SOCIALES ET FISCALES | B26: =B17+B24 -> 0 | C26: =C17+C24 -> 0 | D26: =D17+D24 -> 0 | E26: =E17+E24 -> #DIV/0! | F26: =F17+F24 -> 0 | G26: =G17+G24 -> 0 | H26: =H17+H24 -> 0
A28: Commentaires:
A29:  Commenter toute variation significative.
A30:  Commenter les dettes anciennes.

Sheet NOTE 19
A4: Désignation entité : | E4: Exercice clos le
A5: Numéro d’identification : | E5: Durée (en mois)
A6: NOTE 19
A7: AUTRES DETTES ET PROVISIONS POUR RISQUES A COURT TERME
A8: Libellés | B8: Année N | C8: Année N-1 | D8: Variation en valeur absolue | E8: Variation en % | F8: Dettes à un an au plus | G8: Dettes à plus d'un an et à deux ans au plus | H8: Dettes à plus de deux ans
A10: Organismes internationaux
A12: Apporteurs, opérations sur le capital
A13: Associés, compte courant
A14: Associés dividendes à payer
A15: Groupe, comptes courants
A16: Autres dettes associés
A17: TOTAL DETTES ASSOCIES
A19: Créditeurs divers | B19: =+PASSIF!D30 -> 0 | C19: =+PASSIF!E30 -> 0 | D19: =B19-C19 -> 0 | E19: =IF(D19=0,0,D19/C19) -> 0
A20: Obligataires
A21: Rémunérations d'administrateurs
A22: Compte du factor
A23: Versements restant à effectuer sur titres de placement non libérés
A24: Compte transitoire ajustement spécial lié à la révision du SYSCOHADA
A25: Autres créditeurs divers
A26: TOTAL CREDITEURS DIVERS | B26: =B19 -> 0 | C26: =C19 -> 0 | D26: =D19 -> 0 | E26: =E19 -> 0
A28: Comptes permanents non bloqués des établissements et des succursales
A29: Comptes de liaison charges et produits
A30: Comptes de liaison des sociétés en participation
A31: TOTAL COMPTES DE LIAISON
A33: TOTAL AUTRES DETTES | B33: =B26 -> 0 | C33: =C26 -> 0 | D33: =D26 -> 0 | E33: =E26 -> 0
A35: Provisions pour risques à court terme (voir note 28)
A36: Commentaires :
A37: • Commenter toute variation significative.
A38: • Indiquer le taux de rémunération si compte courant rémunéré.
A39: • Commenter les dettes anciennes.
A40: • Compte transitoire ajustement spécial, indiquer le détail du compte et la durée restant pour l'apurement.

Sheet NOTE 20
A5: Désignation entité : | C5: Exercice clos le
A6: Numéro d’identification : | C6: Durée (en mois)
A8: NOTE 20
A9: BANQUES, CREDIT D'ESCOMPTE ET DE TRESORERIE
A10: Libellés | B10: Année N | C10: Année N-1 | D10: Variation en %
A12: Escomptes de crédit de campagne
A13: Escomptes de crédit ordinaires
A14: TOTAL: BANQUES, CREDITS
A15: D'ESCOMPTE ET DE TRESORERIE
A17: Banques locales
A18: Banques autres états région
A19: Autres Banques
A20: Banques intérêts courus
A21: Crédit de trésorerie | B21: =+PASSIF!D34 -> 0 | C21: =+PASSIF!E34 -> 0 | D21: =(B21-C21)/C21 -> #DIV/0!
A22: TOTAL: BANQUES, CREDITS DE TRESORERIE | B22: =B21 -> 0 | C22: =C21 -> 0 | D22: =D21 -> #DIV/0!
A24: TOTAL GENERAL | B24: =B22 -> 0 | C24: =C22 -> 0 | D24: =D22 -> #DIV/0!
A25: Commentaires:
A26: • Commenter toute variation significative.
A27: • Indiquer le nom de l'organisme les conditions de crédit, le taux d'intérêt, la durée du crédit.
A28: NB : Banques et intérêts courus figure dans cette rubrique si le compte principal attaché est créditeur.

Sheet NOTE 21
A6: Désignation entité : | B6: Exercice clos le
A7: Numéro d’identification : | B7: Durée (en mois)
A9: NOTE 21
A10: CHIFFRE D’AFFAIRES et AUTRES PRODUITS
A11: Libellés | B11: Année N | C11: Année N-1 | D11: Variation en %
A13: Ventes dans la région | B13: 0 | C13: 0 | D13: =(B13-C13)/C13 -> #DIV/0!
A14: Ventes hors région
A15: Ventes groupe
A16: Ventes sur internet
A17: TOTAL : VENTES MARCHANDISES | B17: =SUM(B13:B16) -> 0 | C17: =SUM(C13:C16) -> 0 | D17: =(B17-C17)/C17 -> #DIV/0!
A19: Ventes dans la région
A20: Ventes hors région
A21: Ventes groupe
A22: Ventes sur internet
A23: TOTAL : VENTES DE PRODUITS FABRIQUES | B23: 0 | C23: 0
A25: Ventes dans la région | B25: 0 | C25: 0 | D25: =(B25-C25)/C25 -> #DIV/0!
A26: Ventes hors région
A27: Ventes groupe
A28: Ventes sur internet
A29: TOTAL : VENTES DE TRAVAUX ET SERVICES VENDUS | B29: =SUM(B25:B28) -> 0 | C29: =SUM(C25:C28) -> 0 | D29: =(B29-C29)/C29 -> #DIV/0!
A31: Produits accessoires | B31: 0 | C31: 0 | D31: =(B31-C31)/C31 -> #DIV/0!
A34: TOTAL : CHIFFRES D'AFFAIRES | B34: =B17+B23+B29+B31 -> 0 | C34: =C17+C23+C29+C31 -> 0 | D34: =(B34-C34)/C34 -> #DIV/0!
A36: Production immobilisée
A37: Subventions d'exploitation | B37: ='Compte de Résultat'!E19 -> 0 | C37: 0
A38: Autres produits | B38: 0 | C38: 0 | D38: =(B38-C38)/C38 -> #DIV/0!
A39: TOTAL : AUTRES PRODUITS | B39: =SUM(B36:B38) -> 0 | C39: =SUM(C36:C38) -> 0 | D39: =(B39-C39)/C39 -> #DIV/0!
A41: TOTAL | B41: =B34+B39 -> 0 | C41: =C34+C39 -> 0 | D41: =(B41-C41)/C41 -> #DIV/0!
A42: Commentaires:
A43: • Justifier toute variation significative.
A44: • Détailler, produits, intermédiaires, produits résiduels, produits accessoires, autres produits si significatifs.

Sheet NOTE 22
A5: Désignation entité : | B5: Exercice clos le
A6: Numéro d’identification : | B6: Durée (en mois)
A8: NOTE 22
A9: ACHATS
A10: Libellés | B10: Année N | C10: Année N-1 | D10: Variation en %
A11: Achats dans la région | B11: 0 | C11: 0 | D11: =(B11-C11)/C11 -> #DIV/0!
A12: Achats hors région
A13: Achats groupe
A14: TOTAL : ACHATS DE MARCHANDISES | B14: =SUM(B11:B13) -> 0 | C14: =SUM(C11:C13) -> 0 | D14: =SUM(D11:D13) -> #DIV/0!
A16: Achats dans la région
A17: Achats hors région
A18: Achats groupe
A19: TOTAL : ACHATS MATIERES PREMIERES ET FOURNITURES LIEES | B19: =SUM(B15:B18) -> 0 | C19: =SUM(C15:C18) -> 0 | D19: =SUM(D15:D18) -> 0
A21: Matières consommables
A22: Matières combustibles
A23: Produits d'entretien
A24: Fournitures d'atelier, d'usine et de magasin
A25: Eau | B25: 0 | C25: 0 | D25: =(B25-C25)/C25 -> #DIV/0!
A26: Electricité | B26: 0 | C26: 0 | D26: =(B26-C26)/C26 -> #DIV/0!
A27: Autres énergies | B27: 0 | C27: 0 | D27: =(B27-C27)/C27 -> #DIV/0!
A28: Fourniture d'entretien | B28: 0 | C28: 0 | D28: =(B28-C28)/C28 -> #DIV/0!
A29: Fourniture de bureau | B29: 0 | C29: 0 | D29: =(B29-C29)/C29 -> #DIV/0!
A30: Petit matériel et outillages | B30: 0 | C30: 0 | D30: =(B30-C30)/C30 -> #DIV/0!
A31: Achats études, prestations de services, de travaux matériels et équipements | B31: 0 | C31: 0 | D31: =(B31-C31)/C31 -> #DIV/0!
A32: Achats d'emballages
A33: Frais sur achats
A34: Remises rabais, remises et ristournes
A35: TOTAL : AUTRES ACHATS | B35: =SUM(B21:B34) -> 0 | C35: =SUM(C21:C34) -> 0 | D35: =(B35-C35)/C35 -> #DIV/0!
A37: Commentaire :
A38:  Commenter toute variation significative.

Sheet NOTE 23
A4: Désignation entité : | C4: Exercice clos le
A5: Numéro d’identification : | C5: Durée (en mois)
A7: NOTE 23
A8: TRANSPORTS
A9: Libellés | B9: Année N | C9: Année N-1 | D9: Variation en %
A10: Transports sur ventes
A11: Transports pour le compte de tiers
A12: Transport du personnel
A13: Transports de plis
A14: Autres transports | B14: 0 | C14: 0 | D14: =(B14-C14)/C14 -> #DIV/0!
A15: TOTAL | B15: =SUM(B10:B14) -> 0 | C15: =SUM(C10:C14) -> 0 | D15: =(B15-C15)/C15 -> #DIV/0!
A16: Commentaire :
A17:  Commenter toute variation significative.

Sheet NOTE 24
A4: Désignation entité : | C4: Exercice clos le
A5: Numéro d’identification : | C5: Durée (en mois)
A7: NOTE 24
A8: SERVICES EXTERIEURS
A9: Libellés | B9: Année N | C9: Année N-1 | D9: Variation en %
A10: Sous-traitance générale
A11: Locations et charges locatives | B11: 0 | C11: 0 | D11: =(B11-C11)/C11 -> #DIV/0!
A12: Redevances de location acquisition
A13: Entretien, réparations et maintenance | B13: 0 | C13: 0 | D13: =(B13-C13)/C13 -> #DIV/0!
A14: Primes d'assurance | B14: 0 | C14: 0 | D14: =(B14-C14)/C14 -> #DIV/0!
A15: Etudes, recherches et documentation
A16: Publicité, publications, relations publiques
A17: Frais de télécommunications | B17: 0 | C17: 0 | D17: =(B17-C17)/C17 -> #DIV/0!
A18: Frais bancaires | B18: 0 | C18: 0 | D18: =(B18-C18)/C18 -> #DIV/0!
A19: Rémunérations d'intermédiaires et de conseils | B19: 0 | C19: 0 | D19: =(B19-C19)/C19 -> #DIV/0!
A20: Frais de formation du personnel
A21: Redevances pour brevets, licences, logiciels, concession et droits similaires | C21: 0 | D21: =(B21-C21)/C21 -> #DIV/0!
A22: Cotisations | C22: 0 | D22: =(B22-C22)/C22 -> #DIV/0!
A23: Autres charges externes | B23: 0 | C23: 0 | D23: =(B23-C23)/C23 -> #DIV/0!
A24: TOTAL | B24: =SUM(B10:B23) -> 0 | C24: =SUM(C10:C23) -> 0 | D24: =(B24-C24)/C24 -> #DIV/0!
A25: Commentaire :
A26:  Commenter toute variation significative.

Sheet NOTE 25
A5: Désignation entité : | C5: Exercice clos le
A6: Numéro d’identification : | C6: Durée (en mois)
A8: NOTE 25
A9: IMPOTS ET TAXES
A10: Libellés | B10: Année N | C10: Année N-1 | D10: Variation en %
A11: Impôts et taxes directs | B11: 0
A12: Impôts et taxes indirects | B12: 0
A13: Droits d'enregistrement | C13: 0 | D13: =(B13-C13)/C13 -> #DIV/0!
A14: Pénalités et amendes fiscales
A15: Autres impôts et taxes | C15: 0 | D15: =(B15-C15)/C15 -> #DIV/0!
A16: TOTAL | B16: =SUM(B11:B15) -> 0 | C16: =SUM(C11:C15) -> 0 | D16: =(B16-C16)/C16 -> #DIV/0!
A17: Commentaires:
A18: • Commenter toute variation significative.
A19: • Détailler les pénalités et amendes et indiquer la cause.

Sheet NOTE 26
