Workbook

Sheet BALANCE N
A1: Compte | B1: Intitulé | C1: Préfixe 2 | D1: Préfixe 3 | E1: Préfixe 4 | F1: Solde final débit | G1: Solde final crédit | J1: Poste(s) d'affectation
A2: 2441 | B2: Matériel et mobilier de bureau | C2: 24 | D2: 244 | E2: 2441 | F2: 4000000 | G2: 0 | J2: AD
A3: 2451 | B3: Matériel de transport automobile | C3: 24 | D3: 245 | E3: 2451 | F3: 8000000 | G3: 0 | J3: AE
A4: 2751 | B4: Dépôts et cautionnements - loyers d'avance | C4: 27 | D4: 275 | E4: 2751 | F4: 500000 | G4: 0 | J4: AG
A5: 521 | B5: Banques locales | C5: 52 | D5: 521 | E5: 521 | F5: 2450000 | G5: 0 | J5: BW, DW
A6: 571 | B6: Caisse | C6: 57 | D6: 571 | E6: 571 | F6: 200000 | G6: 0 | J6: BW
A7: 162 | B7: Fonds affectés aux investissements - bailleurs | C7: 16 | D7: 162 | E7: 162 | F7: 0 | G7: 12500000 | J7: CA
A8: 462 | B8: Bailleurs - fonds d'administration | C8: 46 | D8: 462 | E8: 462 | F8: 0 | G8: 1200000 | J8: DF
A9: 4011 | B9: Fournisseurs | C9: 40 | D9: 401 | E9: 4011 | F9: 0 | G9: 800000 | J9: DG
A10: 422 | B10: Personnel, rémunérations dues | C10: 42 | D10: 422 | E10: 422 | F10: 0 | G10: 300000 | J10: BE, DH
A11: 431 | B11: Sécurité sociale | C11: 43 | D11: 431 | E11: 431 | F11: 0 | G11: 150000 | J11: BE, DH
A12: 447 | B12: État, impôts retenus à la source | C12: 44 | D12: 447 | E12: 447 | F12: 0 | G12: 100000 | J12: BE, DH
A13: 601 | B13: Achats de biens et services liés à l'activité | C13: 60 | D13: 601 | E13: 601 | F13: 2500000 | G13: 0 | J13: TA
... A23: 771 | B23: Intérêts de prêts et créances diverses | C23: 77 | D23: 771 | E23: 771 | F23: 0 | G23: 50000 | J23: RD

Sheet BALANCE N-1
A1: Compte | B1: Intitulé | C1: Préfixe 2 | D1: Préfixe 3 | E1: Préfixe 4 | F1: Solde final débit | G1: Solde final crédit | J1: Poste(s) d'affectation
A2: 2441 | B2: Matériel et mobilier de bureau | C2: 24 | D2: 244 | E2: 2441 | F2: 4000000 | G2: 0 | J2: AD
A3: 2451 | B3: Matériel de transport automobile | C3: 24 | D3: 245 | E3: 2451 | F3: 5000000 | G3: 0 | J3: AE
A4: 2751 | B4: Dépôts et cautionnements - loyers d'avance | C4: 27 | D4: 275 | E4: 2751 | F4: 500000 | G4: 0 | J4: AG
A5: 521 | B5: Banques locales | C5: 52 | D5: 521 | E5: 521 | F5: 1800000 | G5: 0 | J5: BW, DW
A6: 571 | B6: Caisse | C6: 57 | D6: 571 | E6: 571 | F6: 100000 | G6: 0 | J6: BW
A7: 162 | B7: Fonds affectés aux investissements - bailleurs | C7: 16 | D7: 162 | E7: 162 | F7: 0 | G7: 10000000 | J7: CA
A8: 462 | B8: Bailleurs - fonds d'administration | C8: 46 | D8: 462 | E8: 462 | F8: 0 | G8: 700000 | J8: DF
A9: 4011 | B9: Fournisseurs | C9: 40 | D9: 401 | E9: 4011 | F9: 0 | G9: 500000 | J9: DG
A10: 422 | B10: Personnel, rémunérations dues | C10: 42 | D10: 422 | E10: 422 | F10: 0 | G10: 150000 | J10: BE, DH
A11: 431 | B11: Sécurité sociale | C11: 43 | D11: 431 | E11: 431 | F11: 0 | G11: 50000 | J11: BE, DH

Sheet CONTROLE BALANCE
A1: EQUILIBRE DE LA BALANCE
A2: BALANCE N | B2: Mouvements Débit | C2: Mouvements Crédit | D2: Solde Final Débit | E2: Solde Final Crédit
B3: =SUM('BALANCE N'!H2:H23) | C3: =SUM('BALANCE N'!I2:I23) | D3: =SUM('BALANCE N'!F2:F23) | E3: =SUM('BALANCE N'!G2:G23)
B4: =IF(ROUND(B3-C3,0)=0,"Equilibre","Déséquilibre : écart de "&TEXT(B3-C3,"#,##0")) | D4: =IF(ROUND(D3-E3,0)=0,"Equilibre","Déséquilibre : écart de "&TEXT(D3-E3,"#,##0"))
A5: BALANCE N-1 | B5: Mouvements Débit | C5: Mouvements Crédit | D5: Solde Final Débit | E5: Solde Final Crédit
B6: =SUM('BALANCE N-1'!H2:H11) | C6: =SUM('BALANCE N-1'!I2:I11) | D6: =SUM('BALANCE N-1'!F2:F11) | E6: =SUM('BALANCE N-1'!G2:G11)
B7: =IF(ROUND(B6-C6,0)=0,"Equilibre","Déséquilibre : écart de "&TEXT(B6-C6,"#,##0")) | D7: =IF(ROUND(D6-E6,0)=0,"Equilibre","Déséquilibre : écart de "&TEXT(D6-E6,"#,##0"))

Sheet Couverture
E26: PROJET EAU POTABLE RURALE
E31: LIASSE PROJETS DE DEVELOPPEMENT
E34: Exercice clos le 31-12-2025

Sheet Garde
B12: ETATS FINANCIERS NORMALISES DU SYSTEME COMPTABLE DES ENTITES A BUT NON LUCRATIF (SYCEBNL)
B13: Projets de développement et assimilés
C16: Exercice clos le 31-12-2025 - Durée (en mois) : 12
B20: DESIGNATION DE L'ENTITE
B22: DENOMINATION SOCIALE : | E22: PROJET EAU POTABLE RURALE
B24: SIGLE USUEL : | E24: PEPR
B26: ADRESSE COMPLETE :
B28: N° de compte contribuable (NCC) : | E28: PD-2023-017
B30: N° de télédéclarant (NTD) :
B32: PROJETS DE DEVELOPPEMENT
B34: Documents déposés | H34: Réservé à l'administration
B35: Fiche d'identification et renseignements divers | F35: X | H35: Date de dépôt
B36: Tableau emplois-ressources | F36: X
B37: Tableau d'exécution budgétaire | F37: X
B38: Tableau de réconciliation de trésorerie | F38: X
B39: Bilan (actif et passif) | F39: X | H39: Nom de l'agent ayant réceptionné le dépôt
B40: Compte d'exploitation | F40: X
B41: Notes annexes | F41: X
H43: Signature de l'agent et cachet du service
B48: Nombre de pages déposées par exemplaire :
B49: Nombre d'exemplaires déposés :

Sheet Fiche 1
A1: - 1 -
I2: FICHE 1
A3: Dénomination sociale : PROJET EAU POTABLE RURALE
A4: Adresse : | I4: Sigle usuel : | J4: PEPR
A5: N° de compte contribuable (NCC) : PD-2023-017 | G5: Exercice clos le 31-12-2025 | I5: Durée (en mois) : 12
A6: N° de télédéclarant (NTD) :
A7: FICHE D'IDENTIFICATION ET RENSEIGNEMENTS DIVERS
A8: SYCEBNL - Projets de développement et assimilés
A10: ZA | B10: EXERCICE COMPTABLE | G10: DU : 01-01-2025 AU : 31-12-2025
A11: ZB | B11: DATE D'ARRETE EFFECTIF DES COMPTES
A12: ZC | B12: EXERCICE PRECEDENT CLOS LE
A13: ZD | B13: DUREE DE L'EXERCICE PRECEDENT (EN MOIS)
A14: ZE | B14: N° REGISTRE (RCCM, F92, CONVENTION...) ET GREFFE
A15: ZF | B15: N° REPERTOIRE DES ENTITES
A16: ZG | B16: N° DE CAISSE SOCIALE
A17: ZH | B17: N° CODE IMPORTATEUR
A18: ZI | B18: CODE ACTIVITE PRINCIPALE
A19: ZJ | B19: DESIGNATION DE L'ENTITE ET SIGLE | G19: PROJET EAU POTABLE RURALE (PEPR)
A20: ZK | B20: N° DE TELEPHONE, ADRESSE E-MAIL, BOITE POSTALE, VILLE
A21: ZL | B21: ADRESSE GEOGRAPHIQUE COMPLETE (IMMEUBLE, RUE, QUARTIER, VILLE, PAYS)
A22: ZM | B22: DESIGNATION PRECISE DE L'ACTIVITE PRINCIPALE EXERCEE
A23: ZN | B23: % DE CAPACITE DE PRODUCTION UTILE
A24: ZO | B24: NOM, ADRESSE, TELEPHONE, E-MAIL ET QUALITE DE LA PERSONNE A CONTACTER EN CAS DE DEMANDE
A25: ZP | B25: NOM, ADRESSE, TELEPHONE ET E-MAIL DU SALARIE OU DU PROFESSIONNEL COMPTABLE AYANT ETABLI LES ETATS FINANCIERS
A26: ZQ | B26: NOM, ADRESSE, TELEPHONE, E-MAIL ET N° D'INSCRIPTION A L'ORDRE DE L'EXPERT-COMPTABLE AYANT DELIVRE L'ATTESTATION DE VISA
A27: ZR | B27: NOM, ADRESSE, TELEPHONE, E-MAIL ET N° D'INSCRIPTION DU COMMISSAIRE AUX COMPTES, LE CAS ECHEANT
A28: ZS | B28: ETATS FINANCIERS APPROUVES PAR L'ORGANE COMPETENT (OUI / NON)
A29: ZT | B29: NOM DU SIGNATAIRE DES ETATS FINANCIERS
A30: ZU | B30: QUALITE DU SIGNATAIRE DES ETATS FINANCIERS
A31: ZV | B31: DATE DE SIGNATURE
A32: ZW | B32: DOMICILIATIONS BANCAIRES (BANQUE ET NUMERO DE COMPTE)
B34: Signature

Sheet Fiche 2
A1: - 2 -
I2: FICHE 2
A3: Dénomination sociale : PROJET EAU POTABLE RURALE
A4: Adresse : | I4: Sigle usuel : | J4: PEPR
A5: N° de compte contribuable (NCC) : PD-2023-017 | G5: Exercice clos le 31-12-2025 | I5: Durée (en mois) : 12
A6: N° de télédéclarant (NTD) :
A7: FICHE D'IDENTIFICATION ET RENSEIGNEMENTS DIVERS
A8: EQUIPE DU PROJET
A10: Nom et Prénoms | C10: Nationalité | D10: Autres nationalités (à préciser) (2) | E10: Qualité | F10: N° d'identification fiscale | H10: Adresse (BP, ville, pays, adresse géographique et adresse e-mail)
A32: (2) Mentionner les autres nationalités le cas échéant.

Sheet Emplois-Ressources
A1: - 3 -
D2: EMPLOIS-RESSOURCES PROJETS DE DEVELOPPEMENT
A3: Dénomination sociale : PROJET EAU POTABLE RURALE
A4: Adresse : | D4: Sigle usuel : | E4: PEPR
A5: N° de compte contribuable (NCC) : PD-2023-017 | C5: Exercice clos le 31-12-2025 | D5: Durée (en mois) : 12
A6: N° de télédéclarant (NTD) :
A7: TABLEAU EMPLOIS-RESSOURCES
A8: REF | B8: DESIGNATION | C8: SOLDE CUMULE DEBUT EXERCICE N | D8: EXERCICE N | E8: SOLDE CUMULE FIN EXERCICE N
A9: FA | B9: Fonds reçus, Bailleurs | D9: =(SUMIF('BALANCE N'!$A$2:$A$50,"162*",'BALANCE N'!$G$2:$G$50)-SUMIF('BALANCE N'!$A$2:$A$50,"162*",'BALANCE N'!$F$2:$F$50)+SUMIF('BALANCE N'!$A$2:$A$50,"462*",'BALANCE N'!$G$2:$G$50)-SUMIF('BALANCE N'!$A$2:$A$50,"462*",'BALANCE N'!$F$2:$F$50))-(SUMIF('BALANCE N-1'!$A$2:$A$50,"162*",'BALANCE N-1'!$G$2:$G$50)-SUMIF('BALANCE N-1'!$A$2:$A$50,"162*",'BALANCE N-1'!$F$2:$F$50)+SUMIF('BALANCE N-1'!$A$2:$A$50,"462*",'BALANCE N-1'!$G$2:$G$50)-SUMIF('BALANCE N-1'!$A$2:$A$50,"462*",'BALANCE N-1'!$F$2:$F$50))+(SUMIF('BALANCE N'!$A$2:$A$50,"702*",'BALANCE N'!$G$2:$G$50)-SUMIF('BALANCE N'!$A$2:$A$50,"702*",'BALANCE N'!$F$2:$F$50)) | E9: =C9+D9
A10: FB | B10: Fonds reçus, Bailleurs (autres)
A11: FC | B11: Fonds contrepartie État | D11: =(SUMIF('BALANCE N'!$A$2:$A$50,"463*",'BALANCE N'!$G$2:$G$50)-SUMIF('BALANCE N'!$A$2:$A$50,"463*",'BALANCE N'!$F$2:$F$50)+SUMIF('BALANCE N'!$A$2:$A$50,"163*",'BALANCE N'!$G$2:$G$50)-SUMIF('BALANCE N'!$A$2:$A$50,"163*",'BALANCE N'!$F$2:$F$50))-(SUMIF('BALANCE N-1'!$A$2:$A$50,"463*",'BALANCE N-1'!$G$2:$G$50)-SUMIF('BALANCE N-1'!$A$2:$A$50,"463*",'BALANCE N-1'!$F$2:$F$50)+SUMIF('BALANCE N-1'!$A$2:$A$50,"163*",'BALANCE N-1'!$G$2:$G$50)-SUMIF('BALANCE N-1'!$A$2:$A$50,"163*",'BALANCE N-1'!$F$2:$F$50)) | E11: =C11+D11
A12: FD | B12: Autres fonds reçus | D12: =(SUMIF('BALANCE N'!$A$2:$A$50,"168*",'BALANCE N'!$G$2:$G$50)-SUMIF('BALANCE N'!$A$2:$A$50,"168*",'BALANCE N'!$F$2:$F$50)+SUMIF('BALANCE N'!$A$2:$A$50,"161*",'BALANCE N'!$G$2:$G$50)-SUMIF('BALANCE N'!$A$2:$A$50,"161*",'BALANCE N'!$F$2:$F$50)+SUMIF('BALANCE N'!$A$2:$A$50,"165*",'BALANCE N'!$G$2:$G$50)-SUMIF('BALANCE N'!$A$2:$A$50,"165*",'BALANCE N'!$F$2:$F$50)+SUMIF('BALANCE N'!$A$2:$A$50,"164*",'BALANCE N'!$G$2:$G$50)-SUMIF('BALANCE N'!$A$2:$A$50,"164*",'BALANCE N'!$F$2:$F$50)+SUMIF('BALANCE N'!$A$2:$A$50,"464*",'BALANCE N'!$G$2:$G$50)-SUMIF('BALANCE N'!$A$2:$A$50,"464*",'BALANCE N'!$F$2:$F$50))-(SUMIF('BALANCE N-1'!$A$2:$A$50,"168*",'BALANCE N-1'!$G$2:$G$50)-SUMIF('BALANCE N-1'!$A$2:$A$50,"168*",'BALANCE N-1'!$F$2:$F$50)+SUMIF('BALANCE N-1'!$A$2:$A$50,"161*",'BALANCE N-1'!$G$2:$G$50)-SUMIF('BALANCE N-1'!$A$2:$A$50,"161*",'BALANCE N-1'!$F$2:$F$50)+SUMIF('BALANCE N-1'!$A$2:$A$50,"165*",'BALANCE N-1'!$G$2:$G$50)-SUMIF('BALANCE N-1'!$A$2:$A$50,"165*",'BALANCE N-1'!$F$2:$F$50)+SUMIF('BALANCE N-1'!$A$2:$A$50,"164*",'BALANCE N-1'!$G$2:$G$50)-SUMIF('BALANCE N-1'!$A$2:$A$50,"164*",'BALANCE N-1'!$F$2:$F$50)+SUMIF('BALANCE N-1'!$A$2:$A$50,"464*",'BALANCE N-1'!$G$2:$G$50)-SUMIF('BALANCE N-1'!$A$2:$A$50,"464*",'BALANCE N-1'!$F$2:$F$50)) | E12: =C12+D12
A13: GR | B13: I. RESSOURCES | C13: =C9+C10+C11+C12 | D13: =D9+D10+D11+D12 | E13: =E9+E10+E11+E12
A14: FE | B14: Immobilisations incorporelles | C14: =SUMIF('BALANCE N-1'!$A$2:$A$50,"21*",'BALANCE N-1'!$F$2:$F$50)-SUMIF('BALANCE N-1'!$A$2:$A$50,"21*",'BALANCE N-1'!$G$2:$G$50)+SUMIF('BALANCE N-1'!$A$2:$A$50,"251*",'BALANCE N-1'!$F$2:$F$50)-SUMIF('BALANCE N-1'!$A$2:$A$50,"251*",'BALANCE N-1'!$G$2:$G$50) | D14: =E14-C14 | E14: =SUMIF('BALANCE N'!$A$2:$A$50,"21*",'BALANCE N'!$F$2:$F$50)-SUMIF('BALANCE N'!$A$2:$A$50,"21*",'BALANCE N'!$G$2:$G$50)+SUMIF('BALANCE N'!$A$2:$A$50,"251*",'BALANCE N'!$F$2:$F$50)-SUMIF('BALANCE N'!$A$2:$A$50,"251*",'BALANCE N'!$G$2:$G$50)
A15: FF | B15: Terrains | C15: =SUMIF('BALANCE N-1'!$A$2:$A$50,"22*",'BALANCE N-1'!$F$2:$F$50)-SUMIF('BALANCE N-1'!$A$2:$A$50,"22*",'BALANCE N-1'!$G$2:$G$50) | D15: =E15-C15 | E15: =SUMIF('BALANCE N'!$A$2:$A$50,"22*",'BALANCE N'!$F$2:$F$50)-SUMIF('BALANCE N'!$A$2:$A$50,"22*",'BALANCE N'!$G$2:$G$50)
A16: FG | B16: Bâtiments | C16: =SUMIF('BALANCE N-1'!$A$2:$A$50,"231*",'BALANCE N-1'!$F$2:$F$50)-SUMIF('BALANCE N-1'!$A$2:$A$50,"231*",'BALANCE N-1'!$G$2:$G$50)+SUMIF('BALANCE N-1'!$A$2:$A$50,"232*",'BALANCE N-1'!$F$2:$F$50)-SUMIF('BALANCE N-1'!$A$2:$A$50,"232*",'BALANCE N-1'!$G$2:$G$50)+SUMIF('BALANCE N-1'!$A$2:$A$50,"233*",'BALANCE N-1'!$F$2:$F$50)-SUMIF('BALANCE N-1'!$A$2:$A$50,"233*",'BALANCE N-1'!$G$2:$G$50)+SUMIF('BALANCE N-1'!$A$2:$A$50,"2393*",'BALANCE N-1'!$F$2:$F$50)-SUMIF('BALANCE N-1'!$A$2:$A$50,"2393*",'BALANCE N-1'!$G$2:$G$50)+SUMIF('BALANCE N-1'!$A$2:$A$50,"2396*",'BALANCE N-1'!$F$2:$F$50)-SUMIF('BALANCE N-1'!$A$2:$A$50,"2396*",'BALANCE N-1'!$G$2:$G$50)+SUMIF('BALANCE N-1'!$A$2:$A$50,"2391*",'BALANCE N-1'!$F$2:$F$50)-SUMIF('BALANCE N-1'!$A$2:$A$50,"2391*",'BALANCE N-1'!$G$2:$G$50)+SUMIF('BALANCE N-1'!$A$2:$A$50,"2392*",'BALANCE N-1'!$F$2:$F$50)-SUMIF('BALANCE N-1'!$A$2:$A$50,"2392*",'BALANCE N-1'!$G$2:$G$50) | D16: =E16-C16 | E16: =SUMIF('BALANCE N'!$A$2:$A$50,"231*",'BALANCE N'!$F$2:$F$50)-SUMIF('BALANCE N'!$A$2:$A$50,"231*",'BALANCE N'!$G$2:$G$50)+SUMIF('BALANCE N'!$A$2:$A$50,"232*",'BALANCE N'!$F$2:$F$50)-SUMIF('BALANCE N'!$A$2:$A$50,"232*",'BALANCE N'!$G$2:$G$50)+SUMIF('BALANCE N'!$A$2:$A$50,"233*",'BALANCE N'!$F$2:$F$50)-SUMIF('BALANCE N'!$A$2:$A$50,"233*",'BALANCE N'!$G$2:$G$50)+SUMIF('BALANCE N'!$A$2:$A$50,"2393*",'BALANCE N'!$F$2:$F$50)-SUMIF('BALANCE N'!$A$2:$A$50,"2393*",'BALANCE N'!$G$2:$G$50)+SUMIF('BALANCE N'!$A$2:$A$50,"2396*",'BALANCE N'!$F$2:$F$50)-SUMIF('BALANCE N'!$A$2:$A$50,"2396*",'BALANCE N'!$G$2:$G$50)+SUMIF('BALANCE N'!$A$2:$A$50,"2391*",'BALANCE N'!$F$2:$F$50)-SUMIF('BALANCE N'!$A$2:$A$50,"2391*",'BALANCE N'!$G$2:$G$50)+SUMIF('BALANCE N'!$A$2:$A$50,"2392*",'BALANCE N'!$F$2:$F$50)-SUMIF('BALANCE N'!$A$2:$A$50,"2392*",'BALANCE N'!$G$2:$G$50)
A17: FH | B17: Aménagements, agencements et installations | C17: =SUMIF('BALANCE N-1'!$A$2:$A$50,"238*",'BALANCE N-1'!$F$2:$F$50)-SUMIF('BALANCE N-1'!$A$2:$A$50,"238*",'BALANCE N-1'!$G$2:$G$50)+SUMIF('BALANCE N-1'!$A$2:$A$50,"234*",'BALANCE N-1'!$F$2:$F$50)-SUMIF('BALANCE N-1'!$A$2:$A$50,"234*",'BALANCE N-1'!$G$2:$G$50)+SUMIF('BALANCE N-1'!$A$2:$A$50,"235*",'BALANCE N-1'!$F$2:$F$50)-SUMIF('BALANCE N-1'!$A$2:$A$50,"235*",'BALANCE N-1'!$G$2:$G$50)+SUMIF('BALANCE N-1'!$A$2:$A$50,"2394*",'BALANCE N-1'!$F$2:$F$50)-SUMIF('BALANCE N-1'!$A$2:$A$50,"2394*",'BALANCE N-1'!$G$2:$G$50)+SUMIF('BALANCE N-1'!$A$2:$A$50,"2398*",'BALANCE N-1'!$F$2:$F$50)-SUMIF('BALANCE N-1'!$A$2:$A$50,"2398*",'BALANCE N-1'!$G$2:$G$50)+SUMIF('BALANCE N-1'!$A$2:$A$50,"2395*",'BALANCE N-1'!$F$2:$F$50)-SUMIF('BALANCE N-1'!$A$2:$A$50,"2395*",'BALANCE N-1'!$G$2:$G$50) | D17: =E17-C17 | E17: =SUMIF('BALANCE N'!$A$2:$A$50,"238*",'BALANCE N'!$F$2:$F$50)-SUMIF('BALANCE N'!$A$2:$A$50,"238*",'BALANCE N'!$G$2:$G$50)+SUMIF('BALANCE N'!$A$2:$A$50,"234*",'BALANCE N'!$F$2:$F$50)-SUMIF('BALANCE N'!$A$2:$A$50,"234*",'BALANCE N'!$G$2:$G$50)+SUMIF('BALANCE N'!$A$2:$A$50,"235*",'BALANCE N'!$F$2:$F$50)-SUMIF('BALANCE N'!$A$2:$A$50,"235*",'BALANCE N'!$G$2:$G$50)+SUMIF('BALANCE N'!$A$2:$A$50,"2394*",'BALANCE N'!$F$2:$F$50)-SUMIF('BALANCE N'!$A$2:$A$50,"2394*",'BALANCE N'!$G$2:$G$50)+SUMIF('BALANCE N'!$A$2:$A$50,"2398*",'BALANCE N'!$F$2:$F$50)-SUMIF('BALANCE N'!$A$2:$A$50,"2398*",'BALANCE N'!$G$2:$G$50)+SUMIF('BALANCE N'!$A$2:$A$50,"2395*",'BALANCE N'!$F$2:$F$50)-SUMIF('BALANCE N'!$A$2:$A$50,"2395*",'BALANCE N'!$G$2:$G$50)
A18: FI | B18: Matériel, mobilier et actifs biologiques | C18: =SUMIF('BALANCE N-1'!$A$2:$A$50,"24*",'BALANCE N-1'!$F$2:$F$50)-SUMIF('BALANCE N-1'!$A$2:$A$50,"24*",'BALANCE N-1'!$G$2:$G$50)-SUMIF('BALANCE N-1'!$A$2:$A$50,"245*",'BALANCE N-1'!$F$2:$F$50)+SUMIF('BALANCE N-1'!$A$2:$A$50,"245*",'BALANCE N-1'!$G$2:$G$50)-SUMIF('BALANCE N-1'!$A$2:$A$50,"2495*",'BALANCE N-1'!$F$2:$F$50)+SUMIF('BALANCE N-1'!$A$2:$A$50,"2495*",'BALANCE N-1'!$G$2:$G$50) | D18: =E18-C18 | E18: =SUMIF('BALANCE N'!$A$2:$A$50,"24*",'BALANCE N'!$F$2:$F$50)-SUMIF('BALANCE N'!$A$2:$A$50,"24*",'BALANCE N'!$G$2:$G$50)-SUMIF('BALANCE N'!$A$2:$A$50,"245*",'BALANCE N'!$F$2:$F$50)+SUMIF('BALANCE N'!$A$2:$A$50,"245*",'BALANCE N'!$G$2:$G$50)-SUMIF('BALANCE N'!$A$2:$A$50,"2495*",'BALANCE N'!$F$2:$F$50)+SUMIF('BALANCE N'!$A$2:$A$50,"2495*",'BALANCE N'!$G$2:$G$50)
A19: FJ | B19: Matériel de transport | C19: =SUMIF('BALANCE N-1'!$A$2:$A$50,"245*",'BALANCE N-1'!$F$2:$F$50)-SUMIF('BALANCE N-1'!$A$2:$A$50,"245*",'BALANCE N-1'!$G$2:$G$50)+SUMIF('BALANCE N-1'!$A$2:$A$50,"2495*",'BALANCE N-1'!$F$2:$F$50)-SUMIF('BALANCE N-1'!$A$2:$A$50,"2495*",'BALANCE N-1'!$G$2:$G$50) | D19: =E19-C19 | E19: =SUMIF('BALANCE N'!$A$2:$A$50,"245*",'BALANCE N'!$F$2:$F$50)-SUMIF('BALANCE N'!$A$2:$A$50,"245*",'BALANCE N'!$G$2:$G$50)+SUMIF('BALANCE N'!$A$2:$A$50,"2495*",'BALANCE N'!$F$2:$F$50)-SUMIF('BALANCE N'!$A$2:$A$50,"2495*",'BALANCE N'!$G$2:$G$50)
A20: FK | B20: Avances et acomptes sur immobilisations | C20: =SUMIF('BALANCE N-1'!$A$2:$A$50,"252*",'BALANCE N-1'!$F$2:$F$50)-SUMIF('BALANCE N-1'!$A$2:$A$50,"252*",'BALANCE N-1'!$G$2:$G$50) | D20: =E20-C20 | E20: =SUMIF('BALANCE N'!$A$2:$A$50,"252*",'BALANCE N'!$F$2:$F$50)-SUMIF('BALANCE N'!$A$2:$A$50,"252*",'BALANCE N'!$G$2:$G$50)
A21: FL | B21: Immobilisations financières | C21: =SUMIF('BALANCE N-1'!$A$2:$A$50,"26*",'BALANCE N-1'!$F$2:$F$50)-SUMIF('BALANCE N-1'!$A$2:$A$50,"26*",'BALANCE N-1'!$G$2:$G$50)+SUMIF('BALANCE N-1'!$A$2:$A$50,"27*",'BALANCE N-1'!$F$2:$F$50)-SUMIF('BALANCE N-1'!$A$2:$A$50,"27*",'BALANCE N-1'!$G$2:$G$50) | D21: =E21-C21 | E21: =SUMIF('BALANCE N'!$A$2:$A$50,"26*",'BALANCE N'!$F$2:$F$50)-SUMIF('BALANCE N'!$A$2:$A$50,"26*",'BALANCE N'!$G$2:$G$50)+SUMIF('BALANCE N'!$A$2:$A$50,"27*",'BALANCE N'!$F$2:$F$50)-SUMIF('BALANCE N'!$A$2:$A$50,"27*",'BALANCE N'!$G$2:$G$50)
A22: GS | B22: A - TOTAL DES IMMOBILISATIONS | C22: =C14+C15+C16+C17+C18+C19+C20+C21 | D22: =D14+D15+D16+D17+D18+D19+D20+D21 | E22: =E14+E15+E16+E17+E18+E19+E20+E21
A23: FM | B23: Achats de biens et services | D23: =SUMIF('BALANCE N'!$A$2:$A$50,"60*",'BALANCE N'!$F$2:$F$50)-SUMIF('BALANCE N'!$A$2:$A$50,"60*",'BALANCE N'!$G$2:$G$50) | E23: =C23+D23
A24: FN | B24: Transports | D24: =SUMIF('BALANCE N'!$A$2:$A$50,"61*",'BALANCE N'!$F$2:$F$50)-SUMIF('BALANCE N'!$A$2:$A$50,"61*",'BALANCE N'!$G$2:$G$50) | E24: =C24+D24
A25: FO | B25: Services extérieurs | D25: =SUMIF('BALANCE N'!$A$2:$A$50,"62*",'BALANCE N'!$F$2:$F$50)-SUMIF('BALANCE N'!$A$2:$A$50,"62*",'BALANCE N'!$G$2:$G$50)+SUMIF('BALANCE N'!$A$2:$A$50,"63*",'BALANCE N'!$F$2:$F$50)-SUMIF('BALANCE N'!$A$2:$A$50,"63*",'BALANCE N'!$G$2:$G$50) | E25: =C25+D25
A26: FP | B26: Impôts et taxes | D26: =SUMIF('BALANCE N'!$A$2:$A$50,"64*",'BALANCE N'!$F$2:$F$50)-SUMIF('BALANCE N'!$A$2:$A$50,"64*",'BALANCE N'!$G$2:$G$50) | E26: =C26+D26
A27: FQ | B27: Autres charges | D27: =SUMIF('BALANCE N'!$A$2:$A$50,"65*",'BALANCE N'!$F$2:$F$50)-SUMIF('BALANCE N'!$A$2:$A$50,"65*",'BALANCE N'!$G$2:$G$50) | E27: =C27+D27
A28: FR | B28: Charges de personnel | D28: =SUMIF('BALANCE N'!$A$2:$A$50,"66*",'BALANCE N'!$F$2:$F$50)-SUMIF('BALANCE N'!$A$2:$A$50,"66*",'BALANCE N'!$G$2:$G$50) | E28: =C28+D28
A29: FS | B29: Charges financières | D29: =SUMIF('BALANCE N'!$A$2:$A$50,"67*",'BALANCE N'!$F$2:$F$50)-SUMIF('BALANCE N'!$A$2:$A$50,"67*",'BALANCE N'!$G$2:$G$50) | E29: =C29+D29
A30: FT | B30: Avances sur charges (à justifier) | D30: =(SUMIF('BALANCE N'!$A$2:$A$50,"421*",'BALANCE N'!$F$2:$F$50))-(SUMIF('BALANCE N-1'!$A$2:$A$50,"421*",'BALANCE N-1'!$F$2:$F$50)) | E30: =C30+D30
A31: GT | B31: B - TOTAL DES CHARGES DE FONCTIONNEMENT | C31: =C23+C24+C25+C26+C27+C28+C29+C30 | D31: =D23+D24+D25+D26+D27+D28+D29+D30 | E31: =E23+E24+E25+E26+E27+E28+E29+E30
A32: GU | B32: II. EMPLOIS (A + B) | C32: =C22+C31 | D32: =D22+D31 | E32: =E22+E31
A33: GV | B33: III. EXCÉDENT / DÉFICIT DES FONDS REÇUS SUR LES EMPLOIS (I - II) | C33: =C13-C32 | D33: =D13-D32 | E33: =E13-E32
A34: FU | B34: Fonds Bailleur en début d'exercice N
A35: FV | B35: Fonds de contrepartie État en début d'exercice N
A36: FW | B36: Autres fonds en début d'exercice N
A37: GW | B37: IV. FONDS DISPONIBLE EN DÉBUT D'EXERCICE | C37: =C34+C35+C36 | D37: =D34+D35+D36 | E37: =E34+E35+E36
A38: GX | B38: V. MONTANT NET DE L'ENCAISSE DISPONIBLE (III + IV) | C38: =C33+C37 | D38: =D33+D37 | E38: =E33+E37
A39: FX | B39: Fonds Bailleur en fin d'exercice N
A40: FY | B40: Fonds de contrepartie État en fin d'exercice N
...

Sheet Execution budgetaire
A1: - 4 -
G2: EXECUTION BUDGETAIRE PROJETS DE DEVELOPPEMENT
A3: Dénomination sociale : PROJET EAU POTABLE RURALE
A4: Adresse : | G4: Sigle usuel : | H4: PEPR
A5: N° de compte contribuable (NCC) : PD-2023-017 | E5: Exercice clos le 31-12-2025 | G5: Durée (en mois) : 12
A6: N° de télédéclarant (NTD) :
A7: TABLEAU DE SUIVI D'EXECUTION DU BUDGET
A8: Code | B8: Libellé | C8: Budget de l'exercice (1) | D8: Décaissement (2) | E8: Engagement (3) | F8: Réalisation (4 = 2 + 3) | G8: Crédit disponible (5 = 1 - 4) | H8: Exécution budget % (4/1)
F9: =D9+E9 | G9: =C9-F9 | H9: =IF(C9=0,"",F9/C9)
F10: =D10+E10 | G10: =C10-F10 | H10: =IF(C10=0,"",F10/C10)
F11: =D11+E11 | G11: =C11-F11 | H11: =IF(C11=0,"",F11/C11)
F12: =D12+E12 | G12: =C12-F12 | H12: =IF(C12=0,"",F12/C12)
F13: =D13+E13 | G13: =C13-F13 | H13: =IF(C13=0,"",F13/C13)
F14: =D14+E14 | G14: =C14-F14 | H14: =IF(C14=0,"",F14/C14)
F15: =D15+E15 | G15: =C15-F15 | H15: =IF(C15=0,"",F15/C15)
F16: =D16+E16 | G16: =C16-F16 | H16: =IF(C16=0,"",F16/C16)
F17: =D17+E17 | G17: =C17-F17 | H17: =IF(C17=0,"",F17/C17)
F18: =D18+E18 | G18: =C18-F18 | H18: =IF(C18=0,"",F18/C18)
F19: =D19+E19 | G19: =C19-F19 | H19: =IF(C19=0,"",F19/C19)
F20: =D20+E20 | G20: =C20-F20 | H20: =IF(C20=0,"",F20/C20)
... F22: =D22+E22 | G22: =C22-F22 | H22: =IF(C22=0,"",F22/C22)
B23: TOTAL | C23: =SUM(C9:C22) | D23: =SUM(D9:D22) | E23: =SUM(E9:E22) | F23: =SUM(F9:F22) | G23: =SUM(G9:G22) | H23: =IF(C23=0,"",F23/C23)
A25: Remplir code et libellé suivant la nomenclature budgétaire du projet.

Sheet Reconciliation tresorerie
A1: - 5 -
B2: RECONCILIATION PROJETS DE DEVELOPPEMENT
A3: Dénomination sociale : PROJET EAU POTABLE RURALE
A4: Adresse : | C4: PEPR
A5: N° de compte contribuable (NCC) : PD-2023-017 | C5: Durée (en mois) : 12
A6: N° de télédéclarant (NTD) :
A7: TABLEAU DE RECONCILIATION DE LA TRESORERIE
A8: LIBELLE | B8: REP. | C8: MONTANT
A9: TRÉSORERIE EN DÉBUT D'EXERCICE N | B9: A | C9: =SUMIF('BALANCE N-1'!$A$2:$A$50,"5*",'BALANCE N-1'!$F$2:$F$50)-SUMIF('BALANCE N-1'!$A$2:$A$50,"5*",'BALANCE N-1'!$G$2:$G$50)-SUMIF('BALANCE N-1'!$A$2:$A$50,"59*",'BALANCE N-1'!$F$2:$F$50)+SUMIF('BALANCE N-1'!$A$2:$A$50,"59*",'BALANCE N-1'!$G$2:$G$50)
A10: FONDS REÇUS DES BAILLEURS AU COURS DE L'EXERCICE N | B10: B | C10: ='Emplois-Ressources'!D9+'Emplois-Ressources'!D10+'Emplois-Ressources'!D11
A11: INTÉRÊTS REÇUS AU COURS DE L'EXERCICE N | B11: C | C11: =SUMIF('BALANCE N'!$A$2:$A$50,"77*",'BALANCE N'!$G$2:$G$50)-SUMIF('BALANCE N'!$A$2:$A$50,"77*",'BALANCE N'!$F$2:$F$50)
A12: AUTRES FONDS REÇUS AU COURS DE L'EXERCICE N | B12: D | C12: ='Emplois-Ressources'!D12
A13: VIREMENTS SUR COMPTES OPÉRATIONNELS | B13: E
A14: DÉPENSES DE L'EXERCICE N | B14: F | C14: ='Emplois-Ressources'!D32
A15: TRÉSORERIE EN FIN D'EXERCICE N (A+B+C+D-E-F) | B15: G | C15: =C9+C10+C11+C12-C13-C14
A16: PAIEMENTS EN INSTANCE | B16: H
A17: TRÉSORERIE NETTE DES PAIEMENTS EN INSTANCE (G-H) | B17: I | C17: =C15-C16
A19: Rappel balance - trésorerie de clôture (classe 5 nette) : | C19: =(SUMIF('BALANCE N'!$A$2:$A$50,"5*",'BALANCE N'!$F$2:$F$50)-SUMIF('BALANCE N'!$A$2:$A$50,"5*",'BALANCE N'!$G$2:$G$50)-SUMIF('BALANCE N'!$A$2:$A$50,"59*",'BALANCE N'!$F$2:$F$50)+SUMIF('BALANCE N'!$A$2:$A$50,"59*",'BALANCE N'!$G$2:$G$50))-(SUMIF('BALANCE N'!$A$2:$A$50,"59*",'BALANCE N'!$G$2:$G$50)-SUMIF('BALANCE N'!$A$2:$A$50,"599*",'BALANCE N'!$G$2:$G$50))
A20: Écart avec la ligne G (dépenses non décaissées, créances : à expliquer en NOTE 2) : | C20: =C15-C19

Sheet Bilan paysage
A1: - 6 -
I2: BILAN PAGE 1/1 PROJETS DE DEVELOPPEMENT
A3: Dénomination sociale : PROJET EAU POTABLE RURALE
A4: Adresse : | I4: Sigle usuel : | J4: PEPR
A5: N° de compte contribuable (NCC) : PD-2023-017 | G5: Exercice clos le 31-12-2025 | I5: Durée (en mois) : 12
A6: N° de télédéclarant (NTD) :
C7: BILAN
A8: REF | B8: ACTIF | C8: NOTE | D8: NET | E8: NET N-1 | F8: REF | G8: PASSIF | H8: NOTE | I8: NET | J8: NET N-1
A10: AA | B10: Immobilisations incorporelles | C10: 3A | D10: ='Bilan-Actif'!D9 | E10: ='Bilan-Actif'!E9 | F10: CA | G10: Fonds affectes aux investissements | H10: 9 | I10: ='Bilan-Passif'!D9 | J10: ='Bilan-Passif'!E9
A11: AB | B11: Terrains et batiments | C11: 3A | D11: ='Bilan-Actif'!D10 | E11: ='Bilan-Actif'!E10 | F11: CB | G11: Report a nouveau (+ ou -) | I11: ='Bilan-Passif'!D10 | J11: ='Bilan-Passif'!E10
A12: AC | B12: Amenagements, agencements et installations | C12: 3A | D12: ='Bilan-Actif'!D11 | E12: ='Bilan-Actif'!E11 | F12: CC | G12: Solde des operations de l'exercice | I12: ='Bilan-Passif'!D11 | J12: ='Bilan-Passif'!E11
A13: AD | B13: Materiel, mobilier et actifs biologiques | C13: 3A | D13: ='Bilan-Actif'!D12 | E13: ='Bilan-Actif'!E12 | F13: CD | G13: Subventions d'investissement | H13: 10 | I13: ='Bilan-Passif'!D12 | J13: ='Bilan-Passif'!E12
A14: AE | B14: Materiel de transport | C14: 3A | D14: ='Bilan-Actif'!D13 | E14: ='Bilan-Actif'!E13 | F14: CZ | G14: TOTAL RESSOURCES PROPRES ET ASSIMILEES | I14: ='Bilan-Passif'!D13 | J14: ='Bilan-Passif'!E13
A15: AF | B15: Avances et acomptes verses sur immobilisations | C15: 3A | D15: ='Bilan-Actif'!D14 | E15: ='Bilan-Actif'!E14 | F15: DA | G15: Emprunts et dettes assimilees | H15: 11 | I15: ='Bilan-Passif'!D14 | J15: ='Bilan-Passif'!E14
A16: AG | B16: Depots et cautionnements | C16: 3A | D16: ='Bilan-Actif'!D15 | E16: ='Bilan-Actif'!E15 | F16: DB | G16: Provisions pour risques et charges | H16: 11 | I16: ='Bilan-Passif'!D15 | J16: ='Bilan-Passif'!E15
A17: AH | B17: Autres immobilisations corporelles et financieres | C17: 3A | D17: ='Bilan-Actif'!D16 | E17: ='Bilan-Actif'!E16 | F17: DC | G17: TOTAL DETTES FINANCIERES ET RESSOURCES ASSIMILEES | I17: ='Bilan-Passif'!D16 | J17: ='Bilan-Passif'!E16
A18: AZ | B18: TOTAL ACTIF IMMOBILISE | D18: ='Bilan-Actif'!D17 | E18: ='Bilan-Actif'!E17 | F18: DD | G18: TOTAL RESSOURCES STABLES | I18: ='Bilan-Passif'!D17 | J18: ='Bilan-Passif'!E17
A19: BA | B19: Actif circulant HAO | C19: 4 | D19: ='Bilan-Actif'!D18 | E19: ='Bilan-Actif'!E18 | F19: DE | G19: Dettes circulantes HAO | H19: 4 | I19: ='Bilan-Passif'!D18 | J19: ='Bilan-Passif'!E18
A20: BB | B20: Stocks et encours | C20: 5 | D20: ='Bilan-Actif'!D19 | E20: ='Bilan-Actif'!E19 | F20: DF | G20: Fonds d'administration | H20: 9 | I20: ='Bilan-Passif'!D19 | J20: ='Bilan-Passif'!E19
A21: BC | B21: Fournisseurs debiteurs | C21: 6 | D21: ='Bilan-Actif'!D20 | E21: ='Bilan-Actif'!E20 | F21: DG | G21: Fournisseurs | H21: 12 | I21: ='Bilan-Passif'!D20 | J21: ='Bilan-Passif'!E20
A22: BD | B22: Clients-usagers | C22: 6 | D22: ='Bilan-Actif'!D21 | E22: ='Bilan-Actif'!E21 | F22: DH | G22: Autres dettes | H22: 12 | I22: ='Bilan-Passif'!D21 | J22: ='Bilan-Passif'!E21
A23: BE | B23: Autres creances | C23: 6 | D23: ='Bilan-Actif'!D22 | E23: ='Bilan-Actif'!E22 | F23: DI | G23: Provisions pour risques et charges a court terme | I23: ='Bilan-Passif'!D22 | J23: ='Bilan-Passif'!E22
A24: BF | B24: TOTAL ACTIF CIRCULANT | D24: ='Bilan-Actif'!D23 | E24: ='Bilan-Actif'!E23 | F24: DJ | G24: TOTAL PASSIF CIRCULANT | I24: ='Bilan-Passif'!D23 | J24: ='Bilan-Passif'!E23
A25: BV | B25: Valeurs a encaisser | C25: 7 | D25: ='Bilan-Actif'!D24 | E25: ='Bilan-Actif'!E24 | F25: DW | G25: Banques, etablissements financiers et credits de tresorerie | H25: 13 | I25: ='Bilan-Passif'!D24 | J25: ='Bilan-Passif'!E24
A26: BW | B26: Banques, etablissements financiers, caisses et assimiles | C26: 7 | D26: ='Bilan-Actif'!D25 | E26: ='Bilan-Actif'!E25 | F26: DX | G26: TOTAL TRESORERIE PASSIF | I26: ='Bilan-Passif'!D25 | J26: ='Bilan-Passif'!E25
A27: BX | B27: TOTAL TRESORERIE ACTIF | D27: ='Bilan-Actif'!D26 | E27: ='Bilan-Actif'!E26 | F27: DY | G27: Ecart de conversion-Passif | H27: 8 | I27: ='Bilan-Passif'!D26 | J27: ='Bilan-Passif'!E26
A28: BY | B28: Ecart de conversion-Actif | C28: 8 | D28: ='Bilan-Actif'!D27 | E28: ='Bilan-Actif'!E27 | F28: DZ | G28: TOTAL GENERAL | I28: ='Bilan-Passif'!D27 | J28: ='Bilan-Passif'!E27
A29: BZ | B29: TOTAL GENERAL | D29: ='Bilan-Actif'!D28 | E29: ='Bilan-Actif'!E28

Sheet Bilan-Actif
A1: - 7 -
D2: BILAN PAGE 1/2 PROJETS DE DEVELOPPEMENT
A3: Dénomination sociale : PROJET EAU POTABLE RURALE
A4: Adresse : | D4: Sigle usuel : | E4: PEPR
A5: N° de compte contribuable (NCC) : PD-2023-017 | C5: Exercice clos le 31-12-2025 | D5: Durée (en mois) : 12
A6: N° de télédéclarant (NTD) :
A7: BILAN (EN NET)
A8: REF | B8: ACTIF | C8: NOTE | D8: EXERCICE AU 31/12/N | E8: EXERCICE AU 31/12/N-1
A9: AA | B9: Immobilisations incorporelles | C9: 3A | D9: =((SUMIF('BALANCE N'!$A$2:$A$50,"21*",'BALANCE N'!$F$2:$F$50)-SUMIF('BALANCE N'!$A$2:$A$50,"21*",'BALANCE N'!$G$2:$G$50)))-((SUMIF('BALANCE N'!$A$2:$A$50,"291*",'BALANCE N'!$G$2:$G$50)-SUMIF('BALANCE N'!$A$2:$A$50,"291*",'BALANCE N'!$F$2:$F$50)+SUMIF('BALANCE N'!$A$2:$A$50,"281*",'BALANCE N'!$G$2:$G$50)-SUMIF('BALANCE N'!$A$2:$A$50,"281*",'BALANCE N'!$F$2:$F$50))) | E9: =((SUMIF('BALANCE N-1'!$A$2:$A$50,"21*",'BALANCE N-1'!$F$2:$F$50)-SUMIF('BALANCE N-1'!$A$2:$A$50,"21*",'BALANCE N-1'!$G$2:$G$50)))-((SUMIF('BALANCE N-1'!$A$2:$A$50,"291*",'BALANCE N-1'!$G$2:$G$50)-SUMIF('BALANCE N-1'!$A$2:$A$50,"291*",'BALANCE N-1'!$F$2:$F$50)+SUMIF('BALANCE N-1'!$A$2:$A$50,"281*",'BALANCE N-1'!$G$2:$G$50)-SUMIF('BALANCE N-1'!$A$2:$A$50,"281*",'BALANCE N-1'!$F$2:$F$50)))
A10: AB | B10: Terrains et batiments | C10: 3A | D10: =((SUMIF('BALANCE N'!$A$2:$A$50,"22*",'BALANCE N'!$F$2:$F$50)-SUMIF('BALANCE N'!$A$2:$A$50,"22*",'BALANCE N'!$G$2:$G$50)+SUMIF('BALANCE N'!$A$2:$A$50,"231*",'BALANCE N'!$F$2:$F$50)-SUMIF('BALANCE N'!$A$2:$A$50,"231*",'BALANCE N'!$G$2:$G$50)+SUMIF('BALANCE N'!$A$2:$A$50,"232*",'BALANCE N'!$F$2:$F$50)-SUMIF('BALANCE N'!$A$2:$A$50,"232*",'BALANCE N'!$G$2:$G$50)+SUMIF('BALANCE N'!$A$2:$A$50,"233*",'BALANCE N'!$F$2:$F$50)-SUMIF('BALANCE N'!$A$2:$A$50,"233*",'BALANCE N'!$G$2:$G$50)+SUMIF('BALANCE N'!$A$2:$A$50,"2393*",'BALANCE N'!$F$2:$F$50)-SUMIF('BALANCE N'!$A$2:$A$50,"2393*",'BALANCE N'!$G$2:$G$50)+SUMIF('BALANCE N'!$A$2:$A$50,"2396*",'BALANCE N'!$F$2:$F$50)-SUMIF('BALANCE N'!$A$2:$A$50,"2396*",'BALANCE N'!$G$2:$G$50)+SUMIF('BALANCE N'!$A$2:$A$50,"2391*",'BALANCE N'!$F$2:$F$50)-SUMIF('BALANCE N'!$A$2:$A$50,"2391*",'BALANCE N'!$G$2:$G$50)+SUMIF('BALANCE N'!$A$2:$A$50,"2392*",'BALANCE N'!$F$2:$F$50)-SUMIF('BALANCE N'!$A$2:$A$50,"2392*",'BALANCE N'!$G$2:$G$50)))-((SUMIF('BALANCE N'!$A$2:$A$50,"282*",'BALANCE N'!$G$2:$G$50)-SUMIF('BALANCE N'!$A$2:$A$50,"282*",'BALANCE N'!$F$2:$F$50)+SUMIF('BALANCE N'!$A$2:$A$50,"292*",'BALANCE N'!$G$2:$G$50)-SUMIF('BALANCE N'!$A$2:$A$50,"292*",'BALANCE N'!$F$2:$F$50)+SUMIF('BALANCE N'!$A$2:$A$50,"2933*",'BALANCE N'!$G$2:$G$50)-SUMIF('BALANCE N'!$A$2:$A$50,"2933*",'BALANCE N'!$F$2:$F$50)+SUMIF('BALANCE N'!$A$2:$A$50,"2932*",'BALANCE N'!$G$2:$G$50)-SUMIF('BALANCE N'!$A$2:$A$50,"2932*",'BALANCE N'!$F$2:$F$50)+SUMIF('BALANCE N'!$A$2:$A$50,"2832*",'BALANCE N'!$G$2:$G$50)-SUMIF('BALANCE N'!$A$2:$A$50,"2832*",'BALANCE N'!$F$2:$F$50)+SUMIF('BALANCE N'!$A$2:$A$50,"2831*",'BALANCE N'!$G$2:$G$50)-SUMIF('BALANCE N'!$A$2:$A$50,"2831*",'BALANCE N'!$F$2:$F$50)+SUMIF('BALANCE N'!$A$2:$A$50,"2833*",'BALANCE N'!$G$2:$G$50)-SUMIF('BALANCE N'!$A$2:$A$50,"2833*",'BALANCE N'!$F$2:$F$50)+SUMIF('BALANCE N'!$A$2:$A$50,"2931*",'BALANCE N'!$G$2:$G$50)-SUMIF('BALANCE N'!$A$2:$A$50,"2931*",'BALANCE N'!$F$2:$F$50)+SUMIF('BALANCE N'!$A$2:$A$50,"2939*",'BALANCE N'!$G$2:$G$50)-SUMIF('BALANCE N'!$A$2:$A$50,"2939*",'BALANCE N'!$F$2:$F$50))) | E10: =((SUMIF('BALANCE N-1'!$A$2:$A$50,"22*",'BALANCE N-1'!$F$2:$F$50)-SUMIF('BALANCE N-1'!$A$2:$A$50,"22*",'BALANCE N-1'!$G$2:$G$50)+SUMIF('BALANCE N-1'!$A$2:$A$50,"231*",'BALANCE N-1'!$F$2:$F$50)-SUMIF('BALANCE N-1'!$A$2:$A$50,"231*",'BALANCE N-1'!$G$2:$G$50)+SUMIF('BALANCE N-1'!$A$2:$A$50,"232*",'BALANCE N-1'!$F$2:$F$50)-SUMIF('BALANCE N-1'!$A$2:$A$50,"232*",'BALANCE N-1'!$G$2:$G$50)+SUMIF('BALANCE N-1'!$A$2:$A$50,"233*",'BALANCE N-1'!$F$2:$F$50)-SUMIF('BALANCE N-1'!$A$2:$A$50,"233*",'BALANCE N-1'!$G$2:$G$50)+SUMIF('BALANCE N-1'!$A$2:$A$50,"2393*",'BALANCE N-1'!$F$2:$F$50)-SUMIF('BALANCE N-1'!$A$2:$A$50,"2393*",'BALANCE N-1'!$G$2:$G$50)+SUMIF('BALANCE N-1'!$A$2:$A$50,"2396*",'BALANCE N-1'!$F$2:$F$50)-SUMIF('BALANCE N-1'!$A$2:$A$50,"2396*",'BALANCE N-1'!$G$2:$G$50)+SUMIF('BALANCE N-1'!$A$2:$A$50,"2391*",'BALANCE N-1'!$F$2:$F$50)-SUMIF('BALANCE N-1'!$A$2:$A$50,"2391*",'BALANCE N-1'!$G$2:$G$50)+SUMIF('BALANCE N-1'!$A$2:$A$50,"2392*",'BALANCE N-1'!$F$2:$F$50)-SUMIF('BALANCE N-1'!$A$2:$A$50,"2392*",'BALANCE N-1'!$G$2:$G$50)))-((SUMIF('BALANCE N-1'!$A$2:$A$50,"282*",'BALANCE N-1'!$G$2:$G$50)-SUMIF('BALANCE N-1'!$A$2:$A$50,"282*",'BALANCE N-1'!$F$2:$F$50)+SUMIF('BALANCE N-1'!$A$2:$A$50,"292*",'BALANCE N-1'!$G$2:$G$50)-SUMIF('BALANCE N-1'!$A$2:$A$50,"292*",'BALANCE N-1'!$F$2:$F$50)+SUMIF('BALANCE N-1'!$A$2:$A$50,"2933*",'BALANCE N-1'!$G$2:$G$50)-SUMIF('BALANCE N-1'!$A$2:$A$50,"2933*",'BALANCE N-1'!$F$2:$F$50)+SUMIF('BALANCE N-1'!$A$2:$A$50,"2932*",'BALANCE N-1'!$G$2:$G$50)-SUMIF('BALANCE N-1'!$A$2:$A$50,"2932*",'BALANCE N-1'!$F$2:$F$50)+SUMIF('BALANCE N-1'!$A$2:$A$50,"2832*",'BALANCE N-1'!$G$2:$G$50)-SUMIF('BALANCE N-1'!$A$2:$A$50,"2832*",'BALANCE N-1'!$F$2:$F$50)+SUMIF('BALANCE N-1'!$A$2:$A$50,"2831*",'BALANCE N-1'!$G$2:$G$50)-SUMIF('BALANCE N-1'!$A$2:$A$50,"2831*",'BALANCE N-1'!$F$2:$F$50)+SUMIF('BALANCE N-1'!$A$2:$A$50,"2833*",'BALANCE N-1'!$G$2:$G$50)-SUMIF('BALANCE N-1'!$A$2:$A$50,"2833*",'BALANCE N-1'!$F$2:$F$50)+SUMIF('BALANCE N-1'!$A$2:$A$50,"2931*",'BALANCE N-1'!$G$2:$G$50)-SUMIF('BALANCE N-1'!$A$2:$A$50,"2931*",'BALANCE N-1'!$F$2:$F$50)+SUMIF('BALANCE N-1'!$A$2:$A$50,"2939*",'BALANCE N-1'!$G$2:$G$50)-SUMIF('BALANCE N-1'!$A$2:$A$50,"2939*",'BALANCE N-1'!$F$2:$F$50)))
A11: AC | B11: Amenagements, agencements et installations | C11: 3A | D11: =((SUMIF('BALANCE N'!$A$2:$A$50,"238*",'BALANCE N'!$F$2:$F$50)-SUMIF('BALANCE N'!$A$2:$A$50,"238*",'BALANCE N'!$G$2:$G$50)+SUMIF('BALANCE N'!$A$2:$A$50,"234*",'BALANCE N'!$F$2:$F$50)-SUMIF('BALANCE N'!$A$2:$A$50,"234*",'BALANCE N'!$G$2:$G$50)+SUMIF('BALANCE N'!$A$2:$A$50,"235*",'BALANCE N'!$F$2:$F$50)-SUMIF('BALANCE N'!$A$2:$A$50,"235*",'BALANCE N'!$G$2:$G$50)+SUMIF('BALANCE N'!$A$2:$A$50,"2394*",'BALANCE N'!$F$2:$F$50)-SUMIF('BALANCE N'!$A$2:$A$50,"2394*",'BALANCE N'!$G$2:$G$50)+SUMIF('BALANCE N'!$A$2:$A$50,"2398*",'BALANCE N'!$F$2:$F$50)-SUMIF('BALANCE N'!$A$2:$A$50,"2398*",'BALANCE N'!$G$2:$G$50)+SUMIF('BALANCE N'!$A$2:$A$50,"2395*",'BALANCE N'!$F$2:$F$50)-SUMIF('BALANCE N'!$A$2:$A$50,"2395*",'BALANCE N'!$G$2:$G$50)))-((SUMIF('BALANCE N'!$A$2:$A$50,"2834*",'BALANCE N'!$G$2:$G$50)-SUMIF('BALANCE N'!$A$2:$A$50,"2834*",'BALANCE N'!$F$2:$F$50)+SUMIF('BALANCE N'!$A$2:$A$50,"2838*",'BALANCE N'!$G$2:$G$50)-SUMIF('BALANCE N'!$A$2:$A$50,"2838*",'BALANCE N'!$F$2:$F$50)+SUMIF('BALANCE N'!$A$2:$A$50,"2935*",'BALANCE N'!$G$2:$G$50)-SUMIF('BALANCE N'!$A$2:$A$50,"2935*",'BALANCE N'!$F$2:$F$50)+SUMIF('BALANCE N'!$A$2:$A$50,"2934*",'BALANCE N'!$G$2:$G$50)-SUMIF('BALANCE N'!$A$2:$A$50,"2934*",'BALANCE N'!$F$2:$F$50)+SUMIF('BALANCE N'!$A$2:$A$50,"2938*",'BALANCE N'!$G$2:$G$50)-SUMIF('BALANCE N'!$A$2:$A$50,"2938*",'BALANCE N'!$F$2:$F$50)+SUMIF('BALANCE N'!$A$2:$A$50,"2835*",'BALANCE N'!$G$2:$G$50)-SUMIF('BALANCE N'!$A$2:$A$50,"2835*",'BALANCE N'!$F$2:$F$50))) | E11: =((SUMIF('BALANCE N-1'!$A$2:$A$50,"238*",'BALANCE N-1'!$F$2:$F$50)-SUMIF('BALANCE N-1'!$A$2:$A$50,"238*",'BALANCE N-1'!$G$2:$G$50)+SUMIF('BALANCE N-1'!$A$2:$A$50,"234*",'BALANCE N-1'!$F$2:$F$50)-SUMIF('BALANCE N-1'!$A$2:$A$50,"234*",'BALANCE N-1'!$G$2:$G$50)+SUMIF('BALANCE N-1'!$A$2:$A$50,"235*",'BALANCE N-1'!$F$2:$F$50)-SUMIF('BALANCE N-1'!$A$2:$A$50,"235*",'BALANCE N-1'!$G$2:$G$50)+SUMIF('BALANCE N-1'!$A$2:$A$50,"2394*",'BALANCE N-1'!$F$2:$F$50)-SUMIF('BALANCE N-1'!$A$2:$A$50,"2394*",'BALANCE N-1'!$G$2:$G$50)+SUMIF('BALANCE N-1'!$A$2:$A$50,"2398*",'BALANCE N-1'!$F$2:$F$50)-SUMIF('BALANCE N-1'!$A$2:$A$50,"2398*",'BALANCE N-1'!$G$2:$G$50)+SUMIF('BALANCE N-1'!$A$2:$A$50,"2395*",'BALANCE N-1'!$F$2:$F$50)-SUMIF('BALANCE N-1'!$A$2:$A$50,"2395*",'BALANCE N-1'!$G$2:$G$50)))-((SUMIF('BALANCE N-1'!$A$2:$A$50,"2834*",'BALANCE N-1'!$G$2:$G$50)-SUMIF('BALANCE N-1'!$A$2:$A$50,"2834*",'BALANCE N-1'!$F$2:$F$50)+SUMIF('BALANCE N-1'!$A$2:$A$50,"2838*",'BALANCE N-1'!$G$2:$G$50)-SUMIF('BALANCE N-1'!$A$2:$A$50,"2838*",'BALANCE N-1'!$F$2:$F$50)+SUMIF('BALANCE N-1'!$A$2:$A$50,"2935*",'BALANCE N-1'!$G$2:$G$50)-SUMIF('BALANCE N-1'!$A$2:$A$50,"2935*",'BALANCE N-1'!$F$2:$F$50)+SUMIF('BALANCE N-1'!$A$2:$A$50,"2934*",'BALANCE N-1'!$G$2:$G$50)-SUMIF('BALANCE N-1'!$A$2:$A$50,"2934*",'BALANCE N-1'!$F$2:$F$50)+SUMIF('BALANCE N-1'!$A$2:$A$50,"2938*",'BALANCE N-1'!$G$2:$G$50)-SUMIF('BALANCE N-1'!$A$2:$A$50,"2938*",'BALANCE N-1'!$F$2:$F$50)+SUMIF('BALANCE N-1'!$A$2:$A$50,"2835*",'BALANCE N-1'!$G$2:$G$50)-SUMIF('BALANCE N-1'!$A$2:$A$50,"2835*",'BALANCE N-1'!$F$2:$F$50)))
A12: AD | B12: Materiel, mobilier et actifs biologiques | C12: 3A | D12: =((SUMIF('BALANCE N'!$A$2:$A$50,"24*",'BALANCE N'!$F$2:$F$50)-SUMIF('BALANCE N'!$A$2:$A$50,"24*",'BALANCE N'!$G$2:$G$50)-SUMIF('BALANCE N'!$A$2:$A$50,"245*",'BALANCE N'!$F$2:$F$50)+SUMIF('BALANCE N'!$A$2:$A$50,"245*",'BALANCE N'!$G$2:$G$50)-SUMIF('BALANCE N'!$A$2:$A$50,"2495*",'BALANCE N'!$F$2:$F$50)+SUMIF('BALANCE N'!$A$2:$A$50,"2495*",'BALANCE N'!$G$2:$G$50)))-((SUMIF('BALANCE N'!$A$2:$A$50,"284*",'BALANCE N'!$G$2:$G$50)-SUMIF('BALANCE N'!$A$2:$A$50,"284*",'BALANCE N'!$F$2:$F$50)+SUMIF('BALANCE N'!$A$2:$A$50,"294*",'BALANCE N'!$G$2:$G$50)-SUMIF('BALANCE N'!$A$2:$A$50,"294*",'BALANCE N'!$F$2:$F$50)-SUMIF('BALANCE N'!$A$2:$A$50,"2945*",'BALANCE N'!$G$2:$G$50)+SUMIF('BALANCE N'!$A$2:$A$50,"2945*",'BALANCE N'!$F$2:$F$50)-SUMIF('BALANCE N'!$A$2:$A$50,"2845*",'BALANCE N'!$G$2:$G$50)+SUMIF('BALANCE N'!$A$2:$A$50,"2845*",'BALANCE N'!$F$2:$F$50))) | E12: =((SUMIF('BALANCE N-1'!$A$2:$A$50,"24*",'BALANCE N-1'!$F$2:$F$50)-SUMIF('BALANCE N-1'!$A$2:$A$50,"24*",'BALANCE N-1'!$G$2:$G$50)-SUMIF('BALANCE N-1'!$A$2:$A$50,"245*",'BALANCE N-1'!$F$2:$F$50)+SUMIF('BALANCE N-1'!$A$2:$A$50,"245*",'BALANCE N-1'!$G$2:$G$50)-SUMIF('BALANCE N-1'!$A$2:$A$50,"2495*",'BALANCE N-1'!$F$2:$F$50)+SUMIF('BALANCE N-1'!$A$2:$A$50,"2495*",'BALANCE N-1'!$G$2:$G$50)))-((SUMIF('BALANCE N-1'!$A$2:$A$50,"284*",'BALANCE N-1'!$G$2:$G$50)-SUMIF('BALANCE N-1'!$A$2:$A$50,"284*",'BALANCE N-1'!$F$2:$F$50)+SUMIF('BALANCE N-1'!$A$2:$A$50,"294*",'BALANCE N-1'!$G$2:$G$50)-SUMIF('BALANCE N-1'!$A$2:$A$50,"294*",'BALANCE N-1'!$F$2:$F$50)-SUMIF('BALANCE N-1'!$A$2:$A$50,"2945*",'BALANCE N-1'!$G$2:$G$50)+SUMIF('BALANCE N-1'!$A$2:$A$50,"2945*",'BALANCE N-1'!$F$2:$F$50)-SUMIF('BALANCE N-1'!$A$2:$A$50,"2845*",'BALANCE N-1'!$G$2:$G$50)+SUMIF('BALANCE N-1'!$A$2:$A$50,"2845*",'BALANCE N-1'!$F$2:$F$50)))
A13: AE | B13: Materiel de transport | C13: 3A | D13: =((SUMIF('BALANCE N'!$A$2:$A$50,"245*",'BALANCE N'!$F$2:$F$50)-SUMIF('BALANCE N'!$A$2:$A$50,"245*",'BALANCE N'!$G$2:$G$50)+SUMIF('BALANCE N'!$A$2:$A$50,"2495*",'BALANCE N'!$F$2:$F$50)-SUMIF('BALANCE N'!$A$2:$A$50,"2495*",'BALANCE N'!$G$2:$G$50)))-((SUMIF('BALANCE N'!$A$2:$A$50,"2945*",'BALANCE N'!$G$2:$G$50)-SUMIF('BALANCE N'!$A$2:$A$50,"2945*",'BALANCE N'!$F$2:$F$50)+SUMIF('BALANCE N'!$A$2:$A$50,"2845*",'BALANCE N'!$G$2:$G$50)-SUMIF('BALANCE N'!$A$2:$A$50,"2845*",'BALANCE N'!$F$2:$F$50))) | E13: =((SUMIF('BALANCE N-1'!$A$2:$A$50,"245*",'BALANCE N-1'!$F$2:$F$50)-SUMIF('BALANCE N-1'!$A$2:$A$50,"245*",'BALANCE N-1'!$G$2:$G$50)+SUMIF('BALANCE N-1'!$A$2:$A$50,"2495*",'BALANCE N-1'!$F$2:$F$50)-SUMIF('BALANCE N-1'!$A$2:$A$50,"2495*",'BALANCE N-1'!$G$2:$G$50)))-((SUMIF('BALANCE N-1'!$A$2:$A$50,"2945*",'BALANCE N-1'!$G$2:$G$50)-SUMIF('BALANCE N-1'!$A$2:$A$50,"2945*",'BALANCE N-1'!$F$2:$F$50)+SUMIF('BALANCE N-1'!$A$2:$A$50,"2845*",'BALANCE N-1'!$G$2:$G$50)-SUMIF('BALANCE N-1'!$A$2:$A$50,"2845*",'BALANCE N-1'!$F$2:$F$50)))
A14: AF | B14: Avances et acomptes verses sur immobilisations | C14: 3A | D14: =((SUMIF('BALANCE N'!$A$2:$A$50,"25*",'BALANCE N'!$F$2:$F$50)-SUMIF('BALANCE N'!$A$2:$A$50,"25*",'BALANCE N'!$G$2:$G$50)))-((SUMIF('BALANCE N'!$A$2:$A$50,"295*",'BALANCE N'!$G$2:$G$50)-SUMIF('BALANCE N'!$A$2:$A$50,"295*",'BALANCE N'!$F$2:$F$50))) | E14: =((SUMIF('BALANCE N-1'!$A$2:$A$50,"25*",'BALANCE N-1'!$F$2:$F$50)-SUMIF('BALANCE N-1'!$A$2:$A$50,"25*",'BALANCE N-1'!$G$2:$G$50)))-((SUMIF('BALANCE N-1'!$A$2:$A$50,"295*",'BALANCE N-1'!$G$2:$G$50)-SUMIF('BALANCE N-1'!$A$2:$A$50,"295*",'BALANCE N-1'!$F$2:$F$50)))
A15: AG | B15: Depots et cautionnements | C15: 3A | D15: =((SUMIF('BALANCE N'!$A$2:$A$50,"275*",'BALANCE N'!$F$2:$F$50)-SUMIF('BALANCE N'!$A$2:$A$50,"275*",'BALANCE N'!$G$2:$G$50)))-((SUMIF('BALANCE N'!$A$2:$A$50,"2975*",'BALANCE N'!$G$2:$G$50)-SUMIF('BALANCE N'!$A$2:$A$50,"2975*",'BALANCE N'!$F$2:$F$50))) | E15: =((SUMIF('BALANCE N-1'!$A$2:$A$50,"275*",'BALANCE N-1'!$F$2:$F$50)-SUMIF('BALANCE N-1'!$A$2:$A$50,"275*",'BALANCE N-1'!$G$2:$G$50)))-((SUMIF('BALANCE N-1'!$A$2:$A$50,"2975*",'BALANCE N-1'!$G$2:$G$50)-SUMIF('BALANCE N-1'!$A$2:$A$50,"2975*",'BALANCE N-1'!$F$2:$F$50)))
A16: AH | B16: Autres immobilisations corporelles et financieres | C16: 3A | D16: =((SUMIF('BALANCE N'!$A$2:$A$50,"26*",'BALANCE N'!$F$2:$F$50)-SUMIF('BALANCE N'!$A$2:$A$50,"26*",'BALANCE N'!$G$2:$G$50)+SUMIF('BALANCE N'!$A$2:$A$50,"27*",'BALANCE N'!$F$2:$F$50)-SUMIF('BALANCE N'!$A$2:$A$50,"27*",'BALANCE N'!$G$2:$G$50)-SUMIF('BALANCE N'!$A$2:$A$50,"275*",'BALANCE N'!$F$2:$F$50)+SUMIF('BALANCE N'!$A$2:$A$50,"275*",'BALANCE N'!$G$2:$G$50)))-((SUMIF('BALANCE N'!$A$2:$A$50,"296*",'BALANCE N'!$G$2:$G$50)-SUMIF('BALANCE N'!$A$2:$A$50,"296*",'BALANCE N'!$F$2:$F$50)+SUMIF('BALANCE N'!$A$2:$A$50,"297*",'BALANCE N'!$G$2:$G$50)-SUMIF('BALANCE N'!$A$2:$A$50,"297*",'BALANCE N'!$F$2:$F$50)-SUMIF('BALANCE N'!$A$2:$A$50,"2975*",'BALANCE N'!$G$2:$G$50)+SUMIF('BALANCE N'!$A$2:$A$50,"2975*",'BALANCE N'!$F$2:$F$50))) | E16: =((SUMIF('BALANCE N-1'!$A$2:$A$50,"26*",'BALANCE N-1'!$F$2:$F$50)-SUMIF('BALANCE N-1'!$A$2:$A$50,"26*",'BALANCE N-1'!$G$2:$G$50)+SUMIF('BALANCE N-1'!$A$2:$A$50,"27*",'BALANCE N-1'!$F$2:$F$50)-SUMIF('BALANCE N-1'!$A$2:$A$50,"27*",'BALANCE N-1'!$G$2:$G$50)-SUMIF('BALANCE N-1'!$A$2:$A$50,"275*",'BALANCE N-1'!$F$2:$F$50)+SUMIF('BALANCE N-1'!$A$2:$A$50,"275*",'BALANCE N-1'!$G$2:$G$50)))-((SUMIF('BALANCE N-1'!$A$2:$A$50,"296*",'BALANCE N-1'!$G$2:$G$50)-SUMIF('BALANCE N-1'!$A$2:$A$50,"296*",'BALANCE N-1'!$F$2:$F$50)+SUMIF('BALANCE N-1'!$A$2:$A$50,"297*",'BALANCE N-1'!$G$2:$G$50)-SUMIF('BALANCE N-1'!$A$2:$A$50,"297*",'BALANCE N-1'!$F$2:$F$50)-SUMIF('BALANCE N-1'!$A$2:$A$50,"2975*",'BALANCE N-1'!$G$2:$G$50)+SUMIF('BALANCE N-1'!$A$2:$A$50,"2975*",'BALANCE N-1'!$F$2:$F$50)))
A17: AZ | B17: TOTAL ACTIF IMMOBILISE | D17: =D9+D10+D11+D12+D13+D14+D15+D16 | E17: =E9+E10+E11+E12+E13+E14+E15+E16
A18: BA | B18: Actif circulant HAO | C18: 4 | D18: =((SUMIF('BALANCE N'!$A$2:$A$50,"485*",'BALANCE N'!$F$2:$F$50)-SUMIF('BALANCE N'!$A$2:$A$50,"485*",'BALANCE N'!$G$2:$G$50)))-((SUMIF('BALANCE N'!$A$2:$A$50,"498*",'BALANCE N'!$G$2:$G$50)-SUMIF('BALANCE N'!$A$2:$A$50,"498*",'BALANCE N'!$F$2:$F$50))) | E18: =((SUMIF('BALANCE N-1'!$A$2:$A$50,"485*",'BALANCE N-1'!$F$2:$F$50)-SUMIF('BALANCE N-1'!$A$2:$A$50,"485*",'BALANCE N-1'!$G$2:$G$50)))-((SUMIF('BALANCE N-1'!$A$2:$A$50,"498*",'BALANCE N-1'!$G$2:$G$50)-SUMIF('BALANCE N-1'!$A$2:$A$50,"498*",'BALANCE N-1'!$F$2:$F$50)))
A19: BB | B19: Stocks et encours | C19: 5 | D19: =((SUMIF('BALANCE N'!$A$2:$A$50,"36*",'BALANCE N'!$F$2:$F$50)-SUMIF('BALANCE N'!$A$2:$A$50,"36*",'BALANCE N'!$G$2:$G$50)+SUMIF('BALANCE N'!$A$2:$A$50,"31*",'BALANCE N'!$F$2:$F$50)-SUMIF('BALANCE N'!$A$2:$A$50,"31*",'BALANCE N'!$G$2:$G$50)+SUMIF('BALANCE N'!$A$2:$A$50,"38*",'BALANCE N'!$F$2:$F$50)-SUMIF('BALANCE N'!$A$2:$A$50,"38*",'BALANCE N'!$G$2:$G$50)+SUMIF('BALANCE N'!$A$2:$A$50,"34*",'BALANCE N'!$F$2:$F$50)-SUMIF('BALANCE N'!$A$2:$A$50,"34*",'BALANCE N'!$G$2:$G$50)+SUMIF('BALANCE N'!$A$2:$A$50,"33*",'BALANCE N'!$F$2:$F$50)-SUMIF('BALANCE N'!$A$2:$A$50,"33*",'BALANCE N'!$G$2:$G$50)+SUMIF('BALANCE N'!$A$2:$A$50,"37*",'BALANCE N'!$F$2:$F$50)-SUMIF('BALANCE N'!$A$2:$A$50,"37*",'BALANCE N'!$G$2:$G$50)+SUMIF('BALANCE N'!$A$2:$A$50,"32*",'BALANCE N'!$F$2:$F$50)-SUMIF('BALANCE N'!$A$2:$A$50,"32*",'BALANCE N'!$G$2:$G$50)))-((SUMIF('BALANCE N'!$A$2:$A$50,"39*",'BALANCE N'!$G$2:$G$50)-SUMIF('BALANCE N'!$A$2:$A$50,"39*",'BALANCE N'!$F$2:$F$50))) | E19: =((SUMIF('BALANCE N-1'!$A$2:$A$50,"36*",'BALANCE N-1'!$F$2:$F$50)-SUMIF('BALANCE N-1'!$A$2:$A$50,"36*",'BALANCE N-1'!$G$2:$G$50)+SUMIF('BALANCE N-1'!$A$2:$A$50,"31*",'BALANCE N-1'!$F$2:$F$50)-SUMIF('BALANCE N-1'!$A$2:$A$50,"31*",'BALANCE N-1'!$G$2:$G$50)+SUMIF('BALANCE N-1'!$A$2:$A$50,"38*",'BALANCE N-1'!$F$2:$F$50)-SUMIF('BALANCE N-1'!$A$2:$A$50,"38*",'BALANCE N-1'!$G$2:$G$50)+SUMIF('BALANCE N-1'!$A$2:$A$50,"34*",'BALANCE N-1'!$F$2:$F$50)-SUMIF('BALANCE N-1'!$A$2:$A$50,"34*",'BALANCE N-1'!$G$2:$G$50)+SUMIF('BALANCE N-1'!$A$2:$A$50,"33*",'BALANCE N-1'!$F$2:$F$50)-SUMIF('BALANCE N-1'!$A$2:$A$50,"33*",'BALANCE N-1'!$G$2:$G$50)+SUMIF('BALANCE N-1'!$A$2:$A$50,"37*",'BALANCE N-1'!$F$2:$F$50)-SUMIF('BALANCE N-1'!$A$2:$A$50,"37*",'BALANCE N-1'!$G$2:$G$50)+SUMIF('BALANCE N-1'!$A$2:$A$50,"32*",'BALANCE N-1'!$F$2:$F$50)-SUMIF('BALANCE N-1'!$A$2:$A$50,"32*",'BALANCE N-1'!$G$2:$G$50)))-((SUMIF('BALANCE N-1'!$A$2:$A$50,"39*",'BALANCE N-1'!$G$2:$G$50)-SUMIF('BALANCE N-1'!$A$2:$A$50,"39*",'BALANCE N-1'!$F$2:$F$50)))
A20: BC | B20: Fournisseurs debiteurs | C20: 6 | D20: =((SUMIF('BALANCE N'!$A$2:$A$50,"409*",'BALANCE N'!$F$2:$F$50)-SUMIF('BALANCE N'!$A$2:$A$50,"409*",'BALANCE N'!$G$2:$G$50)))-((SUMIF('BALANCE N'!$A$2:$A$50,"490*",'BALANCE N'!$G$2:$G$50)-SUMIF('BALANCE N'!$A$2:$A$50,"490*",'BALANCE N'!$F$2:$F$50))) | E20: =((SUMIF('BALANCE N-1'!$A$2:$A$50,"409*",'BALANCE N-1'!$F$2:$F$50)-SUMIF('BALANCE N-1'!$A$2:$A$50,"409*",'BALANCE N-1'!$G$2:$G$50)))-((SUMIF('BALANCE N-1'!$A$2:$A$50,"490*",'BALANCE N-1'!$G$2:$G$50)-SUMIF('BALANCE N-1'!$A$2:$A$50,"490*",'BALANCE N-1'!$F$2:$F$50)))
A21: BD | B21: Clients-usagers | C21: 6 | D21: =((SUMIF('BALANCE N'!$A$2:$A$50,"41*",'BALANCE N'!$F$2:$F$50)-SUMIF('BALANCE N'!$A$2:$A$50,"41*",'BALANCE N'!$G$2:$G$50)-SUMIF('BALANCE N'!$A$2:$A$50,"411*",'BALANCE N'!$F$2:$F$50)+SUMIF('BALANCE N'!$A$2:$A$50,"411*",'BALANCE N'!$G$2:$G$50)-SUMIF('BALANCE N'!$A$2:$A$50,"419*",'BALANCE N'!$F$2:$F$50)+SUMIF('BALANCE N'!$A$2:$A$50,"419*",'BALANCE N'!$G$2:$G$50)))-((SUMIF('BALANCE N'!$A$2:$A$50,"491*",'BALANCE N'!$G$2:$G$50)-SUMIF('BALANCE N'!$A$2:$A$50,"491*",'BALANCE N'!$F$2:$F$50))) | E21: =((SUMIF('BALANCE N-1'!$A$2:$A$50,"41*",'BALANCE N-1'!$F$2:$F$50)-SUMIF('BALANCE N-1'!$A$2:$A$50,"41*",'BALANCE N-1'!$G$2:$G$50)-SUMIF('BALANCE N-1'!$A$2:$A$50,"411*",'BALANCE N-1'!$F$2:$F$50)+SUMIF('BALANCE N-1'!$A$2:$A$50,"411*",'BALANCE N-1'!$G$2:$G$50)-SUMIF('BALANCE N-1'!$A$2:$A$50,"419*",'BALANCE N-1'!$F$2:$F$50)+SUMIF('BALANCE N-1'!$A$2:$A$50,"419*",'BALANCE N-1'!$G$2:$G$50)))-((SUMIF('BALANCE N-1'!$A$2:$A$50,"491*",'BALANCE N-1'!$G$2:$G$50)-SUMIF('BALANCE N-1'!$A$2:$A$50,"491*",'BALANCE N-1'!$F$2:$F$50)))
A22: BE | B22: Autres creances | C22: 6 | D22: =((SUMIF('BALANCE N'!$A$2:$A$50,"43*",'BALANCE N'!$F$2:$F$50)+SUMIF('BALANCE N'!$A$2:$A$50,"47*",'BALANCE N'!$F$2:$F$50)+SUMIF('BALANCE N'!$A$2:$A$50,"44*",'BALANCE N'!$F$2:$F$50)+SUMIF('BALANCE N'!$A$2:$A$50,"42*",'BALANCE N'!$F$2:$F$50)-SUMIF('BALANCE N'!$A$2:$A$50,"478*",'BALANCE N'!$F$2:$F$50)))-((SUMIF('BALANCE N'!$A$2:$A$50,"493*",'BALANCE N'!$G$2:$G$50)-SUMIF('BALANCE N'!$A$2:$A$50,"493*",'BALANCE N'!$F$2:$F$50)+SUMIF('BALANCE N'!$A$2:$A$50,"492*",'BALANCE N'!$G$2:$G$50)-SUMIF('BALANCE N'!$A$2:$A$50,"492*",'BALANCE N'!$F$2:$F$50)+SUMIF('BALANCE N'!$A$2:$A$50,"497*",'BALANCE N'!$G$2:$G$50)-SUMIF('BALANCE N'!$A$2:$A$50,"497*",'BALANCE N'!$F$2:$F$50)+SUMIF('BALANCE N'!$A$2:$A$50,"494*",'BALANCE N'!$G$2:$G$50)-SUMIF('BALANCE N'!$A$2:$A$50,"494*",'BALANCE N'!$F$2:$F$50))) | E22: =((SUMIF('BALANCE N-1'!$A$2:$A$50,"43*",'BALANCE N-1'!$F$2:$F$50)+SUMIF('BALANCE N-1'!$A$2:$A$50,"47*",'BALANCE N-1'!$F$2:$F$50)+SUMIF('BALANCE N-1'!$A$2:$A$50,"44*",'BALANCE N-1'!$F$2:$F$50)+SUMIF('BALANCE N-1'!$A$2:$A$50,"42*",'BALANCE N-1'!$F$2:$F$50)-SUMIF('BALANCE N-1'!$A$2:$A$50,"478*",'BALANCE N-1'!$F$2:$F$50)))-((SUMIF('BALANCE N-1'!$A$2:$A$50,"493*",'BALANCE N-1'!$G$2:$G$50)-SUMIF('BALANCE N-1'!$A$2:$A$50,"493*",'BALANCE N-1'!$F$2:$F$50)+SUMIF('BALANCE N-1'!$A$2:$A$50,"492*",'BALANCE N-1'!$G$2:$G$50)-SUMIF('BALANCE N-1'!$A$2:$A$50,"492*",'BALANCE N-1'!$F$2:$F$50)+SUMIF('BALANCE N-1'!$A$2:$A$50,"497*",'BALANCE N-1'!$G$2:$G$50)-SUMIF('BALANCE N-1'!$A$2:$A$50,"497*",'BALANCE N-1'!$F$2:$F$50)+SUMIF('BALANCE N-1'!$A$2:$A$50,"494*",'BALANCE N-1'!$G$2:$G$50)-SUMIF('BALANCE N-1'!$A$2:$A$50,"494*",'BALANCE N-1'!$F$2:$F$50)))
A23: BF | B23: TOTAL ACTIF CIRCULANT | D23: =D18+D19+D20+D21+D22 | E23: =E18+E19+E20+E21+E22
A24: BV | B24: Valeurs a encaisser | C24: 7 | D24: =((SUMIF('BALANCE N'!$A$2:$A$50,"51*",'BALANCE N'!$F$2:$F$50)-SUMIF('BALANCE N'!$A$2:$A$50,"51*",'BALANCE N'!$G$2:$G$50)))-((SUMIF('BALANCE N'!$A$2:$A$50,"591*",'BALANCE N'!$G$2:$G$50)-SUMIF('BALANCE N'!$A$2:$A$50,"591*",'BALANCE N'!$F$2:$F$50))) | E24: =((SUMIF('BALANCE N-1'!$A$2:$A$50,"51*",'BALANCE N-1'!$F$2:$F$50)-SUMIF('BALANCE N-1'!$A$2:$A$50,"51*",'BALANCE N-1'!$G$2:$G$50)))-((SUMIF('BALANCE N-1'!$A$2:$A$50,"591*",'BALANCE N-1'!$G$2:$G$50)-SUMIF('BALANCE N-1'!$A$2:$A$50,"591*",'BALANCE N-1'!$F$2:$F$50)))
A25: BW | B25: Banques, etablissements financiers, caisses et assimiles | C25: 7 | D25: =((SUMIF('BALANCE N'!$A$2:$A$50,"57*",'BALANCE N'!$F$2:$F$50)-SUMIF('BALANCE N'!$A$2:$A$50,"57*",'BALANCE N'!$G$2:$G$50)+SUMIF('BALANCE N'!$A$2:$A$50,"55*",'BALANCE N'!$F$2:$F$50)-SUMIF('BALANCE N'!$A$2:$A$50,"55*",'BALANCE N'!$G$2:$G$50)+SUMIF('BALANCE N'!$A$2:$A$50,"53*",'BALANCE N'!$F$2:$F$50)-SUMIF('BALANCE N'!$A$2:$A$50,"53*",'BALANCE N'!$G$2:$G$50)+SUMIF('BALANCE N'!$A$2:$A$50,"52*",'BALANCE N'!$F$2:$F$50)-SUMIF('BALANCE N'!$A$2:$A$50,"52*",'BALANCE N'!$G$2:$G$50)))-((SUMIF('BALANCE N'!$A$2:$A$50,"592*",'BALANCE N'!$G$2:$G$50)-SUMIF('BALANCE N'!$A$2:$A$50,"592*",'BALANCE N'!$F$2:$F$50)+SUMIF('BALANCE N'!$A$2:$A$50,"595*",'BALANCE N'!$G$2:$G$50)-SUMIF('BALANCE N'!$A$2:$A$50,"595*",'BALANCE N'!$F$2:$F$50)+SUMIF('BALANCE N'!$A$2:$A$50,"593*",'BALANCE N'!$G$2:$G$50)-SUMIF('BALANCE N'!$A$2:$A$50,"593*",'BALANCE N'!$F$2:$F$50))) | E25: =((SUMIF('BALANCE N-1'!$A$2:$A$50,"57*",'BALANCE N-1'!$F$2:$F$50)-SUMIF('BALANCE N-1'!$A$2:$A$50,"57*",'BALANCE N-1'!$G$2:$G$50)+SUMIF('BALANCE N-1'!$A$2:$A$50,"55*",'BALANCE N-1'!$F$2:$F$50)-SUMIF('BALANCE N-1'!$A$2:$A$50,"55*",'BALANCE N-1'!$G$2:$G$50)+SUMIF('BALANCE N-1'!$A$2:$A$50,"53*",'BALANCE N-1'!$F$2:$F$50)-SUMIF('BALANCE N-1'!$A$2:$A$50,"53*",'BALANCE N-1'!$G$2:$G$50)+SUMIF('BALANCE N-1'!$A$2:$A$50,"52*",'BALANCE N-1'!$F$2:$F$50)-SUMIF('BALANCE N-1'!$A$2:$A$50,"52*",'BALANCE N-1'!$G$2:$G$50)))-((SUMIF('BALANCE N-1'!$A$2:$A$50,"592*",'BALANCE N-1'!$G$2:$G$50)-SUMIF('BALANCE N-1'!$A$2:$A$50,"592*",'BALANCE N-1'!$F$2:$F$50)+SUMIF('BALANCE N-1'!$A$2:$A$50,"595*",'BALANCE N-1'!$G$2:$G$50)-SUMIF('BALANCE N-1'!$A$2:$A$50,"595*",'BALANCE N-1'!$F$2:$F$50)+SUMIF('BALANCE N-1'!$A$2:$A$50,"593*",'BALANCE N-1'!$G$2:$G$50)-SUMIF('BALANCE N-1'!$A$2:$A$50,"593*",'BALANCE N-1'!$F$2:$F$50)))
A26: BX | B26: TOTAL TRESORERIE ACTIF | D26: =D24+D25 | E26: =E24+E25
A27: BY | B27: Ecart de conversion-Actif | C27: 8 | D27: =(SUMIF('BALANCE N'!$A$2:$A$50,"478*",'BALANCE N'!$F$2:$F$50)-SUMIF('BALANCE N'!$A$2:$A$50,"478*",'BALANCE N'!$G$2:$G$50)) | E27: =(SUMIF('BALANCE N-1'!$A$2:$A$50,"478*",'BALANCE N-1'!$F$2:$F$50)-SUMIF('BALANCE N-1'!$A$2:$A$50,"478*",'BALANCE N-1'!$G$2:$G$50))
A28: BZ | B28: TOTAL GENERAL | D28: =D17+D23+D26+D27 | E28: =E17+E23+E26+E27

Sheet Bilan-Passif
A1: - 8 -
D2: BILAN PAGE 2/2 PROJETS DE DEVELOPPEMENT
A3: Dénomination sociale : PROJET EAU POTABLE RURALE
A4: Adresse : | D4: Sigle usuel : | E4: PEPR
A5: N° de compte contribuable (NCC) : PD-2023-017 | C5: Exercice clos le 31-12-2025 | D5: Durée (en mois) : 12
A6: N° de télédéclarant (NTD) :
A7: BILAN (EN NET)
A8: REF | B8: PASSIF | C8: NOTE | D8: EXERCICE AU 31/12/N | E8: EXERCICE AU 31/12/N-1
A9: CA | B9: Fonds affectes aux investissements | C9: 9 | D9: =(SUMIF('BALANCE N'!$A$2:$A$50,"16*",'BALANCE N'!$G$2:$G$50)-SUMIF('BALANCE N'!$A$2:$A$50,"16*",'BALANCE N'!$F$2:$F$50)) | E9: =(SUMIF('BALANCE N-1'!$A$2:$A$50,"16*",'BALANCE N-1'!$G$2:$G$50)-SUMIF('BALANCE N-1'!$A$2:$A$50,"16*",'BALANCE N-1'!$F$2:$F$50))
A10: CB | B10: Report a nouveau (+ ou -) | D10: =(SUMIF('BALANCE N'!$A$2:$A$50,"12*",'BALANCE N'!$G$2:$G$50)-SUMIF('BALANCE N'!$A$2:$A$50,"12*",'BALANCE N'!$F$2:$F$50)) | E10: =(SUMIF('BALANCE N-1'!$A$2:$A$50,"12*",'BALANCE N-1'!$G$2:$G$50)-SUMIF('BALANCE N-1'!$A$2:$A$50,"12*",'BALANCE N-1'!$F$2:$F$50))
A11: CC | B11: Solde des operations de l'exercice | D11: ='Compte Exploitation'!D28+(SUMIF('BALANCE N'!$A$2:$A$50,"13*",'BALANCE N'!$G$2:$G$50)-SUMIF('BALANCE N'!$A$2:$A$50,"13*",'BALANCE N'!$F$2:$F$50)) | E11: ='Compte Exploitation'!E28+(SUMIF('BALANCE N-1'!$A$2:$A$50,"13*",'BALANCE N-1'!$G$2:$G$50)-SUMIF('BALANCE N-1'!$A$2:$A$50,"13*",'BALANCE N-1'!$F$2:$F$50))
A12: CD | B12: Subventions d'investissement | C12: 10 | D12: =(SUMIF('BALANCE N'!$A$2:$A$50,"14*",'BALANCE N'!$G$2:$G$50)-SUMIF('BALANCE N'!$A$2:$A$50,"14*",'BALANCE N'!$F$2:$F$50)) | E12: =(SUMIF('BALANCE N-1'!$A$2:$A$50,"14*",'BALANCE N-1'!$G$2:$G$50)-SUMIF('BALANCE N-1'!$A$2:$A$50,"14*",'BALANCE N-1'!$F$2:$F$50))
A13: CZ | B13: TOTAL RESSOURCES PROPRES ET ASSIMILEES | D13: =D9+D10+D11+D12 | E13: =E9+E10+E11+E12
A14: DA | B14: Emprunts et dettes assimilees | C14: 11 | D14: =(SUMIF('BALANCE N'!$A$2:$A$50,"18*",'BALANCE N'!$G$2:$G$50)-SUMIF('BALANCE N'!$A$2:$A$50,"18*",'BALANCE N'!$F$2:$F$50)) | E14: =(SUMIF('BALANCE N-1'!$A$2:$A$50,"18*",'BALANCE N-1'!$G$2:$G$50)-SUMIF('BALANCE N-1'!$A$2:$A$50,"18*",'BALANCE N-1'!$F$2:$F$50))
A15: DB | B15: Provisions pour risques et charges | C15: 11 | D15: =(SUMIF('BALANCE N'!$A$2:$A$50,"19*",'BALANCE N'!$G$2:$G$50)-SUMIF('BALANCE N'!$A$2:$A$50,"19*",'BALANCE N'!$F$2:$F$50)) | E15: =(SUMIF('BALANCE N-1'!$A$2:$A$50,"19*",'BALANCE N-1'!$G$2:$G$50)-SUMIF('BALANCE N-1'!$A$2:$A$50,"19*",'BALANCE N-1'!$F$2:$F$50))
A16: DC | B16: TOTAL DETTES FINANCIERES ET RESSOURCES ASSIMILEES | D16: =D14+D15 | E16: =E14+E15
A17: DD | B17: TOTAL RESSOURCES STABLES | D17: =D13+D16 | E17: =E13+E16
A18: DE | B18: Dettes circulantes HAO | C18: 4 | D18: =(SUMIF('BALANCE N'!$A$2:$A$50,"484*",'BALANCE N'!$G$2:$G$50)-SUMIF('BALANCE N'!$A$2:$A$50,"484*",'BALANCE N'!$F$2:$F$50)+SUMIF('BALANCE N'!$A$2:$A$50,"481*",'BALANCE N'!$G$2:$G$50)-SUMIF('BALANCE N'!$A$2:$A$50,"481*",'BALANCE N'!$F$2:$F$50)+SUMIF('BALANCE N'!$A$2:$A$50,"4998*",'BALANCE N'!$G$2:$G$50)-SUMIF('BALANCE N'!$A$2:$A$50,"4998*",'BALANCE N'!$F$2:$F$50)) | E18: =(SUMIF('BALANCE N-1'!$A$2:$A$50,"484*",'BALANCE N-1'!$G$2:$G$50)-SUMIF('BALANCE N-1'!$A$2:$A$50,"484*",'BALANCE N-1'!$F$2:$F$50)+SUMIF('BALANCE N-1'!$A$2:$A$50,"481*",'BALANCE N-1'!$G$2:$G$50)-SUMIF('BALANCE N-1'!$A$2:$A$50,"481*",'BALANCE N-1'!$F$2:$F$50)+SUMIF('BALANCE N-1'!$A$2:$A$50,"4998*",'BALANCE N-1'!$G$2:$G$50)-SUMIF('BALANCE N-1'!$A$2:$A$50,"4998*",'BALANCE N-1'!$F$2:$F$50))
A19: DF | B19: Fonds d'administration | C19: 9 | D19: =(SUMIF('BALANCE N'!$A$2:$A$50,"46*",'BALANCE N'!$G$2:$G$50)-SUMIF('BALANCE N'!$A$2:$A$50,"46*",'BALANCE N'!$F$2:$F$50)) | E19: =(SUMIF('BALANCE N-1'!$A$2:$A$50,"46*",'BALANCE N-1'!$G$2:$G$50)-SUMIF('BALANCE N-1'!$A$2:$A$50,"46*",'BALANCE N-1'!$F$2:$F$50))
A20: DG | B20: Fournisseurs | C20: 12 | D20: =(SUMIF('BALANCE N'!$A$2:$A$50,"40*",'BALANCE N'!$G$2:$G$50)-SUMIF('BALANCE N'!$A$2:$A$50,"40*",'BALANCE N'!$F$2:$F$50)-SUMIF('BALANCE N'!$A$2:$A$50,"409*",'BALANCE N'!$G$2:$G$50)+SUMIF('BALANCE N'!$A$2:$A$50,"409*",'BALANCE N'!$F$2:$F$50)) | E20: =(SUMIF('BALANCE N-1'!$A$2:$A$50,"40*",'BALANCE N-1'!$G$2:$G$50)-SUMIF('BALANCE N-1'!$A$2:$A$50,"40*",'BALANCE N-1'!$F$2:$F$50)-SUMIF('BALANCE N-1'!$A$2:$A$50,"409*",'BALANCE N-1'!$G$2:$G$50)+SUMIF('BALANCE N-1'!$A$2:$A$50,"409*",'BALANCE N-1'!$F$2:$F$50))
A21: DH | B21: Autres dettes | C21: 12 | D21: =(SUMIF('BALANCE N'!$A$2:$A$50,"419*",'BALANCE N'!$G$2:$G$50)-SUMIF('BALANCE N'!$A$2:$A$50,"419*",'BALANCE N'!$F$2:$F$50)-SUMIF('BALANCE N'!$A$2:$A$50,"479*",'BALANCE N'!$G$2:$G$50)+SUMIF('BALANCE N'!$A$2:$A$50,"479*",'BALANCE N'!$F$2:$F$50))+(SUMIF('BALANCE N'!$A$2:$A$50,"43*",'BALANCE N'!$G$2:$G$50)+SUMIF('BALANCE N'!$A$2:$A$50,"47*",'BALANCE N'!$G$2:$G$50)+SUMIF('BALANCE N'!$A$2:$A$50,"44*",'BALANCE N'!$G$2:$G$50)+SUMIF('BALANCE N'!$A$2:$A$50,"42*",'BALANCE N'!$G$2:$G$50)-SUMIF('BALANCE N'!$A$2:$A$50,"479*",'BALANCE N'!$G$2:$G$50)) | E21: =(SUMIF('BALANCE N-1'!$A$2:$A$50,"419*",'BALANCE N-1'!$G$2:$G$50)-SUMIF('BALANCE N-1'!$A$2:$A$50,"419*",'BALANCE N-1'!$F$2:$F$50)-SUMIF('BALANCE N-1'!$A$2:$A$50,"479*",'BALANCE N-1'!$G$2:$G$50)+SUMIF('BALANCE N-1'!$A$2:$A$50,"479*",'BALANCE N-1'!$F$2:$F$50))+(SUMIF('BALANCE N-1'!$A$2:$A$50,"43*",'BALANCE N-1'!$G$2:$G$50)+SUMIF('BALANCE N-1'!$A$2:$A$50,"47*",'BALANCE N-1'!$G$2:$G$50)+SUMIF('BALANCE N-1'!$A$2:$A$50,"44*",'BALANCE N-1'!$G$2:$G$50)+SUMIF('BALANCE N-1'!$A$2:$A$50,"42*",'BALANCE N-1'!$G$2:$G$50)-SUMIF('BALANCE N-1'!$A$2:$A$50,"479*",'BALANCE N-1'!$G$2:$G$50))
A22: DI | B22: Provisions pour risques et charges a court terme | D22: =(SUMIF('BALANCE N'!$A$2:$A$50,"499*",'BALANCE N'!$G$2:$G$50)-SUMIF('BALANCE N'!$A$2:$A$50,"499*",'BALANCE N'!$F$2:$F$50)+SUMIF('BALANCE N'!$A$2:$A$50,"599*",'BALANCE N'!$G$2:$G$50)-SUMIF('BALANCE N'!$A$2:$A$50,"599*",'BALANCE N'!$F$2:$F$50)-SUMIF('BALANCE N'!$A$2:$A$50,"4998*",'BALANCE N'!$G$2:$G$50)+SUMIF('BALANCE N'!$A$2:$A$50,"4998*",'BALANCE N'!$F$2:$F$50)) | E22: =(SUMIF('BALANCE N-1'!$A$2:$A$50,"499*",'BALANCE N-1'!$G$2:$G$50)-SUMIF('BALANCE N-1'!$A$2:$A$50,"499*",'BALANCE N-1'!$F$2:$F$50)+SUMIF('BALANCE N-1'!$A$2:$A$50,"599*",'BALANCE N-1'!$G$2:$G$50)-SUMIF('BALANCE N-1'!$A$2:$A$50,"599*",'BALANCE N-1'!$F$2:$F$50)-SUMIF('BALANCE N-1'!$A$2:$A$50,"4998*",'BALANCE N-1'!$G$2:$G$50)+SUMIF('BALANCE N-1'!$A$2:$A$50,"4998*",'BALANCE N-1'!$F$2:$F$50))
A23: DJ | B23: TOTAL PASSIF CIRCULANT | D23: =D18+D19+D20+D21+D22 | E23: =E18+E19+E20+E21+E22
A24: DW | B24: Banques, etablissements financiers et credits de tresorerie | C24: 13 | D24: =(SUMIF('BALANCE N'!$A$2:$A$50,"56*",'BALANCE N'!$G$2:$G$50)-SUMIF('BALANCE N'!$A$2:$A$50,"56*",'BALANCE N'!$F$2:$F$50))+(SUMIF('BALANCE N'!$A$2:$A$50,"53*",'BALANCE N'!$G$2:$G$50)+SUMIF('BALANCE N'!$A$2:$A$50,"52*",'BALANCE N'!$G$2:$G$50)) | E24: =(SUMIF('BALANCE N-1'!$A$2:$A$50,"56*",'BALANCE N-1'!$G$2:$G$50)-SUMIF('BALANCE N-1'!$A$2:$A$50,"56*",'BALANCE N-1'!$F$2:$F$50))+(SUMIF('BALANCE N-1'!$A$2:$A$50,"53*",'BALANCE N-1'!$G$2:$G$50)+SUMIF('BALANCE N-1'!$A$2:$A$50,"52*",'BALANCE N-1'!$G$2:$G$50))
A25: DX | B25: TOTAL TRESORERIE PASSIF | D25: =D24 | E25: =E24
A26: DY | B26: Ecart de conversion-Passif | C26: 8 | D26: =(SUMIF('BALANCE N'!$A$2:$A$50,"479*",'BALANCE N'!$G$2:$G$50)-SUMIF('BALANCE N'!$A$2:$A$50,"479*",'BALANCE N'!$F$2:$F$50)) | E26: =(SUMIF('BALANCE N-1'!$A$2:$A$50,"479*",'BALANCE N-1'!$G$2:$G$50)-SUMIF('BALANCE N-1'!$A$2:$A$50,"479*",'BALANCE N-1'!$F$2:$F$50))
A27: DZ | B27: TOTAL GENERAL | D27: =D17+D23+D25+D26 | E27: =E17+E23+E25+E26

Sheet Compte Exploitation
A1: - 9 -
D2: COMPTE D'EXPLOITATION PROJETS DE DEVELOPPEMENT
A3: Dénomination sociale : PROJET EAU POTABLE RURALE
A4: Adresse : | D4: Sigle usuel : | E4: PEPR
A5: N° de compte contribuable (NCC) : PD-2023-017 | C5: Exercice clos le 31-12-2025 | D5: Durée (en mois) : 12
A6: N° de télédéclarant (NTD) :
A7: COMPTE D'EXPLOITATION
A8: REF | B8: LIBELLES | C8: NOTE | D8: EXERCICE AU 31/12/N | E8: EXERCICE AU 31/12/N-1
A9: RA | B9: Fonds d'administration consommes | C9: 9 et 14 | D9: =(SUMIF('BALANCE N'!$A$2:$A$50,"702*",'BALANCE N'!$G$2:$G$50)-SUMIF('BALANCE N'!$A$2:$A$50,"702*",'BALANCE N'!$F$2:$F$50)) | E9: =(SUMIF('BALANCE N-1'!$A$2:$A$50,"702*",'BALANCE N-1'!$G$2:$G$50)-SUMIF('BALANCE N-1'!$A$2:$A$50,"702*",'BALANCE N-1'!$F$2:$F$50))
A10: RB | B10: Ventes de marchandises, produits finis et prestations de services | C10: 14 | D10: =(SUMIF('BALANCE N'!$A$2:$A$50,"705*",'BALANCE N'!$G$2:$G$50)-SUMIF('BALANCE N'!$A$2:$A$50,"705*",'BALANCE N'!$F$2:$F$50)) | E10: =(SUMIF('BALANCE N-1'!$A$2:$A$50,"705*",'BALANCE N-1'!$G$2:$G$50)-SUMIF('BALANCE N-1'!$A$2:$A$50,"705*",'BALANCE N-1'!$F$2:$F$50))
A11: RC | B11: Subventions d'exploitation | C11: 14 | D11: =(SUMIF('BALANCE N'!$A$2:$A$50,"71*",'BALANCE N'!$G$2:$G$50)-SUMIF('BALANCE N'!$A$2:$A$50,"71*",'BALANCE N'!$F$2:$F$50)) | E11: =(SUMIF('BALANCE N-1'!$A$2:$A$50,"71*",'BALANCE N-1'!$G$2:$G$50)-SUMIF('BALANCE N-1'!$A$2:$A$50,"71*",'BALANCE N-1'!$F$2:$F$50))
