Workbook

Sheet BALANCE N
A1: Compte | B1: Intitulé | C1: Solde d'ouverture débit | D1: Solde d'ouverture crédit | E1: Mouvement débit | F1: Mouvement crédit | G1: Solde de clôture débit | H1: Solde de clôture crédit
B2: TOTAL GENERAL | C2: 0 | D2: 0 | E2: 0 | F2: 0 | G2: 0 | H2: 0
B3: Contrôle d'équilibre par solde (débit - crédit, doit être 0) | C3: =C2-D2 | E3: =E2-F2 | G3: =G2-H2

Sheet BALANCE N-1
A1: Compte | B1: Intitulé | C1: Solde d'ouverture débit | D1: Solde d'ouverture crédit | E1: Mouvement débit | F1: Mouvement crédit | G1: Solde de clôture débit | H1: Solde de clôture crédit
B2: TOTAL GENERAL | C2: 0 | D2: 0 | E2: 0 | F2: 0 | G2: 0 | H2: 0
B3: Contrôle d'équilibre par solde (débit - crédit, doit être 0) | C3: =C2-D2 | E3: =E2-F2 | G3: =G2-H2

Sheet CONTROLE BALANCE
A1: EQUILIBRE DE LA BALANCE
A2: BALANCE N | B2: Solde d'ouverture Débit | C2: Solde d'ouverture Crédit | D2: Mouvements Débit | E2: Mouvements Crédit | F2: Solde de clôture Débit | G2: Solde de clôture Crédit
B3: =SUM('BALANCE N'!C2:C2) | C3: =SUM('BALANCE N'!D2:D2) | D3: =SUM('BALANCE N'!E2:E2) | E3: =SUM('BALANCE N'!F2:F2) | F3: =SUM('BALANCE N'!G2:G2) | G3: =SUM('BALANCE N'!H2:H2)
B4: =IF(ROUND(B3-C3,0)=0,"Equilibre","Déséquilibre : écart de "&TEXT(B3-C3,"#,##0")) | D4: =IF(ROUND(D3-E3,0)=0,"Equilibre","Déséquilibre : écart de "&TEXT(D3-E3,"#,##0")) | F4: =IF(ROUND(F3-G3,0)=0,"Equilibre","Déséquilibre : écart de "&TEXT(F3-G3,"#,##0"))
A5: BALANCE N-1 | B5: Solde d'ouverture Débit | C5: Solde d'ouverture Crédit | D5: Mouvements Débit | E5: Mouvements Crédit | F5: Solde de clôture Débit | G5: Solde de clôture Crédit
B6: =SUM('BALANCE N-1'!C2:C2) | C6: =SUM('BALANCE N-1'!D2:D2) | D6: =SUM('BALANCE N-1'!E2:E2) | E6: =SUM('BALANCE N-1'!F2:F2) | F6: =SUM('BALANCE N-1'!G2:G2) | G6: =SUM('BALANCE N-1'!H2:H2)
B7: =IF(ROUND(B6-C6,0)=0,"Equilibre","Déséquilibre : écart de "&TEXT(B6-C6,"#,##0")) | D7: =IF(ROUND(D6-E6,0)=0,"Equilibre","Déséquilibre : écart de "&TEXT(D6-E6,"#,##0")) | F7: =IF(ROUND(F6-G6,0)=0,"Equilibre","Déséquilibre : écart de "&TEXT(F6-G6,"#,##0"))

Sheet Couverture
E31: LIASSE SYSTEME NORMAL
E34: Exercice clos le

Sheet Garde
B12: ETATS FINANCIERS NORMALISES DU SYSTEME COMPTABLE DES ENTITES A BUT NON LUCRATIF (SYCEBNL)
B13: Associations, Ordres Professionnels, Fondations et Assimilées
C16: Exercice clos le - Durée (en mois) : 12
B20: DESIGNATION DE L'ENTITE
B22: DENOMINATION SOCIALE :
B24: SIGLE USUEL :
B26: ADRESSE COMPLETE :
B28: N° de compte contribuable (NCC) :
B30: N° de télédéclarant (NTD) :
B32: SYSTEME NORMAL
B34: Documents déposés | H34: Réservé à l'administration
B35: Fiche d'identification et renseignements divers | F35: X | H35: Date de dépôt
B36: Bilan (actif et passif) | F36: X
B37: Compte de résultat | F37: X
B38: Tableau des flux de trésorerie | F38: X
B39: Notes annexes | F39: X | H39: Nom de l'agent ayant réceptionné le dépôt
H43: Signature de l'agent et cachet du service
B48: Nombre de pages déposées par exemplaire :
B49: Nombre d'exemplaires déposés :

Sheet Fiche 1
A1: - 1 -
I2: FICHE 1
A3: Dénomination sociale :
A4: Adresse : | I4: Sigle usuel :
A5: N° de compte contribuable (NCC) : | G5: Exercice clos le | I5: Durée (en mois) : 12
A6: N° de télédéclarant (NTD) :
A7: FICHE D'IDENTIFICATION ET RENSEIGNEMENTS DIVERS
A8: SYCEBNL - Associations et ordres professionnels - Système normal
A10: ZA | B10: EXERCICE COMPTABLE | G10: DU : AU :
A11: ZB | B11: DATE D'ARRETE EFFECTIF DES COMPTES
A12: ZC | B12: EXERCICE PRECEDENT CLOS LE
A13: ZD | B13: DUREE DE L'EXERCICE PRECEDENT (EN MOIS)
A14: ZE | B14: N° REGISTRE (RCCM, F92, CONVENTION...) ET GREFFE
A15: ZF | B15: N° REPERTOIRE DES ENTITES
A16: ZG | B16: N° DE CAISSE SOCIALE
A17: ZH | B17: N° CODE IMPORTATEUR
A18: ZI | B18: CODE ACTIVITE PRINCIPALE
A19: ZJ | B19: DESIGNATION DE L'ENTITE ET SIGLE
A20: ZK | B20: N° DE TELEPHONE, ADRESSE E-MAIL, BOITE POSTALE, VILLE
A21: ZL | B21: ADRESSE GEOGRAPHIQUE COMPLETE (IMMEUBLE, RUE, QUARTIER, VILLE, PAYS)
A22: ZM | B22: DESIGNATION PRECISE DE L'ACTIVITE PRINCIPALE EXERCEE
... A32: ZW | B32: DOMICILIATIONS BANCAIRES (BANQUE ET NUMERO DE COMPTE)
B34: Signature

Sheet Fiche 2
A1: - 2 -
I2: FICHE 2
A3: Dénomination sociale :
A4: Adresse : | I4: Sigle usuel :
A5: N° de compte contribuable (NCC) : | G5: Exercice clos le | I5: Durée (en mois) : 12
A6: N° de télédéclarant (NTD) :
A7: FICHE D'IDENTIFICATION ET RENSEIGNEMENTS DIVERS
A8: EQUIPE DE L'ENTITE A BUT NON LUCRATIF
A10: Nom et Prénoms | C10: Nationalité | D10: Autres nationalités (à préciser) (2) | E10: Qualité | F10: N° d'identification fiscale | H10: Adresse (BP, ville, pays, adresse géographique et adresse e-mail)
A32: (2) Mentionner les autres nationalités le cas échéant.

Sheet Bilan paysage
A1: - 3 -
K2: BILAN SYSTEME NORMAL PAGE 1/1
A3: Dénomination sociale :
A4: Adresse : | K4: Sigle usuel :
A5: N° de compte contribuable (NCC) : | I5: Exercice clos le | K5: Durée (en mois) : 12
A6: N° de télédéclarant (NTD) :
C7: BILAN
A8: REF | B8: ACTIF | C8: NOTE | D8: BRUT | E8: AMORT et DEPREC. | F8: NET | G8: NET N-1 | H8: REF | I8: PASSIF | J8: NOTE | K8: NET | L8: NET N-1
A10: AA | B10: IMMOBILISATIONS DESTINEES A LA VENTE PROVENANT DE DONS ET LEGS NON ENCORE RECUES ET USUFRUIT TEMPORAIRE | C10: note 5 | D10: ='Bilan-Actif'!D10 | E10: ='Bilan-Actif'!E10 | F10: ='Bilan-Actif'!F10 | G10: ='Bilan-Actif'!G10 | H10: CA | I10: Donation non consomptible sans droit reprise | J10: note 15 | K10: ='Bilan-Passif'!D10 | L10: ='Bilan-Passif'!E10
A11: AB | B11: Immobilisations incorporelles | D11: ='Bilan-Actif'!D11 | E11: ='Bilan-Actif'!E11 | F11: ='Bilan-Actif'!F11 | G11: ='Bilan-Actif'!G11 | H11: CB | I11: Donation non consomptible avec droit reprise | J11: note 15 | K11: ='Bilan-Passif'!D11 | L11: ='Bilan-Passif'!E11
A12: AC | B12: Immobilisations corporelles et financieres | D12: ='Bilan-Actif'!D12 | E12: ='Bilan-Actif'!E12 | F12: ='Bilan-Actif'!F12 | G12: ='Bilan-Actif'!G12 | H12: CC | I12: Droit d'entree | J12: note 15 | K12: ='Bilan-Passif'!D12 | L12: ='Bilan-Passif'!E12
A13: AD | B13: IMMOBILISATIONS INCORPORELLES | C13: note 5 | D13: ='Bilan-Actif'!D13 | E13: ='Bilan-Actif'!E13 | F13: ='Bilan-Actif'!F13 | G13: ='Bilan-Actif'!G13 | H13: CD | I13: Donation consomptible | J13: note 15 | K13: ='Bilan-Passif'!D13 | L13: ='Bilan-Passif'!E13
A14: AE | B14: Brevets, licences, logiciels et droits similaires | C14: note 5F | D14: ='Bilan-Actif'!D14 | E14: ='Bilan-Actif'!E14 | F14: ='Bilan-Actif'!F14 | G14: ='Bilan-Actif'!G14 | H14: CE | I14: Ecarts de reevaluation | J14: note 5F | K14: ='Bilan-Passif'!D14 | L14: ='Bilan-Passif'!E14
A15: AF | B15: Autres immobilisations incorporelles | D15: ='Bilan-Actif'!D15 | E15: ='Bilan-Actif'!E15 | F15: ='Bilan-Actif'!F15 | G15: ='Bilan-Actif'!G15 | H15: CF | I15: Reserves | J15: note 16 | K15: ='Bilan-Passif'!D15 | L15: ='Bilan-Passif'!E15
A16: AG | B16: Avances et acomptes verses sur immobilisations incorporelles | D16: ='Bilan-Actif'!D16 | E16: ='Bilan-Actif'!E16 | F16: ='Bilan-Actif'!F16 | G16: ='Bilan-Actif'!G16 | H16: CG | I16: Report a nouveau (+ ou -) | J16: note 16 | K16: ='Bilan-Passif'!D16 | L16: ='Bilan-Passif'!E16
A17: AH | B17: IMMOBILISATIONS CORPORELLES | C17: note 5 | D17: ='Bilan-Actif'!D17 | E17: ='Bilan-Actif'!E17 | F17: ='Bilan-Actif'!F17 | G17: ='Bilan-Actif'!G17 | H17: CH | I17: Resultat net de l'exercice (excedent + ou deficit -) | K17: ='Bilan-Passif'!D17 | L17: ='Bilan-Passif'!E17
A18: AI | B18: Terrains | D18: ='Bilan-Actif'!D18 | E18: ='Bilan-Actif'!E18 | F18: ='Bilan-Actif'!F18 | G18: ='Bilan-Actif'!G18 | H18: CI | I18: Subventions d'investissement | J18: note 17A | K18: ='Bilan-Passif'!D18 | L18: ='Bilan-Passif'!E18
A19: AJ | B19: Batiments | D19: ='Bilan-Actif'!D19 | E19: ='Bilan-Actif'!E19 | F19: ='Bilan-Actif'!F19 | G19: ='Bilan-Actif'!G19 | H19: CJ | I19: Provisions reglementees | J19: note 17A | K19: ='Bilan-Passif'!D19 | L19: ='Bilan-Passif'!E19
A20: AK | B20: Amenagements, agencements et installations | D20: ='Bilan-Actif'!D20 | E20: ='Bilan-Actif'!E20 | F20: ='Bilan-Actif'!F20 | G20: ='Bilan-Actif'!G20 | H20: CK | I20: TOTAL FONDS PROPRES ET ASSIMILES | K20: ='Bilan-Passif'!D20 | L20: ='Bilan-Passif'!E20
A21: AL | B21: Materiel, mobilier et actifs biologiques | D21: ='Bilan-Actif'!D21 | E21: ='Bilan-Actif'!E21 | F21: ='Bilan-Actif'!F21 | G21: ='Bilan-Actif'!G21 | H21: CW | I21: Fonds affectes et provenant de dons et legs d'immobilisations | J21: note 17B | K21: ='Bilan-Passif'!D21 | L21: ='Bilan-Passif'!E21
A22: AM | B22: Materiel de transport | D22: ='Bilan-Actif'!D22 | E22: ='Bilan-Actif'!E22 | F22: ='Bilan-Actif'!F22 | G22: ='Bilan-Actif'!G22 | H22: CX | I22: Fonds reportes | J22: note 17B | K22: ='Bilan-Passif'!D22 | L22: ='Bilan-Passif'!E22
A23: AN | B23: Avances et acomptes verses sur immobilisations corporelles | D23: ='Bilan-Actif'!D23 | E23: ='Bilan-Actif'!E23 | F23: ='Bilan-Actif'!F23 | G23: ='Bilan-Actif'!G23 | H23: CY | I23: TOTAL FONDS AFFECTES ET REPORTES | K23: ='Bilan-Passif'!D23 | L23: ='Bilan-Passif'!E23
A24: AO | B24: IMMOBILISATIONS FINANCIERES | C24: note 6 | D24: ='Bilan-Actif'!D24 | E24: ='Bilan-Actif'!E24 | F24: ='Bilan-Actif'!F24 | G24: ='Bilan-Actif'!G24 | H24: CZ | I24: TOTAL RESSOURCES PROPRES ET ASSIMILEES | K24: ='Bilan-Passif'!D24 | L24: ='Bilan-Passif'!E24
A25: AX | B25: Titres de participation | D25: ='Bilan-Actif'!D25 | E25: ='Bilan-Actif'!E25 | F25: ='Bilan-Actif'!F25 | G25: ='Bilan-Actif'!G25 | H25: DA | I25: Emprunts et dettes financieres | J25: note 18A | K25: ='Bilan-Passif'!D25 | L25: ='Bilan-Passif'!E25
A26: AY | B26: Autres immobilisations financieres | D26: ='Bilan-Actif'!D26 | E26: ='Bilan-Actif'!E26 | F26: ='Bilan-Actif'!F26 | G26: ='Bilan-Actif'!G26 | H26: DB | I26: Dettes de location-acquisition | J26: note 18A | K26: ='Bilan-Passif'!D26 | L26: ='Bilan-Passif'!E26
A27: AZ | B27: TOTAL ACTIF IMMOBILISE | D27: ='Bilan-Actif'!D27 | E27: ='Bilan-Actif'!E27 | F27: ='Bilan-Actif'!F27 | G27: ='Bilan-Actif'!G27 | H27: DC | I27: Provisions pour risques et charges | J27: note 18A | K27: ='Bilan-Passif'!D27 | L27: ='Bilan-Passif'!E27
A28: BA | B28: Actif circulant HAO | C28: note 7 | D28: ='Bilan-Actif'!D28 | E28: ='Bilan-Actif'!E28 | F28: ='Bilan-Actif'!F28 | G28: ='Bilan-Actif'!G28 | H28: DD | I28: TOTAL DETTES FINANCIERES ET RESSOURCES ASSIMILEES | K28: ='Bilan-Passif'!D28 | L28: ='Bilan-Passif'!E28
A29: BB | B29: Stocks et encours | C29: note 8 | D29: ='Bilan-Actif'!D29 | E29: ='Bilan-Actif'!E29 | F29: ='Bilan-Actif'!F29 | G29: ='Bilan-Actif'!G29 | H29: DE | I29: TOTAL RESSOURCES STABLES | K29: ='Bilan-Passif'!D29 | L29: ='Bilan-Passif'!E29
A30: BC | B30: Fournisseurs debiteurs | C30: note 19 | D30: ='Bilan-Actif'!D30 | E30: ='Bilan-Actif'!E30 | F30: ='Bilan-Actif'!F30 | G30: ='Bilan-Actif'!G30 | H30: DF | I30: Dettes circulantes HAO | J30: note 7 | K30: ='Bilan-Passif'!D30 | L30: ='Bilan-Passif'!E30
A31: BD | B31: Adherents, Clients-usagers | C31: note 9 | D31: ='Bilan-Actif'!D31 | E31: ='Bilan-Actif'!E31 | F31: ='Bilan-Actif'!F31 | G31: ='Bilan-Actif'!G31 | H31: DG | I31: Adherents, clients-usagers crediteurs | J31: note 9 | K31: ='Bilan-Passif'!D31 | L31: ='Bilan-Passif'!E31
A32: BE | B32: Autres creances | C32: note 10 | D32: ='Bilan-Actif'!D32 | E32: ='Bilan-Actif'!E32 | F32: ='Bilan-Actif'!F32 | G32: ='Bilan-Actif'!G32 | H32: DH | I32: Fournisseurs | J32: note 19 | K32: ='Bilan-Passif'!D32 | L32: ='Bilan-Passif'!E32
A33: BT | B33: TOTAL ACTIF CIRCULANT | D33: ='Bilan-Actif'!D33 | E33: ='Bilan-Actif'!E33 | F33: ='Bilan-Actif'!F33 | G33: ='Bilan-Actif'!G33 | H33: DI | I33: Autres dettes | J33: note 20 et 21 | K33: ='Bilan-Passif'!D33 | L33: ='Bilan-Passif'!E33
A34: BU | B34: Titres de placement | C34: note 11 | D34: ='Bilan-Actif'!D34 | E34: ='Bilan-Actif'!E34 | F34: ='Bilan-Actif'!F34 | G34: ='Bilan-Actif'!G34 | H34: DV | I34: TOTAL PASSIF CIRCULANT | K34: ='Bilan-Passif'!D34 | L34: ='Bilan-Passif'!E34
A35: BV | B35: Valeurs a encaisser | C35: note 12 | D35: ='Bilan-Actif'!D35 | E35: ='Bilan-Actif'!E35 | F35: ='Bilan-Actif'!F35 | G35: ='Bilan-Actif'!G35 | H35: DW | I35: Banques, etablissements financiers et credits de tresorerie | J35: note 22 | K35: ='Bilan-Passif'!D35 | L35: ='Bilan-Passif'!E35
A36: BW | B36: Banques, etablissements financiers, caisses et assimiles | C36: note 13 | D36: ='Bilan-Actif'!D36 | E36: ='Bilan-Actif'!E36 | F36: ='Bilan-Actif'!F36 | G36: ='Bilan-Actif'!G36 | H36: DX | I36: TOTAL TRESORERIE PASSIF | K36: ='Bilan-Passif'!D36 | L36: ='Bilan-Passif'!E36
A37: BX | B37: TOTAL TRESORERIE ACTIF | D37: ='Bilan-Actif'!D37 | E37: ='Bilan-Actif'!E37 | F37: ='Bilan-Actif'!F37 | G37: ='Bilan-Actif'!G37 | H37: DY | I37: Ecart de conversion-Passif | J37: note 14 | K37: ='Bilan-Passif'!D37 | L37: ='Bilan-Passif'!E37
A38: BY | B38: Ecart de conversion-Actif | C38: note 14 | D38: ='Bilan-Actif'!D38 | E38: ='Bilan-Actif'!E38 | F38: ='Bilan-Actif'!F38 | G38: ='Bilan-Actif'!G38 | H38: DZ | I38: TOTAL GENERAL | K38: ='Bilan-Passif'!D38 | L38: ='Bilan-Passif'!E38
A39: BZ | B39: TOTAL GENERAL | D39: ='Bilan-Actif'!D39 | E39: ='Bilan-Actif'!E39 | F39: ='Bilan-Actif'!F39 | G39: ='Bilan-Actif'!G39

Sheet Bilan-Actif
A1: - 4 -
F2: BILAN SYSTEME NORMAL PAGE 1/2
A3: Dénomination sociale :
A4: Adresse : | F4: Sigle usuel :
A5: N° de compte contribuable (NCC) : | D5: Exercice clos le | F5: Durée (en mois) : 12
A6: N° de télédéclarant (NTD) :
B7: BILAN
A8: REF | B8: ACTIF | C8: NOTE | D8: EXERCICE AU 31/12/N | G8: EXERCICE AU 31/12/N-1
D9: BRUT | E9: AMORT et DEPREC. | F9: NET | G9: NET
A10: AA | B10: IMMOBILISATIONS DESTINEES A LA VENTE PROVENANT DE DONS ET LEGS NON ENCORE RECUES ET USUFRUIT TEMPORAIRE | C10: note 5 | D10: =D11+D12 | E10: =E11+E12 | F10: =F11+F12 | G10: =G11+G12
A11: AB | B11: Immobilisations incorporelles | D11: =(SUMIF('BALANCE N'!$A$2:$A$2000,"201*",'BALANCE N'!$G$2:$G$2000)-SUMIF('BALANCE N'!$A$2:$A$2000,"201*",'BALANCE N'!$H$2:$H$2000)) | E11: =(SUMIF('BALANCE N'!$A$2:$A$2000,"280*",'BALANCE N'!$H$2:$H$2000)-SUMIF('BALANCE N'!$A$2:$A$2000,"280*",'BALANCE N'!$G$2:$G$2000)+SUMIF('BALANCE N'!$A$2:$A$2000,"2901*",'BALANCE N'!$H$2:$H$2000)-SUMIF('BALANCE N'!$A$2:$A$2000,"2901*",'BALANCE N'!$G$2:$G$2000)) | F11: =D11-E11 | G11: =((SUMIF('BALANCE N-1'!$A$2:$A$2000,"201*",'BALANCE N-1'!$G$2:$G$2000)-SUMIF('BALANCE N-1'!$A$2:$A$2000,"201*",'BALANCE N-1'!$H$2:$H$2000)))-((SUMIF('BALANCE N-1'!$A$2:$A$2000,"280*",'BALANCE N-1'!$H$2:$H$2000)-SUMIF('BALANCE N-1'!$A$2:$A$2000,"280*",'BALANCE N-1'!$G$2:$G$2000)+SUMIF('BALANCE N-1'!$A$2:$A$2000,"2901*",'BALANCE N-1'!$H$2:$H$2000)-SUMIF('BALANCE N-1'!$A$2:$A$2000,"2901*",'BALANCE N-1'!$G$2:$G$2000)))
A12: AC | B12: Immobilisations corporelles et financieres | D12: =(SUMIF('BALANCE N'!$A$2:$A$2000,"202*",'BALANCE N'!$G$2:$G$2000)-SUMIF('BALANCE N'!$A$2:$A$2000,"202*",'BALANCE N'!$H$2:$H$2000)+SUMIF('BALANCE N'!$A$2:$A$2000,"203*",'BALANCE N'!$G$2:$G$2000)-SUMIF('BALANCE N'!$A$2:$A$2000,"203*",'BALANCE N'!$H$2:$H$2000)+SUMIF('BALANCE N'!$A$2:$A$2000,"204*",'BALANCE N'!$G$2:$G$2000)-SUMIF('BALANCE N'!$A$2:$A$2000,"204*",'BALANCE N'!$H$2:$H$2000)+SUMIF('BALANCE N'!$A$2:$A$2000,"205*",'BALANCE N'!$G$2:$G$2000)-SUMIF('BALANCE N'!$A$2:$A$2000,"205*",'BALANCE N'!$H$2:$H$2000)) | E12: =(SUMIF('BALANCE N'!$A$2:$A$2000,"2902*",'BALANCE N'!$H$2:$H$2000)-SUMIF('BALANCE N'!$A$2:$A$2000,"2902*",'BALANCE N'!$G$2:$G$2000)) | F12: =D12-E12 | G12: =((SUMIF('BALANCE N-1'!$A$2:$A$2000,"202*",'BALANCE N-1'!$G$2:$G$2000)-SUMIF('BALANCE N-1'!$A$2:$A$2000,"202*",'BALANCE N-1'!$H$2:$H$2000)+SUMIF('BALANCE N-1'!$A$2:$A$2000,"203*",'BALANCE N-1'!$G$2:$G$2000)-SUMIF('BALANCE N-1'!$A$2:$A$2000,"203*",'BALANCE N-1'!$H$2:$H$2000)+SUMIF('BALANCE N-1'!$A$2:$A$2000,"204*",'BALANCE N-1'!$G$2:$G$2000)-SUMIF('BALANCE N-1'!$A$2:$A$2000,"204*",'BALANCE N-1'!$H$2:$H$2000)+SUMIF('BALANCE N-1'!$A$2:$A$2000,"205*",'BALANCE N-1'!$G$2:$G$2000)-SUMIF('BALANCE N-1'!$A$2:$A$2000,"205*",'BALANCE N-1'!$H$2:$H$2000)))-((SUMIF('BALANCE N-1'!$A$2:$A$2000,"2902*",'BALANCE N-1'!$H$2:$H$2000)-SUMIF('BALANCE N-1'!$A$2:$A$2000,"2902*",'BALANCE N-1'!$G$2:$G$2000)))
A13: AD | B13: IMMOBILISATIONS INCORPORELLES | C13: note 5 | D13: =D14+D15+D16 | E13: =E14+E15+E16 | F13: =F14+F15+F16 | G13: =G14+G15+G16
A14: AE | B14: Brevets, licences, logiciels et droits similaires | C14: note 5F | D14: =(SUMIF('BALANCE N'!$A$2:$A$2000,"212*",'BALANCE N'!$G$2:$G$2000)-SUMIF('BALANCE N'!$A$2:$A$2000,"212*",'BALANCE N'!$H$2:$H$2000)+SUMIF('BALANCE N'!$A$2:$A$2000,"213*",'BALANCE N'!$G$2:$G$2000)-SUMIF('BALANCE N'!$A$2:$A$2000,"213*",'BALANCE N'!$H$2:$H$2000)+SUMIF('BALANCE N'!$A$2:$A$2000,"214*",'BALANCE N'!$G$2:$G$2000)-SUMIF('BALANCE N'!$A$2:$A$2000,"214*",'BALANCE N'!$H$2:$H$2000)+SUMIF('BALANCE N'!$A$2:$A$2000,"2193*",'BALANCE N'!$G$2:$G$2000)-SUMIF('BALANCE N'!$A$2:$A$2000,"2193*",'BALANCE N'!$H$2:$H$2000)) | E14: =(SUMIF('BALANCE N'!$A$2:$A$2000,"2812*",'BALANCE N'!$H$2:$H$2000)-SUMIF('BALANCE N'!$A$2:$A$2000,"2812*",'BALANCE N'!$G$2:$G$2000)+SUMIF('BALANCE N'!$A$2:$A$2000,"2813*",'BALANCE N'!$H$2:$H$2000)-SUMIF('BALANCE N'!$A$2:$A$2000,"2813*",'BALANCE N'!$G$2:$G$2000)+SUMIF('BALANCE N'!$A$2:$A$2000,"2814*",'BALANCE N'!$H$2:$H$2000)-SUMIF('BALANCE N'!$A$2:$A$2000,"2814*",'BALANCE N'!$G$2:$G$2000)+SUMIF('BALANCE N'!$A$2:$A$2000,"2912*",'BALANCE N'!$H$2:$H$2000)-SUMIF('BALANCE N'!$A$2:$A$2000,"2912*",'BALANCE N'!$G$2:$G$2000)+SUMIF('BALANCE N'!$A$2:$A$2000,"2913*",'BALANCE N'!$H$2:$H$2000)-SUMIF('BALANCE N'!$A$2:$A$2000,"2913*",'BALANCE N'!$G$2:$G$2000)+SUMIF('BALANCE N'!$A$2:$A$2000,"2919*",'BALANCE N'!$H$2:$H$2000)-SUMIF('BALANCE N'!$A$2:$A$2000,"2919*",'BALANCE N'!$G$2:$G$2000)) | F14: =D14-E14 | G14: =((SUMIF('BALANCE N-1'!$A$2:$A$2000,"212*",'BALANCE N-1'!$G$2:$G$2000)-SUMIF('BALANCE N-1'!$A$2:$A$2000,"212*",'BALANCE N-1'!$H$2:$H$2000)+SUMIF('BALANCE N-1'!$A$2:$A$2000,"213*",'BALANCE N-1'!$G$2:$G$2000)-SUMIF('BALANCE N-1'!$A$2:$A$2000,"213*",'BALANCE N-1'!$H$2:$H$2000)+SUMIF('BALANCE N-1'!$A$2:$A$2000,"214*",'BALANCE N-1'!$G$2:$G$2000)-SUMIF('BALANCE N-1'!$A$2:$A$2000,"214*",'BALANCE N-1'!$H$2:$H$2000)+SUMIF('BALANCE N-1'!$A$2:$A$2000,"2193*",'BALANCE N-1'!$G$2:$G$2000)-SUMIF('BALANCE N-1'!$A$2:$A$2000,"2193*",'BALANCE N-1'!$H$2:$H$2000)))-((SUMIF('BALANCE N-1'!$A$2:$A$2000,"2812*",'BALANCE N-1'!$H$2:$H$2000)-SUMIF('BALANCE N-1'!$A$2:$A$2000,"2812*",'BALANCE N-1'!$G$2:$G$2000)+SUMIF('BALANCE N-1'!$A$2:$A$2000,"2813*",'BALANCE N-1'!$H$2:$H$2000)-SUMIF('BALANCE N-1'!$A$2:$A$2000,"2813*",'BALANCE N-1'!$G$2:$G$2000)+SUMIF('BALANCE N-1'!$A$2:$A$2000,"2814*",'BALANCE N-1'!$H$2:$H$2000)-SUMIF('BALANCE N-1'!$A$2:$A$2000,"2814*",'BALANCE N-1'!$G$2:$G$2000)+SUMIF('BALANCE N-1'!$A$2:$A$2000,"2912*",'BALANCE N-1'!$H$2:$H$2000)-SUMIF('BALANCE N-1'!$A$2:$A$2000,"2912*",'BALANCE N-1'!$G$2:$G$2000)+SUMIF('BALANCE N-1'!$A$2:$A$2000,"2913*",'BALANCE N-1'!$H$2:$H$2000)-SUMIF('BALANCE N-1'!$A$2:$A$2000,"2913*",'BALANCE N-1'!$G$2:$G$2000)+SUMIF('BALANCE N-1'!$A$2:$A$2000,"2919*",'BALANCE N-1'!$H$2:$H$2000)-SUMIF('BALANCE N-1'!$A$2:$A$2000,"2919*",'BALANCE N-1'!$G$2:$G$2000)))
A15: AF | B15: Autres immobilisations incorporelles | D15: =(SUMIF('BALANCE N'!$A$2:$A$2000,"218*",'BALANCE N'!$G$2:$G$2000)-SUMIF('BALANCE N'!$A$2:$A$2000,"218*",'BALANCE N'!$H$2:$H$2000)+SUMIF('BALANCE N'!$A$2:$A$2000,"2198*",'BALANCE N'!$G$2:$G$2000)-SUMIF('BALANCE N'!$A$2:$A$2000,"2198*",'BALANCE N'!$H$2:$H$2000)) | E15: =(SUMIF('BALANCE N'!$A$2:$A$2000,"2818*",'BALANCE N'!$H$2:$H$2000)-SUMIF('BALANCE N'!$A$2:$A$2000,"2818*",'BALANCE N'!$G$2:$G$2000)+SUMIF('BALANCE N'!$A$2:$A$2000,"2918*",'BALANCE N'!$H$2:$H$2000)-SUMIF('BALANCE N'!$A$2:$A$2000,"2918*",'BALANCE N'!$G$2:$G$2000)+SUMIF('BALANCE N'!$A$2:$A$2000,"2919*",'BALANCE N'!$H$2:$H$2000)-SUMIF('BALANCE N'!$A$2:$A$2000,"2919*",'BALANCE N'!$G$2:$G$2000)) | F15: =D15-E15 | G15: =((SUMIF('BALANCE N-1'!$A$2:$A$2000,"218*",'BALANCE N-1'!$G$2:$G$2000)-SUMIF('BALANCE N-1'!$A$2:$A$2000,"218*",'BALANCE N-1'!$H$2:$H$2000)+SUMIF('BALANCE N-1'!$A$2:$A$2000,"2198*",'BALANCE N-1'!$G$2:$G$2000)-SUMIF('BALANCE N-1'!$A$2:$A$2000,"2198*",'BALANCE N-1'!$H$2:$H$2000)))-((SUMIF('BALANCE N-1'!$A$2:$A$2000,"2818*",'BALANCE N-1'!$H$2:$H$2000)-SUMIF('BALANCE N-1'!$A$2:$A$2000,"2818*",'BALANCE N-1'!$G$2:$G$2000)+SUMIF('BALANCE N-1'!$A$2:$A$2000,"2918*",'BALANCE N-1'!$H$2:$H$2000)-SUMIF('BALANCE N-1'!$A$2:$A$2000,"2918*",'BALANCE N-1'!$G$2:$G$2000)+SUMIF('BALANCE N-1'!$A$2:$A$2000,"2919*",'BALANCE N-1'!$H$2:$H$2000)-SUMIF('BALANCE N-1'!$A$2:$A$2000,"2919*",'BALANCE N-1'!$G$2:$G$2000)))
A16: AG | B16: Avances et acomptes verses sur immobilisations incorporelles | D16: =(SUMIF('BALANCE N'!$A$2:$A$2000,"251*",'BALANCE N'!$G$2:$G$2000)-SUMIF('BALANCE N'!$A$2:$A$2000,"251*",'BALANCE N'!$H$2:$H$2000)) | E16: 0 | F16: =D16-E16 | G16: =((SUMIF('BALANCE N-1'!$A$2:$A$2000,"251*",'BALANCE N-1'!$G$2:$G$2000)-SUMIF('BALANCE N-1'!$A$2:$A$2000,"251*",'BALANCE N-1'!$H$2:$H$2000)))-(0)
A17: AH | B17: IMMOBILISATIONS CORPORELLES | C17: note 5 | D17: =D18+D19+D20+D21+D22+D23 | E17: =E18+E19+E20+E21+E22+E23 | F17: =F18+F19+F20+F21+F22+F23 | G17: =G18+G19+G20+G21+G22+G23
A18: AI | B18: Terrains | D18: =(SUMIF('BALANCE N'!$A$2:$A$2000,"22*",'BALANCE N'!$G$2:$G$2000)-SUMIF('BALANCE N'!$A$2:$A$2000,"22*",'BALANCE N'!$H$2:$H$2000)) | E18: =(SUMIF('BALANCE N'!$A$2:$A$2000,"282*",'BALANCE N'!$H$2:$H$2000)-SUMIF('BALANCE N'!$A$2:$A$2000,"282*",'BALANCE N'!$G$2:$G$2000)+SUMIF('BALANCE N'!$A$2:$A$2000,"292*",'BALANCE N'!$H$2:$H$2000)-SUMIF('BALANCE N'!$A$2:$A$2000,"292*",'BALANCE N'!$G$2:$G$2000)) | F18: =D18-E18 | G18: =((SUMIF('BALANCE N-1'!$A$2:$A$2000,"22*",'BALANCE N-1'!$G$2:$G$2000)-SUMIF('BALANCE N-1'!$A$2:$A$2000,"22*",'BALANCE N-1'!$H$2:$H$2000)))-((SUMIF('BALANCE N-1'!$A$2:$A$2000,"282*",'BALANCE N-1'!$H$2:$H$2000)-SUMIF('BALANCE N-1'!$A$2:$A$2000,"282*",'BALANCE N-1'!$G$2:$G$2000)+SUMIF('BALANCE N-1'!$A$2:$A$2000,"292*",'BALANCE N-1'!$H$2:$H$2000)-SUMIF('BALANCE N-1'!$A$2:$A$2000,"292*",'BALANCE N-1'!$G$2:$G$2000)))
A19: AJ | B19: Batiments | D19: =(SUMIF('BALANCE N'!$A$2:$A$2000,"231*",'BALANCE N'!$G$2:$G$2000)-SUMIF('BALANCE N'!$A$2:$A$2000,"231*",'BALANCE N'!$H$2:$H$2000)+SUMIF('BALANCE N'!$A$2:$A$2000,"232*",'BALANCE N'!$G$2:$G$2000)-SUMIF('BALANCE N'!$A$2:$A$2000,"232*",'BALANCE N'!$H$2:$H$2000)+SUMIF('BALANCE N'!$A$2:$A$2000,"233*",'BALANCE N'!$G$2:$G$2000)-SUMIF('BALANCE N'!$A$2:$A$2000,"233*",'BALANCE N'!$H$2:$H$2000)+SUMIF('BALANCE N'!$A$2:$A$2000,"2391*",'BALANCE N'!$G$2:$G$2000)-SUMIF('BALANCE N'!$A$2:$A$2000,"2391*",'BALANCE N'!$H$2:$H$2000)+SUMIF('BALANCE N'!$A$2:$A$2000,"2392*",'BALANCE N'!$G$2:$G$2000)-SUMIF('BALANCE N'!$A$2:$A$2000,"2392*",'BALANCE N'!$H$2:$H$2000)+SUMIF('BALANCE N'!$A$2:$A$2000,"2393*",'BALANCE N'!$G$2:$G$2000)-SUMIF('BALANCE N'!$A$2:$A$2000,"2393*",'BALANCE N'!$H$2:$H$2000)+SUMIF('BALANCE N'!$A$2:$A$2000,"2396*",'BALANCE N'!$G$2:$G$2000)-SUMIF('BALANCE N'!$A$2:$A$2000,"2396*",'BALANCE N'!$H$2:$H$2000)) | E19: =(SUMIF('BALANCE N'!$A$2:$A$2000,"2831*",'BALANCE N'!$H$2:$H$2000)-SUMIF('BALANCE N'!$A$2:$A$2000,"2831*",'BALANCE N'!$G$2:$G$2000)+SUMIF('BALANCE N'!$A$2:$A$2000,"2832*",'BALANCE N'!$H$2:$H$2000)-SUMIF('BALANCE N'!$A$2:$A$2000,"2832*",'BALANCE N'!$G$2:$G$2000)+SUMIF('BALANCE N'!$A$2:$A$2000,"2833*",'BALANCE N'!$H$2:$H$2000)-SUMIF('BALANCE N'!$A$2:$A$2000,"2833*",'BALANCE N'!$G$2:$G$2000)+SUMIF('BALANCE N'!$A$2:$A$2000,"2931*",'BALANCE N'!$H$2:$H$2000)-SUMIF('BALANCE N'!$A$2:$A$2000,"2931*",'BALANCE N'!$G$2:$G$2000)+SUMIF('BALANCE N'!$A$2:$A$2000,"2932*",'BALANCE N'!$H$2:$H$2000)-SUMIF('BALANCE N'!$A$2:$A$2000,"2932*",'BALANCE N'!$G$2:$G$2000)+SUMIF('BALANCE N'!$A$2:$A$2000,"2933*",'BALANCE N'!$H$2:$H$2000)-SUMIF('BALANCE N'!$A$2:$A$2000,"2933*",'BALANCE N'!$G$2:$G$2000)+SUMIF('BALANCE N'!$A$2:$A$2000,"2939*",'BALANCE N'!$H$2:$H$2000)-SUMIF('BALANCE N'!$A$2:$A$2000,"2939*",'BALANCE N'!$G$2:$G$2000)) | F19: =D19-E19 | G19: =((SUMIF('BALANCE N-1'!$A$2:$A$2000,"231*",'BALANCE N-1'!$G$2:$G$2000)-SUMIF('BALANCE N-1'!$A$2:$A$2000,"231*",'BALANCE N-1'!$H$2:$H$2000)+SUMIF('BALANCE N-1'!$A$2:$A$2000,"232*",'BALANCE N-1'!$G$2:$G$2000)-SUMIF('BALANCE N-1'!$A$2:$A$2000,"232*",'BALANCE N-1'!$H$2:$H$2000)+SUMIF('BALANCE N-1'!$A$2:$A$2000,"233*",'BALANCE N-1'!$G$2:$G$2000)-SUMIF('BALANCE N-1'!$A$2:$A$2000,"233*",'BALANCE N-1'!$H$2:$H$2000)+SUMIF('BALANCE N-1'!$A$2:$A$2000,"2391*",'BALANCE N-1'!$G$2:$G$2000)-SUMIF('BALANCE N-1'!$A$2:$A$2000,"2391*",'BALANCE N-1'!$H$2:$H$2000)+SUMIF('BALANCE N-1'!$A$2:$A$2000,"2392*",'BALANCE N-1'!$G$2:$G$2000)-SUMIF('BALANCE N-1'!$A$2:$A$2000,"2392*",'BALANCE N-1'!$H$2:$H$2000)+SUMIF('BALANCE N-1'!$A$2:$A$2000,"2393*",'BALANCE N-1'!$G$2:$G$2000)-SUMIF('BALANCE N-1'!$A$2:$A$2000,"2393*",'BALANCE N-1'!$H$2:$H$2000)+SUMIF('BALANCE N-1'!$A$2:$A$2000,"2396*",'BALANCE N-1'!$G$2:$G$2000)-SUMIF('BALANCE N-1'!$A$2:$A$2000,"2396*",'BALANCE N-1'!$H$2:$H$2000)))-((SUMIF('BALANCE N-1'!$A$2:$A$2000,"2831*",'BALANCE N-1'!$H$2:$H$2000)-SUMIF('BALANCE N-1'!$A$2:$A$2000,"2831*",'BALANCE N-1'!$G$2:$G$2000)+SUMIF('BALANCE N-1'!$A$2:$A$2000,"2832*",'BALANCE N-1'!$H$2:$H$2000)-SUMIF('BALANCE N-1'!$A$2:$A$2000,"2832*",'BALANCE N-1'!$G$2:$G$2000)+SUMIF('BALANCE N-1'!$A$2:$A$2000,"2833*",'BALANCE N-1'!$H$2:$H$2000)-SUMIF('BALANCE N-1'!$A$2:$A$2000,"2833*",'BALANCE N-1'!$G$2:$G$2000)+SUMIF('BALANCE N-1'!$A$2:$A$2000,"2931*",'BALANCE N-1'!$H$2:$H$2000)-SUMIF('BALANCE N-1'!$A$2:$A$2000,"2931*",'BALANCE N-1'!$G$2:$G$2000)+SUMIF('BALANCE N-1'!$A$2:$A$2000,"2932*",'BALANCE N-1'!$H$2:$H$2000)-SUMIF('BALANCE N-1'!$A$2:$A$2000,"2932*",'BALANCE N-1'!$G$2:$G$2000)+SUMIF('BALANCE N-1'!$A$2:$A$2000,"2933*",'BALANCE N-1'!$H$2:$H$2000)-SUMIF('BALANCE N-1'!$A$2:$A$2000,"2933*",'BALANCE N-1'!$G$2:$G$2000)+SUMIF('BALANCE N-1'!$A$2:$A$2000,"2939*",'BALANCE N-1'!$H$2:$H$2000)-SUMIF('BALANCE N-1'!$A$2:$A$2000,"2939*",'BALANCE N-1'!$G$2:$G$2000)))
A20: AK | B20: Amenagements, agencements et installations | D20: =(SUMIF('BALANCE N'!$A$2:$A$2000,"234*",'BALANCE N'!$G$2:$G$2000)-SUMIF('BALANCE N'!$A$2:$A$2000,"234*",'BALANCE N'!$H$2:$H$2000)+SUMIF('BALANCE N'!$A$2:$A$2000,"235*",'BALANCE N'!$G$2:$G$2000)-SUMIF('BALANCE N'!$A$2:$A$2000,"235*",'BALANCE N'!$H$2:$H$2000)+SUMIF('BALANCE N'!$A$2:$A$2000,"238*",'BALANCE N'!$G$2:$G$2000)-SUMIF('BALANCE N'!$A$2:$A$2000,"238*",'BALANCE N'!$H$2:$H$2000)+SUMIF('BALANCE N'!$A$2:$A$2000,"2394*",'BALANCE N'!$G$2:$G$2000)-SUMIF('BALANCE N'!$A$2:$A$2000,"2394*",'BALANCE N'!$H$2:$H$2000)+SUMIF('BALANCE N'!$A$2:$A$2000,"2395*",'BALANCE N'!$G$2:$G$2000)-SUMIF('BALANCE N'!$A$2:$A$2000,"2395*",'BALANCE N'!$H$2:$H$2000)+SUMIF('BALANCE N'!$A$2:$A$2000,"2398*",'BALANCE N'!$G$2:$G$2000)-SUMIF('BALANCE N'!$A$2:$A$2000,"2398*",'BALANCE N'!$H$2:$H$2000)) | E20: =(SUMIF('BALANCE N'!$A$2:$A$2000,"2834*",'BALANCE N'!$H$2:$H$2000)-SUMIF('BALANCE N'!$A$2:$A$2000,"2834*",'BALANCE N'!$G$2:$G$2000)+SUMIF('BALANCE N'!$A$2:$A$2000,"2835*",'BALANCE N'!$H$2:$H$2000)-SUMIF('BALANCE N'!$A$2:$A$2000,"2835*",'BALANCE N'!$G$2:$G$2000)+SUMIF('BALANCE N'!$A$2:$A$2000,"2838*",'BALANCE N'!$H$2:$H$2000)-SUMIF('BALANCE N'!$A$2:$A$2000,"2838*",'BALANCE N'!$G$2:$G$2000)+SUMIF('BALANCE N'!$A$2:$A$2000,"2934*",'BALANCE N'!$H$2:$H$2000)-SUMIF('BALANCE N'!$A$2:$A$2000,"2934*",'BALANCE N'!$G$2:$G$2000)+SUMIF('BALANCE N'!$A$2:$A$2000,"2935*",'BALANCE N'!$H$2:$H$2000)-SUMIF('BALANCE N'!$A$2:$A$2000,"2935*",'BALANCE N'!$G$2:$G$2000)+SUMIF('BALANCE N'!$A$2:$A$2000,"2938*",'BALANCE N'!$H$2:$H$2000)-SUMIF('BALANCE N'!$A$2:$A$2000,"2938*",'BALANCE N'!$G$2:$G$2000)+SUMIF('BALANCE N'!$A$2:$A$2000,"2939*",'BALANCE N'!$H$2:$H$2000)-SUMIF('BALANCE N'!$A$2:$A$2000,"2939*",'BALANCE N'!$G$2:$G$2000)) | F20: =D20-E20 | G20: =((SUMIF('BALANCE N-1'!$A$2:$A$2000,"234*",'BALANCE N-1'!$G$2:$G$2000)-SUMIF('BALANCE N-1'!$A$2:$A$2000,"234*",'BALANCE N-1'!$H$2:$H$2000)+SUMIF('BALANCE N-1'!$A$2:$A$2000,"235*",'BALANCE N-1'!$G$2:$G$2000)-SUMIF('BALANCE N-1'!$A$2:$A$2000,"235*",'BALANCE N-1'!$H$2:$H$2000)+SUMIF('BALANCE N-1'!$A$2:$A$2000,"238*",'BALANCE N-1'!$G$2:$G$2000)-SUMIF('BALANCE N-1'!$A$2:$A$2000,"238*",'BALANCE N-1'!$H$2:$H$2000)+SUMIF('BALANCE N-1'!$A$2:$A$2000,"2394*",'BALANCE N-1'!$G$2:$G$2000)-SUMIF('BALANCE N-1'!$A$2:$A$2000,"2394*",'BALANCE N-1'!$H$2:$H$2000)+SUMIF('BALANCE N-1'!$A$2:$A$2000,"2395*",'BALANCE N-1'!$G$2:$G$2000)-SUMIF('BALANCE N-1'!$A$2:$A$2000,"2395*",'BALANCE N-1'!$H$2:$H$2000)+SUMIF('BALANCE N-1'!$A$2:$A$2000,"2398*",'BALANCE N-1'!$G$2:$G$2000)-SUMIF('BALANCE N-1'!$A$2:$A$2000,"2398*",'BALANCE N-1'!$H$2:$H$2000)))-((SUMIF('BALANCE N-1'!$A$2:$A$2000,"2834*",'BALANCE N-1'!$H$2:$H$2000)-SUMIF('BALANCE N-1'!$A$2:$A$2000,"2834*",'BALANCE N-1'!$G$2:$G$2000)+SUMIF('BALANCE N-1'!$A$2:$A$2000,"2835*",'BALANCE N-1'!$H$2:$H$2000)-SUMIF('BALANCE N-1'!$A$2:$A$2000,"2835*",'BALANCE N-1'!$G$2:$G$2000)+SUMIF('BALANCE N-1'!$A$2:$A$2000,"2838*",'BALANCE N-1'!$H$2:$H$2000)-SUMIF('BALANCE N-1'!$A$2:$A$2000,"2838*",'BALANCE N-1'!$G$2:$G$2000)+SUMIF('BALANCE N-1'!$A$2:$A$2000,"2934*",'BALANCE N-1'!$H$2:$H$2000)-SUMIF('BALANCE N-1'!$A$2:$A$2000,"2934*",'BALANCE N-1'!$G$2:$G$2000)+SUMIF('BALANCE N-1'!$A$2:$A$2000,"2935*",'BALANCE N-1'!$H$2:$H$2000)-SUMIF('BALANCE N-1'!$A$2:$A$2000,"2935*",'BALANCE N-1'!$G$2:$G$2000)+SUMIF('BALANCE N-1'!$A$2:$A$2000,"2938*",'BALANCE N-1'!$H$2:$H$2000)-SUMIF('BALANCE N-1'!$A$2:$A$2000,"2938*",'BALANCE N-1'!$G$2:$G$2000)+SUMIF('BALANCE N-1'!$A$2:$A$2000,"2939*",'BALANCE N-1'!$H$2:$H$2000)-SUMIF('BALANCE N-1'!$A$2:$A$2000,"2939*",'BALANCE N-1'!$G$2:$G$2000)))
A21: AL | B21: Materiel, mobilier et actifs biologiques | D21: =(SUMIF('BALANCE N'!$A$2:$A$2000,"24*",'BALANCE N'!$G$2:$G$2000)-SUMIF('BALANCE N'!$A$2:$A$2000,"24*",'BALANCE N'!$H$2:$H$2000)-SUMIF('BALANCE N'!$A$2:$A$2000,"245*",'BALANCE N'!$G$2:$G$2000)+SUMIF('BALANCE N'!$A$2:$A$2000,"245*",'BALANCE N'!$H$2:$H$2000)-SUMIF('BALANCE N'!$A$2:$A$2000,"2495*",'BALANCE N'!$G$2:$G$2000)+SUMIF('BALANCE N'!$A$2:$A$2000,"2495*",'BALANCE N'!$H$2:$H$2000)) | E21: =(SUMIF('BALANCE N'!$A$2:$A$2000,"284*",'BALANCE N'!$H$2:$H$2000)-SUMIF('BALANCE N'!$A$2:$A$2000,"284*",'BALANCE N'!$G$2:$G$2000)+SUMIF('BALANCE N'!$A$2:$A$2000,"294*",'BALANCE N'!$H$2:$H$2000)-SUMIF('BALANCE N'!$A$2:$A$2000,"294*",'BALANCE N'!$G$2:$G$2000)-SUMIF('BALANCE N'!$A$2:$A$2000,"2845*",'BALANCE N'!$H$2:$H$2000)+SUMIF('BALANCE N'!$A$2:$A$2000,"2845*",'BALANCE N'!$G$2:$G$2000)-SUMIF('BALANCE N'!$A$2:$A$2000,"2945*",'BALANCE N'!$H$2:$H$2000)+SUMIF('BALANCE N'!$A$2:$A$2000,"2945*",'BALANCE N'!$G$2:$G$2000)-SUMIF('BALANCE N'!$A$2:$A$2000,"2949*",'BALANCE N'!$H$2:$H$2000)+SUMIF('BALANCE N'!$A$2:$A$2000,"2949*",'BALANCE N'!$G$2:$G$2000)) | F21: =D21-E21 | G21: =((SUMIF('BALANCE N-1'!$A$2:$A$2000,"24*",'BALANCE N-1'!$G$2:$G$2000)-SUMIF('BALANCE N-1'!$A$2:$A$2000,"24*",'BALANCE N-1'!$H$2:$H$2000)-SUMIF('BALANCE N-1'!$A$2:$A$2000,"245*",'BALANCE N-1'!$G$2:$G$2000)+SUMIF('BALANCE N-1'!$A$2:$A$2000,"245*",'BALANCE N-1'!$H$2:$H$2000)-SUMIF('BALANCE N-1'!$A$2:$A$2000,"2495*",'BALANCE N-1'!$G$2:$G$2000)+SUMIF('BALANCE N-1'!$A$2:$A$2000,"2495*",'BALANCE N-1'!$H$2:$H$2000)))-((SUMIF('BALANCE N-1'!$A$2:$A$2000,"284*",'BALANCE N-1'!$H$2:$H$2000)-SUMIF('BALANCE N-1'!$A$2:$A$2000,"284*",'BALANCE N-1'!$G$2:$G$2000)+SUMIF('BALANCE N-1'!$A$2:$A$2000,"294*",'BALANCE N-1'!$H$2:$H$2000)-SUMIF('BALANCE N-1'!$A$2:$A$2000,"294*",'BALANCE N-1'!$G$2:$G$2000)-SUMIF('BALANCE N-1'!$A$2:$A$2000,"2845*",'BALANCE N-1'!$H$2:$H$2000)+SUMIF('BALANCE N-1'!$A$2:$A$2000,"2845*",'BALANCE N-1'!$G$2:$G$2000)-SUMIF('BALANCE N-1'!$A$2:$A$2000,"2945*",'BALANCE N-1'!$H$2:$H$2000)+SUMIF('BALANCE N-1'!$A$2:$A$2000,"2945*",'BALANCE N-1'!$G$2:$G$2000)-SUMIF('BALANCE N-1'!$A$2:$A$2000,"2949*",'BALANCE N-1'!$H$2:$H$2000)+SUMIF('BALANCE N-1'!$A$2:$A$2000,"2949*",'BALANCE N-1'!$G$2:$G$2000)))
A22: AM | B22: Materiel de transport | D22: =(SUMIF('BALANCE N'!$A$2:$A$2000,"245*",'BALANCE N'!$G$2:$G$2000)-SUMIF('BALANCE N'!$A$2:$A$2000,"245*",'BALANCE N'!$H$2:$H$2000)+SUMIF('BALANCE N'!$A$2:$A$2000,"2495*",'BALANCE N'!$G$2:$G$2000)-SUMIF('BALANCE N'!$A$2:$A$2000,"2495*",'BALANCE N'!$H$2:$H$2000)) | E22: =(SUMIF('BALANCE N'!$A$2:$A$2000,"2845*",'BALANCE N'!$H$2:$H$2000)-SUMIF('BALANCE N'!$A$2:$A$2000,"2845*",'BALANCE N'!$G$2:$G$2000)+SUMIF('BALANCE N'!$A$2:$A$2000,"2945*",'BALANCE N'!$H$2:$H$2000)-SUMIF('BALANCE N'!$A$2:$A$2000,"2945*",'BALANCE N'!$G$2:$G$2000)+SUMIF('BALANCE N'!$A$2:$A$2000,"2949*",'BALANCE N'!$H$2:$H$2000)-SUMIF('BALANCE N'!$A$2:$A$2000,"2949*",'BALANCE N'!$G$2:$G$2000)) | F22: =D22-E22 | G22: =((SUMIF('BALANCE N-1'!$A$2:$A$2000,"245*",'BALANCE N-1'!$G$2:$G$2000)-SUMIF('BALANCE N-1'!$A$2:$A$2000,"245*",'BALANCE N-1'!$H$2:$H$2000)+SUMIF('BALANCE N-1'!$A$2:$A$2000,"2495*",'BALANCE N-1'!$G$2:$G$2000)-SUMIF('BALANCE N-1'!$A$2:$A$2000,"2495*",'BALANCE N-1'!$H$2:$H$2000)))-((SUMIF('BALANCE N-1'!$A$2:$A$2000,"2845*",'BALANCE N-1'!$H$2:$H$2000)-SUMIF('BALANCE N-1'!$A$2:$A$2000,"2845*",'BALANCE N-1'!$G$2:$G$2000)+SUMIF('BALANCE N-1'!$A$2:$A$2000,"2945*",'BALANCE N-1'!$H$2:$H$2000)-SUMIF('BALANCE N-1'!$A$2:$A$2000,"2945*",'BALANCE N-1'!$G$2:$G$2000)+SUMIF('BALANCE N-1'!$A$2:$A$2000,"2949*",'BALANCE N-1'!$H$2:$H$2000)-SUMIF('BALANCE N-1'!$A$2:$A$2000,"2949*",'BALANCE N-1'!$G$2:$G$2000)))
A23: AN | B23: Avances et acomptes verses sur immobilisations corporelles | D23: =(SUMIF('BALANCE N'!$A$2:$A$2000,"252*",'BALANCE N'!$G$2:$G$2000)-SUMIF('BALANCE N'!$A$2:$A$2000,"252*",'BALANCE N'!$H$2:$H$2000)) | E23: =(SUMIF('BALANCE N'!$A$2:$A$2000,"2952*",'BALANCE N'!$H$2:$H$2000)-SUMIF('BALANCE N'!$A$2:$A$2000,"2952*",'BALANCE N'!$G$2:$G$2000)) | F23: =D23-E23 | G23: =((SUMIF('BALANCE N-1'!$A$2:$A$2000,"252*",'BALANCE N-1'!$G$2:$G$2000)-SUMIF('BALANCE N-1'!$A$2:$A$2000,"252*",'BALANCE N-1'!$H$2:$H$2000)))-((SUMIF('BALANCE N-1'!$A$2:$A$2000,"2952*",'BALANCE N-1'!$H$2:$H$2000)-SUMIF('BALANCE N-1'!$A$2:$A$2000,"2952*",'BALANCE N-1'!$G$2:$G$2000)))
A24: AO | B24: IMMOBILISATIONS FINANCIERES | C24: note 6 | D24: =D25+D26 | E24: =E25+E26 | F24: =F25+F26 | G24: =G25+G26
A25: AX | B25: Titres de participation | D25: =(SUMIF('BALANCE N'!$A$2:$A$2000,"26*",'BALANCE N'!$G$2:$G$2000)-SUMIF('BALANCE N'!$A$2:$A$2000,"26*",'BALANCE N'!$H$2:$H$2000)) | E25: =(SUMIF('BALANCE N'!$A$2:$A$2000,"296*",'BALANCE N'!$H$2:$H$2000)-SUMIF('BALANCE N'!$A$2:$A$2000,"296*",'BALANCE N'!$G$2:$G$2000)) | F25: =D25-E25 | G25: =((SUMIF('BALANCE N-1'!$A$2:$A$2000,"26*",'BALANCE N-1'!$G$2:$G$2000)-SUMIF('BALANCE N-1'!$A$2:$A$2000,"26*",'BALANCE N-1'!$H$2:$H$2000)))-((SUMIF('BALANCE N-1'!$A$2:$A$2000,"296*",'BALANCE N-1'!$H$2:$H$2000)-SUMIF('BALANCE N-1'!$A$2:$A$2000,"296*",'BALANCE N-1'!$G$2:$G$2000)))
A26: AY | B26: Autres immobilisations financieres | D26: =(SUMIF('BALANCE N'!$A$2:$A$2000,"27*",'BALANCE N'!$G$2:$G$2000)-SUMIF('BALANCE N'!$A$2:$A$2000,"27*",'BALANCE N'!$H$2:$H$2000)) | E26: =(SUMIF('BALANCE N'!$A$2:$A$2000,"297*",'BALANCE N'!$H$2:$H$2000)-SUMIF('BALANCE N'!$A$2:$A$2000,"297*",'BALANCE N'!$G$2:$G$2000)) | F26: =D26-E26 | G26: =((SUMIF('BALANCE N-1'!$A$2:$A$2000,"27*",'BALANCE N-1'!$G$2:$G$2000)-SUMIF('BALANCE N-1'!$A$2:$A$2000,"27*",'BALANCE N-1'!$H$2:$H$2000)))-((SUMIF('BALANCE N-1'!$A$2:$A$2000,"297*",'BALANCE N-1'!$H$2:$H$2000)-SUMIF('BALANCE N-1'!$A$2:$A$2000,"297*",'BALANCE N-1'!$G$2:$G$2000)))
A27: AZ | B27: TOTAL ACTIF IMMOBILISE | D27: =D10+D13+D17+D24 | E27: =E10+E13+E17+E24 | F27: =F10+F13+F17+F24 | G27: =G10+G13+G17+G24
A28: BA | B28: Actif circulant HAO | C28: note 7 | D28: =(SUMIF('BALANCE N'!$A$2:$A$2000,"485*",'BALANCE N'!$G$2:$G$2000)-SUMIF('BALANCE N'!$A$2:$A$2000,"485*",'BALANCE N'!$H$2:$H$2000)+SUMIF('BALANCE N'!$A$2:$A$2000,"4865*",'BALANCE N'!$G$2:$G$2000)-SUMIF('BALANCE N'!$A$2:$A$2000,"4865*",'BALANCE N'!$H$2:$H$2000)) | E28: =(SUMIF('BALANCE N'!$A$2:$A$2000,"498*",'BALANCE N'!$H$2:$H$2000)-SUMIF('BALANCE N'!$A$2:$A$2000,"498*",'BALANCE N'!$G$2:$G$2000)) | F28: =D28-E28 | G28: =((SUMIF('BALANCE N-1'!$A$2:$A$2000,"485*",'BALANCE N-1'!$G$2:$G$2000)-SUMIF('BALANCE N-1'!$A$2:$A$2000,"485*",'BALANCE N-1'!$H$2:$H$2000)+SUMIF('BALANCE N-1'!$A$2:$A$2000,"4865*",'BALANCE N-1'!$G$2:$G$2000)-SUMIF('BALANCE N-1'!$A$2:$A$2000,"4865*",'BALANCE N-1'!$H$2:$H$2000)))-((SUMIF('BALANCE N-1'!$A$2:$A$2000,"498*",'BALANCE N-1'!$H$2:$H$2000)-SUMIF('BALANCE N-1'!$A$2:$A$2000,"498*",'BALANCE N-1'!$G$2:$G$2000)))
A29: BB | B29: Stocks et encours | C29: note 8 | D29: =(SUMIF('BALANCE N'!$A$2:$A$2000,"31*",'BALANCE N'!$G$2:$G$2000)-SUMIF('BALANCE N'!$A$2:$A$2000,"31*",'BALANCE N'!$H$2:$H$2000)+SUMIF('BALANCE N'!$A$2:$A$2000,"32*",'BALANCE N'!$G$2:$G$2000)-SUMIF('BALANCE N'!$A$2:$A$2000,"32*",'BALANCE N'!$H$2:$H$2000)+SUMIF('BALANCE N'!$A$2:$A$2000,"33*",'BALANCE N'!$G$2:$G$2000)-SUMIF('BALANCE N'!$A$2:$A$2000,"33*",'BALANCE N'!$H$2:$H$2000)+SUMIF('BALANCE N'!$A$2:$A$2000,"34*",'BALANCE N'!$G$2:$G$2000)-SUMIF('BALANCE N'!$A$2:$A$2000,"34*",'BALANCE N'!$H$2:$H$2000)+SUMIF('BALANCE N'!$A$2:$A$2000,"36*",'BALANCE N'!$G$2:$G$2000)-SUMIF('BALANCE N'!$A$2:$A$2000,"36*",'BALANCE N'!$H$2:$H$2000)+SUMIF('BALANCE N'!$A$2:$A$2000,"37*",'BALANCE N'!$G$2:$G$2000)-SUMIF('BALANCE N'!$A$2:$A$2000,"37*",'BALANCE N'!$H$2:$H$2000)+SUMIF('BALANCE N'!$A$2:$A$2000,"38*",'BALANCE N'!$G$2:$G$2000)-SUMIF('BALANCE N'!$A$2:$A$2000,"38*",'BALANCE N'!$H$2:$H$2000)) | E29: =(SUMIF('BALANCE N'!$A$2:$A$2000,"39*",'BALANCE N'!$H$2:$H$2000)-SUMIF('BALANCE N'!$A$2:$A$2000,"39*",'BALANCE N'!$G$2:$G$2000)) | F29: =D29-E29 | G29: =((SUMIF('BALANCE N-1'!$A$2:$A$2000,"31*",'BALANCE N-1'!$G$2:$G$2000)-SUMIF('BALANCE N-1'!$A$2:$A$2000,"31*",'BALANCE N-1'!$H$2:$H$2000)+SUMIF('BALANCE N-1'!$A$2:$A$2000,"32*",'BALANCE N-1'!$G$2:$G$2000)-SUMIF('BALANCE N-1'!$A$2:$A$2000,"32*",'BALANCE N-1'!$H$2:$H$2000)+SUMIF('BALANCE N-1'!$A$2:$A$2000,"33*",'BALANCE N-1'!$G$2:$G$2000)-SUMIF('BALANCE N-1'!$A$2:$A$2000,"33*",'BALANCE N-1'!$H$2:$H$2000)+SUMIF('BALANCE N-1'!$A$2:$A$2000,"34*",'BALANCE N-1'!$G$2:$G$2000)-SUMIF('BALANCE N-1'!$A$2:$A$2000,"34*",'BALANCE N-1'!$H$2:$H$2000)+SUMIF('BALANCE N-1'!$A$2:$A$2000,"36*",'BALANCE N-1'!$G$2:$G$2000)-SUMIF('BALANCE N-1'!$A$2:$A$2000,"36*",'BALANCE N-1'!$H$2:$H$2000)+SUMIF('BALANCE N-1'!$A$2:$A$2000,"37*",'BALANCE N-1'!$G$2:$G$2000)-SUMIF('BALANCE N-1'!$A$2:$A$2000,"37*",'BALANCE N-1'!$H$2:$H$2000)+SUMIF('BALANCE N-1'!$A$2:$A$2000,"38*",'BALANCE N-1'!$G$2:$G$2000)-SUMIF('BALANCE N-1'!$A$2:$A$2000,"38*",'BALANCE N-1'!$H$2:$H$2000)))-((SUMIF('BALANCE N-1'!$A$2:$A$2000,"39*",'BALANCE N-1'!$H$2:$H$2000)-SUMIF('BALANCE N-1'!$A$2:$A$2000,"39*",'BALANCE N-1'!$G$2:$G$2000)))
A30: BC | B30: Fournisseurs debiteurs | C30: note 19 | D30: =(SUMIF('BALANCE N'!$A$2:$A$2000,"409*",'BALANCE N'!$G$2:$G$2000)-SUMIF('BALANCE N'!$A$2:$A$2000,"409*",'BALANCE N'!$H$2:$H$2000)) | E30: =(SUMIF('BALANCE N'!$A$2:$A$2000,"490*",'BALANCE N'!$H$2:$H$2000)-SUMIF('BALANCE N'!$A$2:$A$2000,"490*",'BALANCE N'!$G$2:$G$2000)) | F30: =D30-E30 | G30: =((SUMIF('BALANCE N-1'!$A$2:$A$2000,"409*",'BALANCE N-1'!$G$2:$G$2000)-SUMIF('BALANCE N-1'!$A$2:$A$2000,"409*",'BALANCE N-1'!$H$2:$H$2000)))-((SUMIF('BALANCE N-1'!$A$2:$A$2000,"490*",'BALANCE N-1'!$H$2:$H$2000)-SUMIF('BALANCE N-1'!$A$2:$A$2000,"490*",'BALANCE N-1'!$G$2:$G$2000)))
A31: BD | B31: Adherents, Clients-usagers | C31: note 9 | D31: =(SUMIF('BALANCE N'!$A$2:$A$2000,"41*",'BALANCE N'!$G$2:$G$2000)-SUMIF('BALANCE N'!$A$2:$A$2000,"41*",'BALANCE N'!$H$2:$H$2000)-SUMIF('BALANCE N'!$A$2:$A$2000,"419*",'BALANCE N'!$G$2:$G$2000)+SUMIF('BALANCE N'!$A$2:$A$2000,"419*",'BALANCE N'!$H$2:$H$2000)) | E31: =(SUMIF('BALANCE N'!$A$2:$A$2000,"491*",'BALANCE N'!$H$2:$H$2000)-SUMIF('BALANCE N'!$A$2:$A$2000,"491*",'BALANCE N'!$G$2:$G$2000)) | F31: =D31-E31 | G31: =((SUMIF('BALANCE N-1'!$A$2:$A$2000,"41*",'BALANCE N-1'!$G$2:$G$2000)-SUMIF('BALANCE N-1'!$A$2:$A$2000,"41*",'BALANCE N-1'!$H$2:$H$2000)-SUMIF('BALANCE N-1'!$A$2:$A$2000,"419*",'BALANCE N-1'!$G$2:$G$2000)+SUMIF('BALANCE N-1'!$A$2:$A$2000,"419*",'BALANCE N-1'!$H$2:$H$2000)))-((SUMIF('BALANCE N-1'!$A$2:$A$2000,"491*",'BALANCE N-1'!$H$2:$H$2000)-SUMIF('BALANCE N-1'!$A$2:$A$2000,"491*",'BALANCE N-1'!$G$2:$G$2000)))
A32: BE | B32: Autres creances | C32: note 10 | D32: =(SUMIF('BALANCE N'!$A$2:$A$2000,"42*",'BALANCE N'!$G$2:$G$2000)+SUMIF('BALANCE N'!$A$2:$A$2000,"43*",'BALANCE N'!$G$2:$G$2000)+SUMIF('BALANCE N'!$A$2:$A$2000,"44*",'BALANCE N'!$G$2:$G$2000)+SUMIF('BALANCE N'!$A$2:$A$2000,"45*",'BALANCE N'!$G$2:$G$2000)+SUMIF('BALANCE N'!$A$2:$A$2000,"46*",'BALANCE N'!$G$2:$G$2000)+SUMIF('BALANCE N'!$A$2:$A$2000,"47*",'BALANCE N'!$G$2:$G$2000)-SUMIF('BALANCE N'!$A$2:$A$2000,"478*",'BALANCE N'!$G$2:$G$2000)) | E32: =(SUMIF('BALANCE N'!$A$2:$A$2000,"492*",'BALANCE N'!$H$2:$H$2000)-SUMIF('BALANCE N'!$A$2:$A$2000,"492*",'BALANCE N'!$G$2:$G$2000)+SUMIF('BALANCE N'!$A$2:$A$2000,"493*",'BALANCE N'!$H$2:$H$2000)-SUMIF('BALANCE N'!$A$2:$A$2000,"493*",'BALANCE N'!$G$2:$G$2000)+SUMIF('BALANCE N'!$A$2:$A$2000,"494*",'BALANCE N'!$H$2:$H$2000)-SUMIF('BALANCE N'!$A$2:$A$2000,"494*",'BALANCE N'!$G$2:$G$2000)+SUMIF('BALANCE N'!$A$2:$A$2000,"497*",'BALANCE N'!$H$2:$H$2000)-SUMIF('BALANCE N'!$A$2:$A$2000,"497*",'BALANCE N'!$G$2:$G$2000)) | F32: =D32-E32 | G32: =((SUMIF('BALANCE N-1'!$A$2:$A$2000,"42*",'BALANCE N-1'!$G$2:$G$2000)+SUMIF('BALANCE N-1'!$A$2:$A$2000,"43*",'BALANCE N-1'!$G$2:$G$2000)+SUMIF('BALANCE N-1'!$A$2:$A$2000,"44*",'BALANCE N-1'!$G$2:$G$2000)+SUMIF('BALANCE N-1'!$A$2:$A$2000,"45*",'BALANCE N-1'!$G$2:$G$2000)+SUMIF('BALANCE N-1'!$A$2:$A$2000,"46*",'BALANCE N-1'!$G$2:$G$2000)+SUMIF('BALANCE N-1'!$A$2:$A$2000,"47*",'BALANCE N-1'!$G$2:$G$2000)-SUMIF('BALANCE N-1'!$A$2:$A$2000,"478*",'BALANCE N-1'!$G$2:$G$2000)))-((SUMIF('BALANCE N-1'!$A$2:$A$2000,"492*",'BALANCE N-1'!$H$2:$H$2000)-SUMIF('BALANCE N-1'!$A$2:$A$2000,"492*",'BALANCE N-1'!$G$2:$G$2000)+SUMIF('BALANCE N-1'!$A$2:$A$2000,"493*",'BALANCE N-1'!$H$2:$H$2000)-SUMIF('BALANCE N-1'!$A$2:$A$2000,"493*",'BALANCE N-1'!$G$2:$G$2000)+SUMIF('BALANCE N-1'!$A$2:$A$2000,"494*",'BALANCE N-1'!$H$2:$H$2000)-SUMIF('BALANCE N-1'!$A$2:$A$2000,"494*",'BALANCE N-1'!$G$2:$G$2000)+SUMIF('BALANCE N-1'!$A$2:$A$2000,"497*",'BALANCE N-1'!$H$2:$H$2000)-SUMIF('BALANCE N-1'!$A$2:$A$2000,"497*",'BALANCE N-1'!$G$2:$G$2000)))
A33: BT | B33: TOTAL ACTIF CIRCULANT | D33: =D28+D29+D30+D31+D32 | E33: =E28+E29+E30+E31+E32 | F33: =F28+F29+F30+F31+F32 | G33: =G28+G29+G30+G31+G32
A34: BU | B34: Titres de placement | C34: note 11 | D34: =(SUMIF('BALANCE N'!$A$2:$A$2000,"50*",'BALANCE N'!$G$2:$G$2000)-SUMIF('BALANCE N'!$A$2:$A$2000,"50*",'BALANCE N'!$H$2:$H$2000)) | E34: =(SUMIF('BALANCE N'!$A$2:$A$2000,"590*",'BALANCE N'!$H$2:$H$2000)-SUMIF('BALANCE N'!$A$2:$A$2000,"590*",'BALANCE N'!$G$2:$G$2000)) | F34: =D34-E34 | G34: =((SUMIF('BALANCE N-1'!$A$2:$A$2000,"50*",'BALANCE N-1'!$G$2:$G$2000)-SUMIF('BALANCE N-1'!$A$2:$A$2000,"50*",'BALANCE N-1'!$H$2:$H$2000)))-((SUMIF('BALANCE N-1'!$A$2:$A$2000,"590*",'BALANCE N-1'!$H$2:$H$2000)-SUMIF('BALANCE N-1'!$A$2:$A$2000,"590*",'BALANCE N-1'!$G$2:$G$2000)))
A35: BV | B35: Valeurs a encaisser | C35: note 12 | D35: =(SUMIF('BALANCE N'!$A$2:$A$2000,"51*",'BALANCE N'!$G$2:$G$2000)-SUMIF('BALANCE N'!$A$2:$A$2000,"51*",'BALANCE N'!$H$2:$H$2000)) | E35: =(SUMIF('BALANCE N'!$A$2:$A$2000,"591*",'BALANCE N'!$H$2:$H$2000)-SUMIF('BALANCE N'!$A$2:$A$2000,"591*",'BALANCE N'!$G$2:$G$2000)) | F35: =D35-E35 | G35: =((SUMIF('BALANCE N-1'!$A$2:$A$2000,"51*",'BALANCE N-1'!$G$2:$G$2000)-SUMIF('BALANCE N-1'!$A$2:$A$2000,"51*",'BALANCE N-1'!$H$2:$H$2000)))-((SUMIF('BALANCE N-1'!$A$2:$A$2000,"591*",'BALANCE N-1'!$H$2:$H$2000)-SUMIF('BALANCE N-1'!$A$2:$A$2000,"591*",'BALANCE N-1'!$G$2:$G$2000)))
A36: BW | B36: Banques, etablissements financiers, caisses et assimiles | C36: note 13 | D36: =(SUMIF('BALANCE N'!$A$2:$A$2000,"52*",'BALANCE N'!$G$2:$G$2000)-SUMIF('BALANCE N'!$A$2:$A$2000,"52*",'BALANCE N'!$H$2:$H$2000)+SUMIF('BALANCE N'!$A$2:$A$2000,"53*",'BALANCE N'!$G$2:$G$2000)-SUMIF('BALANCE N'!$A$2:$A$2000,"53*",'BALANCE N'!$H$2:$H$2000)+SUMIF('BALANCE N'!$A$2:$A$2000,"55*",'BALANCE N'!$G$2:$G$2000)-SUMIF('BALANCE N'!$A$2:$A$2000,"55*",'BALANCE N'!$H$2:$H$2000)+SUMIF('BALANCE N'!$A$2:$A$2000,"57*",'BALANCE N'!$G$2:$G$2000)-SUMIF('BALANCE N'!$A$2:$A$2000,"57*",'BALANCE N'!$H$2:$H$2000)) | E36: =(SUMIF('BALANCE N'!$A$2:$A$2000,"592*",'BALANCE N'!$H$2:$H$2000)-SUMIF('BALANCE N'!$A$2:$A$2000,"592*",'BALANCE N'!$G$2:$G$2000)+SUMIF('BALANCE N'!$A$2:$A$2000,"593*",'BALANCE N'!$H$2:$H$2000)-SUMIF('BALANCE N'!$A$2:$A$2000,"593*",'BALANCE N'!$G$2:$G$2000)+SUMIF('BALANCE N'!$A$2:$A$2000,"595*",'BALANCE N'!$H$2:$H$2000)-SUMIF('BALANCE N'!$A$2:$A$2000,"595*",'BALANCE N'!$G$2:$G$2000)) | F36: =D36-E36 | G36: =((SUMIF('BALANCE N-1'!$A$2:$A$2000,"52*",'BALANCE N-1'!$G$2:$G$2000)-SUMIF('BALANCE N-1'!$A$2:$A$2000,"52*",'BALANCE N-1'!$H$2:$H$2000)+SUMIF('BALANCE N-1'!$A$2:$A$2000,"53*",'BALANCE N-1'!$G$2:$G$2000)-SUMIF('BALANCE N-1'!$A$2:$A$2000,"53*",'BALANCE N-1'!$H$2:$H$2000)+SUMIF('BALANCE N-1'!$A$2:$A$2000,"55*",'BALANCE N-1'!$G$2:$G$2000)-SUMIF('BALANCE N-1'!$A$2:$A$2000,"55*",'BALANCE N-1'!$H$2:$H$2000)+SUMIF('BALANCE N-1'!$A$2:$A$2000,"57*",'BALANCE N-1'!$G$2:$G$2000)-SUMIF('BALANCE N-1'!$A$2:$A$2000,"57*",'BALANCE N-1'!$H$2:$H$2000)))-((SUMIF('BALANCE N-1'!$A$2:$A$2000,"592*",'BALANCE N-1'!$H$2:$H$2000)-SUMIF('BALANCE N-1'!$A$2:$A$2000,"592*",'BALANCE N-1'!$G$2:$G$2000)+SUMIF('BALANCE N-1'!$A$2:$A$2000,"593*",'BALANCE N-1'!$H$2:$H$2000)-SUMIF('BALANCE N-1'!$A$2:$A$2000,"593*",'BALANCE N-1'!$G$2:$G$2000)+SUMIF('BALANCE N-1'!$A$2:$A$2000,"595*",'BALANCE N-1'!$H$2:$H$2000)-SUMIF('BALANCE N-1'!$A$2:$A$2000,"595*",'BALANCE N-1'!$G$2:$G$2000)))
A37: BX | B37: TOTAL TRESORERIE ACTIF | D37: =D34+D35+D36 | E37: =E34+E35+E36 | F37: =F34+F35+F36 | G37: =G34+G35+G36
A38: BY | B38: Ecart de conversion-Actif | C38: note 14 | D38: =(SUMIF('BALANCE N'!$A$2:$A$2000,"478*",'BALANCE N'!$G$2:$G$2000)-SUMIF('BALANCE N'!$A$2:$A$2000,"478*",'BALANCE N'!$H$2:$H$2000)) | E38: 0 | F38: =D38-E38 | G38: =((SUMIF('BALANCE N-1'!$A$2:$A$2000,"478*",'BALANCE N-1'!$G$2:$G$2000)-SUMIF('BALANCE N-1'!$A$2:$A$2000,"478*",'BALANCE N-1'!$H$2:$H$2000)))-(0)
A39: BZ | B39: TOTAL GENERAL | D39: =D27+D33+D37+D38 | E39: =E27+E33+E37+E38 | F39: =F27+F33+F37+F38 | G39: =G27+G33+G37+G38

Sheet Bilan-Passif
A1: - 5 -
D2: BILAN SYSTEME NORMAL PAGE 2/2
A3: Dénomination sociale :
A4: Adresse : | D4: Sigle usuel :
A5: N° de compte contribuable (NCC) : | C5: Exercice clos le | D5: Durée (en mois) : 12
A6: N° de télédéclarant (NTD) :
B7: BILAN
A8: REF | B8: PASSIF | C8: NOTE | D8: EXERCICE AU 31/12/N | E8: EXERCICE AU 31/12/N-1
D9: NET | E9: NET
A10: CA | B10: Donation non consomptible sans droit reprise | C10: note 15 | D10: =(SUMIF('BALANCE N'!$A$2:$A$2000,"101*",'BALANCE N'!$H$2:$H$2000)-SUMIF('BALANCE N'!$A$2:$A$2000,"101*",'BALANCE N'!$G$2:$G$2000)) | E10: =(SUMIF('BALANCE N-1'!$A$2:$A$2000,"101*",'BALANCE N-1'!$H$2:$H$2000)-SUMIF('BALANCE N-1'!$A$2:$A$2000,"101*",'BALANCE N-1'!$G$2:$G$2000))
A11: CB | B11: Donation non consomptible avec droit reprise | C11: note 15 | D11: =(SUMIF('BALANCE N'!$A$2:$A$2000,"102*",'BALANCE N'!$H$2:$H$2000)-SUMIF('BALANCE N'!$A$2:$A$2000,"102*",'BALANCE N'!$G$2:$G$2000)) | E11: =(SUMIF('BALANCE N-1'!$A$2:$A$2000,"102*",'BALANCE N-1'!$H$2:$H$2000)-SUMIF('BALANCE N-1'!$A$2:$A$2000,"102*",'BALANCE N-1'!$G$2:$G$2000))
A12: CC | B12: Droit d'entree | C12: note 15 | D12: =(SUMIF('BALANCE N'!$A$2:$A$2000,"103*",'BALANCE N'!$H$2:$H$2000)-SUMIF('BALANCE N'!$A$2:$A$2000,"103*",'BALANCE N'!$G$2:$G$2000)) | E12: =(SUMIF('BALANCE N-1'!$A$2:$A$2000,"103*",'BALANCE N-1'!$H$2:$H$2000)-SUMIF('BALANCE N-1'!$A$2:$A$2000,"103*",'BALANCE N-1'!$G$2:$G$2000))
A13: CD | B13: Donation consomptible | C13: note 15 | D13: =(SUMIF('BALANCE N'!$A$2:$A$2000,"104*",'BALANCE N'!$H$2:$H$2000)-SUMIF('BALANCE N'!$A$2:$A$2000,"104*",'BALANCE N'!$G$2:$G$2000)) | E13: =(SUMIF('BALANCE N-1'!$A$2:$A$2000,"104*",'BALANCE N-1'!$H$2:$H$2000)-SUMIF('BALANCE N-1'!$A$2:$A$2000,"104*",'BALANCE N-1'!$G$2:$G$2000))
A14: CE | B14: Ecarts de reevaluation | C14: note 5F | D14: =(SUMIF('BALANCE N'!$A$2:$A$2000,"106*",'BALANCE N'!$H$2:$H$2000)-SUMIF('BALANCE N'!$A$2:$A$2000,"106*",'BALANCE N'!$G$2:$G$2000)) | E14: =(SUMIF('BALANCE N-1'!$A$2:$A$2000,"106*",'BALANCE N-1'!$H$2:$H$2000)-SUMIF('BALANCE N-1'!$A$2:$A$2000,"106*",'BALANCE N-1'!$G$2:$G$2000))
A15: CF | B15: Reserves | C15: note 16 | D15: =(SUMIF('BALANCE N'!$A$2:$A$2000,"11*",'BALANCE N'!$H$2:$H$2000)-SUMIF('BALANCE N'!$A$2:$A$2000,"11*",'BALANCE N'!$G$2:$G$2000)) | E15: =(SUMIF('BALANCE N-1'!$A$2:$A$2000,"11*",'BALANCE N-1'!$H$2:$H$2000)-SUMIF('BALANCE N-1'!$A$2:$A$2000,"11*",'BALANCE N-1'!$G$2:$G$2000))
A16: CG | B16: Report a nouveau (+ ou -) | C16: note 16 | D16: =(SUMIF('BALANCE N'!$A$2:$A$2000,"12*",'BALANCE N'!$H$2:$H$2000)-SUMIF('BALANCE N'!$A$2:$A$2000,"12*",'BALANCE N'!$G$2:$G$2000)) | E16: =(SUMIF('BALANCE N-1'!$A$2:$A$2000,"12*",'BALANCE N-1'!$H$2:$H$2000)-SUMIF('BALANCE N-1'!$A$2:$A$2000,"12*",'BALANCE N-1'!$G$2:$G$2000))
A17: CH | B17: Resultat net de l'exercice (excedent + ou deficit -) | D17: ='Résultat'!D36+(SUMIF('BALANCE N'!$A$2:$A$2000,"13*",'BALANCE N'!$H$2:$H$2000)-SUMIF('BALANCE N'!$A$2:$A$2000,"13*",'BALANCE N'!$G$2:$G$2000)) | E17: ='Résultat'!E36+(SUMIF('BALANCE N-1'!$A$2:$A$2000,"13*",'BALANCE N-1'!$H$2:$H$2000)-SUMIF('BALANCE N-1'!$A$2:$A$2000,"13*",'BALANCE N-1'!$G$2:$G$2000))
A18: CI | B18: Subventions d'investissement | C18: note 17A | D18: =(SUMIF('BALANCE N'!$A$2:$A$2000,"14*",'BALANCE N'!$H$2:$H$2000)-SUMIF('BALANCE N'!$A$2:$A$2000,"14*",'BALANCE N'!$G$2:$G$2000)) | E18: =(SUMIF('BALANCE N-1'!$A$2:$A$2000,"14*",'BALANCE N-1'!$H$2:$H$2000)-SUMIF('BALANCE N-1'!$A$2:$A$2000,"14*",'BALANCE N-1'!$G$2:$G$2000))
A19: CJ | B19: Provisions reglementees | C19: note 17A | D19: =(SUMIF('BALANCE N'!$A$2:$A$2000,"15*",'BALANCE N'!$H$2:$H$2000)-SUMIF('BALANCE N'!$A$2:$A$2000,"15*",'BALANCE N'!$G$2:$G$2000)) | E19: =(SUMIF('BALANCE N-1'!$A$2:$A$2000,"15*",'BALANCE N-1'!$H$2:$H$2000)-SUMIF('BALANCE N-1'!$A$2:$A$2000,"15*",'BALANCE N-1'!$G$2:$G$2000))
A20: CK | B20: TOTAL FONDS PROPRES ET ASSIMILES | D20: =D10+D11+D12+D13+D14+D15+D16+D17+D18+D19 | E20: =E10+E11+E12+E13+E14+E15+E16+E17+E18+E19
A21: CW | B21: Fonds affectes et provenant de dons et legs d'immobilisations | C21: note 17B | D21: =(SUMIF('BALANCE N'!$A$2:$A$2000,"16*",'BALANCE N'!$H$2:$H$2000)-SUMIF('BALANCE N'!$A$2:$A$2000,"16*",'BALANCE N'!$G$2:$G$2000)) | E21: =(SUMIF('BALANCE N-1'!$A$2:$A$2000,"16*",'BALANCE N-1'!$H$2:$H$2000)-SUMIF('BALANCE N-1'!$A$2:$A$2000,"16*",'BALANCE N-1'!$G$2:$G$2000))
A22: CX | B22: Fonds reportes | C22: note 17B | D22: =(SUMIF('BALANCE N'!$A$2:$A$2000,"17*",'BALANCE N'!$H$2:$H$2000)-SUMIF('BALANCE N'!$A$2:$A$2000,"17*",'BALANCE N'!$G$2:$G$2000)) | E22: =(SUMIF('BALANCE N-1'!$A$2:$A$2000,"17*",'BALANCE N-1'!$H$2:$H$2000)-SUMIF('BALANCE N-1'!$A$2:$A$2000,"17*",'BALANCE N-1'!$G$2:$G$2000))
A23: CY | B23: TOTAL FONDS AFFECTES ET REPORTES | D23: =D21+D22 | E23: =E21+E22
A24: CZ | B24: TOTAL RESSOURCES PROPRES ET ASSIMILEES | D24: =D20+D23 | E24: =E20+E23
A25: DA | B25: Emprunts et dettes financieres | C25: note 18A | D25: =(SUMIF('BALANCE N'!$A$2:$A$2000,"181*",'BALANCE N'!$H$2:$H$2000)-SUMIF('BALANCE N'!$A$2:$A$2000,"181*",'BALANCE N'!$G$2:$G$2000)+SUMIF('BALANCE N'!$A$2:$A$2000,"182*",'BALANCE N'!$H$2:$H$2000)-SUMIF('BALANCE N'!$A$2:$A$2000,"182*",'BALANCE N'!$G$2:$G$2000)+SUMIF('BALANCE N'!$A$2:$A$2000,"183*",'BALANCE N'!$H$2:$H$2000)-SUMIF('BALANCE N'!$A$2:$A$2000,"183*",'BALANCE N'!$G$2:$G$2000)+SUMIF('BALANCE N'!$A$2:$A$2000,"185*",'BALANCE N'!$H$2:$H$2000)-SUMIF('BALANCE N'!$A$2:$A$2000,"185*",'BALANCE N'!$G$2:$G$2000)+SUMIF('BALANCE N'!$A$2:$A$2000,"186*",'BALANCE N'!$H$2:$H$2000)-SUMIF('BALANCE N'!$A$2:$A$2000,"186*",'BALANCE N'!$G$2:$G$2000)+SUMIF('BALANCE N'!$A$2:$A$2000,"188*",'BALANCE N'!$H$2:$H$2000)-SUMIF('BALANCE N'!$A$2:$A$2000,"188*",'BALANCE N'!$G$2:$G$2000)) | E25: =(SUMIF('BALANCE N-1'!$A$2:$A$2000,"181*",'BALANCE N-1'!$H$2:$H$2000)-SUMIF('BALANCE N-1'!$A$2:$A$2000,"181*",'BALANCE N-1'!$G$2:$G$2000)+SUMIF('BALANCE N-1'!$A$2:$A$2000,"182*",'BALANCE N-1'!$H$2:$H$2000)-SUMIF('BALANCE N-1'!$A$2:$A$2000,"182*",'BALANCE N-1'!$G$2:$G$2000)+SUMIF('BALANCE N-1'!$A$2:$A$2000,"183*",'BALANCE N-1'!$H$2:$H$2000)-SUMIF('BALANCE N-1'!$A$2:$A$2000,"183*",'BALANCE N-1'!$G$2:$G$2000)+SUMIF('BALANCE N-1'!$A$2:$A$2000,"185*",'BALANCE N-1'!$H$2:$H$2000)-SUMIF('BALANCE N-1'!$A$2:$A$2000,"185*",'BALANCE N-1'!$G$2:$G$2000)+SUMIF('BALANCE N-1'!$A$2:$A$2000,"186*",'BALANCE N-1'!$H$2:$H$2000)-SUMIF('BALANCE N-1'!$A$2:$A$2000,"186*",'BALANCE N-1'!$G$2:$G$2000)+SUMIF('BALANCE N-1'!$A$2:$A$2000,"188*",'BALANCE N-1'!$H$2:$H$2000)-SUMIF('BALANCE N-1'!$A$2:$A$2000,"188*",'BALANCE N-1'!$G$2:$G$2000))
A26: DB | B26: Dettes de location-acquisition | C26: note 18A | D26: =(SUMIF('BALANCE N'!$A$2:$A$2000,"187*",'BALANCE N'!$H$2:$H$2000)-SUMIF('BALANCE N'!$A$2:$A$2000,"187*",'BALANCE N'!$G$2:$G$2000)) | E26: =(SUMIF('BALANCE N-1'!$A$2:$A$2000,"187*",'BALANCE N-1'!$H$2:$H$2000)-SUMIF('BALANCE N-1'!$A$2:$A$2000,"187*",'BALANCE N-1'!$G$2:$G$2000))
A27: DC | B27: Provisions pour risques et charges | C27: note 18A | D27: =(SUMIF('BALANCE N'!$A$2:$A$2000,"19*",'BALANCE N'!$H$2:$H$2000)-SUMIF('BALANCE N'!$A$2:$A$2000,"19*",'BALANCE N'!$G$2:$G$2000)) | E27: =(SUMIF('BALANCE N-1'!$A$2:$A$2000,"19*",'BALANCE N-1'!$H$2:$H$2000)-SUMIF('BALANCE N-1'!$A$2:$A$2000,"19*",'BALANCE N-1'!$G$2:$G$2000))
A28: DD | B28: TOTAL DETTES FINANCIERES ET RESSOURCES ASSIMILEES | D28: =D25+D26+D27 | E28: =E25+E26+E27
A29: DE | B29: TOTAL RESSOURCES STABLES | D29: =D24+D28 | E29: =E24+E28
A30: DF | B30: Dettes circulantes HAO | C30: note 7 | D30: =(SUMIF('BALANCE N'!$A$2:$A$2000,"481*",'BALANCE N'!$H$2:$H$2000)-SUMIF('BALANCE N'!$A$2:$A$2000,"481*",'BALANCE N'!$G$2:$G$2000)+SUMIF('BALANCE N'!$A$2:$A$2000,"484*",'BALANCE N'!$H$2:$H$2000)-SUMIF('BALANCE N'!$A$2:$A$2000,"484*",'BALANCE N'!$G$2:$G$2000)+SUMIF('BALANCE N'!$A$2:$A$2000,"488*",'BALANCE N'!$H$2:$H$2000)-SUMIF('BALANCE N'!$A$2:$A$2000,"488*",'BALANCE N'!$G$2:$G$2000)+SUMIF('BALANCE N'!$A$2:$A$2000,"4861*",'BALANCE N'!$H$2:$H$2000)-SUMIF('BALANCE N'!$A$2:$A$2000,"4861*",'BALANCE N'!$G$2:$G$2000)+SUMIF('BALANCE N'!$A$2:$A$2000,"4998*",'BALANCE N'!$H$2:$H$2000)-SUMIF('BALANCE N'!$A$2:$A$2000,"4998*",'BALANCE N'!$G$2:$G$2000)) | E30: =(SUMIF('BALANCE N-1'!$A$2:$A$2000,"481*",'BALANCE N-1'!$H$2:$H$2000)-SUMIF('BALANCE N-1'!$A$2:$A$2000,"481*",'BALANCE N-1'!$G$2:$G$2000)+SUMIF('BALANCE N-1'!$A$2:$A$2000,"484*",'BALANCE N-1'!$H$2:$H$2000)-SUMIF('BALANCE N-1'!$A$2:$A$2000,"484*",'BALANCE N-1'!$G$2:$G$2000)+SUMIF('BALANCE N-1'!$A$2:$A$2000,"488*",'BALANCE N-1'!$H$2:$H$2000)-SUMIF('BALANCE N-1'!$A$2:$A$2000,"488*",'BALANCE N-1'!$G$2:$G$2000)+SUMIF('BALANCE N-1'!$A$2:$A$2000,"4861*",'BALANCE N-1'!$H$2:$H$2000)-SUMIF('BALANCE N-1'!$A$2:$A$2000,"4861*",'BALANCE N-1'!$G$2:$G$2000)+SUMIF('BALANCE N-1'!$A$2:$A$2000,"4998*",'BALANCE N-1'!$H$2:$H$2000)-SUMIF('BALANCE N-1'!$A$2:$A$2000,"4998*",'BALANCE N-1'!$G$2:$G$2000))
A31: DG | B31: Adherents, clients-usagers crediteurs | C31: note 9 | D31: =(SUMIF('BALANCE N'!$A$2:$A$2000,"419*",'BALANCE N'!$H$2:$H$2000)-SUMIF('BALANCE N'!$A$2:$A$2000,"419*",'BALANCE N'!$G$2:$G$2000)) | E31: =(SUMIF('BALANCE N-1'!$A$2:$A$2000,"419*",'BALANCE N-1'!$H$2:$H$2000)-SUMIF('BALANCE N-1'!$A$2:$A$2000,"419*",'BALANCE N-1'!$G$2:$G$2000))
A32: DH | B32: Fournisseurs | C32: note 19 | D32: =(SUMIF('BALANCE N'!$A$2:$A$2000,"40*",'BALANCE N'!$H$2:$H$2000)-SUMIF('BALANCE N'!$A$2:$A$2000,"40*",'BALANCE N'!$G$2:$G$2000)-SUMIF('BALANCE N'!$A$2:$A$2000,"409*",'BALANCE N'!$H$2:$H$2000)+SUMIF('BALANCE N'!$A$2:$A$2000,"409*",'BALANCE N'!$G$2:$G$2000)) | E32: =(SUMIF('BALANCE N-1'!$A$2:$A$2000,"40*",'BALANCE N-1'!$H$2:$H$2000)-SUMIF('BALANCE N-1'!$A$2:$A$2000,"40*",'BALANCE N-1'!$G$2:$G$2000)-SUMIF('BALANCE N-1'!$A$2:$A$2000,"409*",'BALANCE N-1'!$H$2:$H$2000)+SUMIF('BALANCE N-1'!$A$2:$A$2000,"409*",'BALANCE N-1'!$G$2:$G$2000))
A33: DI | B33: Autres dettes | C33: note 20 et 21 | D33: =(SUMIF('BALANCE N'!$A$2:$A$2000,"42*",'BALANCE N'!$H$2:$H$2000)+SUMIF('BALANCE N'!$A$2:$A$2000,"43*",'BALANCE N'!$H$2:$H$2000)+SUMIF('BALANCE N'!$A$2:$A$2000,"44*",'BALANCE N'!$H$2:$H$2000)+SUMIF('BALANCE N'!$A$2:$A$2000,"45*",'BALANCE N'!$H$2:$H$2000)+SUMIF('BALANCE N'!$A$2:$A$2000,"46*",'BALANCE N'!$H$2:$H$2000)+SUMIF('BALANCE N'!$A$2:$A$2000,"47*",'BALANCE N'!$H$2:$H$2000)+SUMIF('BALANCE N'!$A$2:$A$2000,"499*",'BALANCE N'!$H$2:$H$2000)+SUMIF('BALANCE N'!$A$2:$A$2000,"599*",'BALANCE N'!$H$2:$H$2000)-SUMIF('BALANCE N'!$A$2:$A$2000,"479*",'BALANCE N'!$H$2:$H$2000)-SUMIF('BALANCE N'!$A$2:$A$2000,"4998*",'BALANCE N'!$H$2:$H$2000)) | E33: =(SUMIF('BALANCE N-1'!$A$2:$A$2000,"42*",'BALANCE N-1'!$H$2:$H$2000)+SUMIF('BALANCE N-1'!$A$2:$A$2000,"43*",'BALANCE N-1'!$H$2:$H$2000)+SUMIF('BALANCE N-1'!$A$2:$A$2000,"44*",'BALANCE N-1'!$H$2:$H$2000)+SUMIF('BALANCE N-1'!$A$2:$A$2000,"45*",'BALANCE N-1'!$H$2:$H$2000)+SUMIF('BALANCE N-1'!$A$2:$A$2000,"46*",'BALANCE N-1'!$H$2:$H$2000)+SUMIF('BALANCE N-1'!$A$2:$A$2000,"47*",'BALANCE N-1'!$H$2:$H$2000)+SUMIF('BALANCE N-1'!$A$2:$A$2000,"499*",'BALANCE N-1'!$H$2:$H$2000)+SUMIF('BALANCE N-1'!$A$2:$A$2000,"599*",'BALANCE N-1'!$H$2:$H$2000)-SUMIF('BALANCE N-1'!$A$2:$A$2000,"479*",'BALANCE N-1'!$H$2:$H$2000)-SUMIF('BALANCE N-1'!$A$2:$A$2000,"4998*",'BALANCE N-1'!$H$2:$H$2000))
A34: DV | B34: TOTAL PASSIF CIRCULANT | D34: =D30+D31+D32+D33 | E34: =E30+E31+E32+E33
A35: DW | B35: Banques, etablissements financiers et credits de tresorerie | C35: note 22 | D35: =(SUMIF('BALANCE N'!$A$2:$A$2000,"564*",'BALANCE N'!$H$2:$H$2000)-SUMIF('BALANCE N'!$A$2:$A$2000,"564*",'BALANCE N'!$G$2:$G$2000)+SUMIF('BALANCE N'!$A$2:$A$2000,"565*",'BALANCE N'!$H$2:$H$2000)-SUMIF('BALANCE N'!$A$2:$A$2000,"565*",'BALANCE N'!$G$2:$G$2000))+(SUMIF('BALANCE N'!$A$2:$A$2000,"52*",'BALANCE N'!$H$2:$H$2000)+SUMIF('BALANCE N'!$A$2:$A$2000,"53*",'BALANCE N'!$H$2:$H$2000)) | E35: =(SUMIF('BALANCE N-1'!$A$2:$A$2000,"564*",'BALANCE N-1'!$H$2:$H$2000)-SUMIF('BALANCE N-1'!$A$2:$A$2000,"564*",'BALANCE N-1'!$G$2:$G$2000)+SUMIF('BALANCE N-1'!$A$2:$A$2000,"565*",'BALANCE N-1'!$H$2:$H$2000)-SUMIF('BALANCE N-1'!$A$2:$A$2000,"565*",'BALANCE N-1'!$G$2:$G$2000))+(SUMIF('BALANCE N-1'!$A$2:$A$2000,"52*",'BALANCE N-1'!$H$2:$H$2000)+SUMIF('BALANCE N-1'!$A$2:$A$2000,"53*",'BALANCE N-1'!$H$2:$H$2000))
A36: DX | B36: TOTAL TRESORERIE PASSIF | D36: =D35 | E36: =E35
A37: DY | B37: Ecart de conversion-Passif | C37: note 14 | D37: =(SUMIF('BALANCE N'!$A$2:$A$2000,"479*",'BALANCE N'!$H$2:$H$2000)-SUMIF('BALANCE N'!$A$2:$A$2000,"479*",'BALANCE N'!$G$2:$G$2000)) | E37: =(SUMIF('BALANCE N-1'!$A$2:$A$2000,"479*",'BALANCE N-1'!$H$2:$H$2000)-SUMIF('BALANCE N-1'!$A$2:$A$2000,"479*",'BALANCE N-1'!$G$2:$G$2000))
A38: DZ | B38: TOTAL GENERAL | D38: =D29+D34+D36+D37 | E38: =E29+E34+E36+E37

Sheet Résultat
A1: - 6 -
D2: COMPTE DE RESULTAT SYSTEME NORMAL
A3: Dénomination sociale :
A4: Adresse : | D4: Sigle usuel :
A5: N° de compte contribuable (NCC) : | C5: Exercice clos le | D5: Durée (en mois) : 12
A6: N° de télédéclarant (NTD) :
B7: COMPTE DE RESULTAT
A8: REF | B8: LIBELLES | C8: NOTE | D8: EXERCICE AU 31/12/N | E8: EXERCICE AU 31/12/N-1
D9: NET | E9: NET
A10: RA | B10: Cotisations | C10: note 23 | D10: =(SUMIF('BALANCE N'!$A$2:$A$2000,"701*",'BALANCE N'!$H$2:$H$2000)-SUMIF('BALANCE N'!$A$2:$A$2000,"701*",'BALANCE N'!$G$2:$G$2000)) | E10: =(SUMIF('BALANCE N-1'!$A$2:$A$2000,"701*",'BALANCE N-1'!$H$2:$H$2000)-SUMIF('BALANCE N-1'!$A$2:$A$2000,"701*",'BALANCE N-1'!$G$2:$G$2000))
A11: RB | B11: Dotations consomptibles transferees au compte de resultat | C11: note 23 | D11: =(SUMIF('BALANCE N'!$A$2:$A$2000,"703*",'BALANCE N'!$H$2:$H$2000)-SUMIF('BALANCE N'!$A$2:$A$2000,"703*",'BALANCE N'!$G$2:$G$2000)) | E11: =(SUMIF('BALANCE N-1'!$A$2:$A$2000,"703*",'BALANCE N-1'!$H$2:$H$2000)-SUMIF('BALANCE N-1'!$A$2:$A$2000,"703*",'BALANCE N-1'!$G$2:$G$2000))
A12: RC | B12: Revenus lies a la generosite | C12: note 23 | D12: =(SUMIF('BALANCE N'!$A$2:$A$2000,"704*",'BALANCE N'!$H$2:$H$2000)-SUMIF('BALANCE N'!$A$2:$A$2000,"704*",'BALANCE N'!$G$2:$G$2000)) | E12: =(SUMIF('BALANCE N-1'!$A$2:$A$2000,"704*",'BALANCE N-1'!$H$2:$H$2000)-SUMIF('BALANCE N-1'!$A$2:$A$2000,"704*",'BALANCE N-1'!$G$2:$G$2000))
A13: RD | B13: Ventes de marchandises | C13: note 23 | D13: =(SUMIF('BALANCE N'!$A$2:$A$2000,"7051*",'BALANCE N'!$H$2:$H$2000)-SUMIF('BALANCE N'!$A$2:$A$2000,"7051*",'BALANCE N'!$G$2:$G$2000)) | E13: =(SUMIF('BALANCE N-1'!$A$2:$A$2000,"7051*",'BALANCE N-1'!$H$2:$H$2000)-SUMIF('BALANCE N-1'!$A$2:$A$2000,"7051*",'BALANCE N-1'!$G$2:$G$2000))
